Workbook

Sheet 1
A2: АО "Полиметалл УК" | AX2: Утверждаю:
A3: Форма ПО-6 | AX3: Управляющий директор
AX4: АО "Золото Северного Урала"
AX6: "_____"____________________ 20___ г.
A7: Отчёт по работе основного самоходного горного оборудования
A12: Тип оборудования, марка | B12: Инв. номер | C12: Хоз. номер | D12: Время в работе | F12: Наработка моточасов факт | H12: Пробег, км | J12: Ед. изм. | K12: Объем работ | M12: Простои, мтч | AQ12: Простои всего, час | AS12: Общий фонд времени | AU12: КТГ | AW12: КИО | AY12: Производительность | BA12: Проверка баланса | BB12: Пояснение по отклонениям
M13: Планируемые | AC13: Не планируемые
M14: ТО | O14: Тр | Q14: Кр | S14: Регламентированные технологические простои (заправка ГСМ, резерв) | U14: Перерывы на обед | W14: Приём-передача смены | Y14: Зачистка забоев/перегон | AA14: БВР | AC14: Аварийный ремонт | AK14: Отсутствие | AO14: Метеоусловия | AP14: Прочие
D15: План | E15: Факт | F15: ДВС | G15: Стрела | H15: Общий | I15: С грузом | K15: План | L15: Факт | M15: План | N15: Факт | O15: План | P15: Факт | Q15: План | R15: Факт | S15: План | T15: Факт | U15: План | V15: Факт | W15: План | X15: Факт | Y15: План | Z15: Факт | AA15: План | AB15: Факт | AC15: ДВС | AD15: Трансмиссия | AE15: Ходовая часть | AF15: Навесное об-ие | AG15: Электр. часть | AH15: Гидравл. часть | AI15: Прочие | AJ15: Автошины | AK15: Фронта работ | AL15: Зап.частей | AM15: ГСМ | AN15: Персонала | AQ15: План | AR15: Факт | AS15: План | AT15: Факт | AU15: План | AV15: Факт | AW15: План | AX15: Факт | AY15: План | AZ15: Факт
A16: 1 | B16: 2 | C16: 3 | D16: 4 | E16: 5 | F16: 6 | G16: 7 | H16: 8 | I16: 9 | J16: 10 | K16: 11 | L16: 12 | M16: 13 | N16: 14 | O16: 15 | P16: 16 | Q16: 17 | R16: 18 | S16: 19 | T16: 20 | U16: 21 | V16: 22 | W16: 23 | X16: 24 | Y16: 25 | Z16: 26 | AA16: 27 | AB16: 28 | AC16: 29 | AD16: 30 | AE16: 31 | AF16: 32 | AG16: 33 | AH16: 34 | AI16: 35 | AJ16: 36 | AK16: 37 | AL16: 38 | AM16: 39 | AN16: 40 | AO16: 41 | AP16: 42 | AQ16: 43 | AR16: 44 | AS16: 45 | AT16: 46 | AU16: 47 | AV16: 48 | AW16: 49 | AX16: 50 | AY16: 51 | AZ16: 52 | BA16: 53 | BB16: 54
A17: Экскаваторы | D17: =AT17*AW17*AU17 -> 0 | E17: =ROUND(AT17*AV17*AX17,4) -> 0 | H17: =SUM(H18:H23) -> 0 | I17: =SUM(I18:I23) -> 0 | K17: =SUM(K18:K23) -> 0 | L17: =SUM(L18:L23) -> 0 | M17: =SUM(M18:M23) -> 0 | N17: =SUM(N18:N23) -> 0 | O17: =SUM(O18:O23) -> 0 | P17: =SUM(P18:P23) -> 0 | Q17: =SUM(Q18:Q23) -> 0 | R17: =SUM(R18:R23) -> 0 | ... AP17: =SUM(AP18:AP23) -> 0 | AQ17: =M17+O17+S17+U17+W17+AA17+Q17+Y17 -> 0 | AR17: =N17+P17+R17+AC17+AD17+AE17+AF17+AG17+AH17+AI17+AJ17+AK17+AL17+AM17+AN17+AO17+AP17+T17+V17+AB17+X17+Z17 -> 0 | AS17: =SUM(AS18:AS23) -> 0 | AT17: =SUM(AT18:AT23) -> 0 | AU17: =IF(AT17-AQ17=0,0,(AT17-M17-O17-Q17)/AT17) -> 0 | AV17: =IF(AT17=0,0,(AT17-N17-P17-R17-AC17-AD17-AE17-AF17-AG17-AH17-AI17-AJ17-AL17)/AT17) -> 0 | AW17: =IF(OR(AT17=0,AU17=0),0,((AT17*AU17)-S17-U17-W17-Y17-AA17)/(AT17*AU17)) -> 0 | AX17: =IF(OR(AT17=0,AV17=0),0,((AT17*AV17)-AK17-AM17-AN17-AO17-AP17-T17-V17-X17-Z17-AB17)/(AT17*AV17)) -> 0 | AY17: =IF(K17=0,0,K17/(D17-Y17)/24) -> 0 | AZ17: =IF(L17=0,0,L17/(E17-Z17)/24) -> 0 | BA17: =ROUND(AT17-E17-AR17,4) -> 0
A18: HITACHI EX-1200 № 22 (Обр) | B18: 22 | C18: 22 | D18: =AS18*AW18*AU18 -> 0 | E18: =ROUND(AS18*AV18*AX18,4) -> 0 | J18: м3 | AQ18: =M18+O18+S18+U18+W18+AA18+Q18+Y18 -> 0 | AR18: =N18+P18+R18+AC18+AD18+AE18+AF18+AG18+AH18+AI18+AJ18+AK18+AL18+AM18+AN18+AO18+AP18+T18+V18+AB18+X18+Z18 -> 0 | AS18: =AT18 -> 0 | AU18: =IF(AT18-AQ18=0,0,(AT18-M18-O18-Q18)/AT18) -> 0 | AV18: =IF(AT18=0,0,(AT18-N18-P18-R18-AC18-AD18-AE18-AF18-AG18-AH18-AI18-AJ18-AL18)/AT18) -> 0 | AW18: =IF(OR(AT18=0,AU18=0),0,((AT18*AU18)-S18-U18-W18-Y18-AA18)/(AT18*AU18)) -> 0 | AX18: =IF(OR(AT18=0,AV18=0),0,((AT18*AV18)-AK18-AM18-AN18-AO18-AP18-T18-V18-X18-Z18-AB18)/(AT18*AV18)) -> 0 | AY18: =IF(K18=0,0,K18/(D18-Y18)/24) -> 0 | AZ18: =IF(L18=0,0,L18/(E18-Z18)/24) -> 0 | BA18: =ROUND(AS18-E18-AR18,4) -> 0
A19: HITACHI EX-1200 №23 (Обр) | B19: 23 | C19: 23 | D19: =AS19*AW19*AU19 -> 0 | E19: =ROUND(AS19*AV19*AX19,4) -> 0 | J19: м3 | AQ19: =M19+O19+S19+U19+W19+AA19+Q19+Y19 -> 0 | AR19: =N19+P19+R19+AC19+AD19+AE19+AF19+AG19+AH19+AI19+AJ19+AK19+AL19+AM19+AN19+AO19+AP19+T19+V19+AB19 -> 0 | AS19: =AT19 -> 0 | AU19: =IF(AT19-AQ19=0,0,(AT19-M19-O19-Q19)/AT19) -> 0 | AV19: =IF(AT19=0,0,(AT19-N19-P19-R19-AC19-AD19-AE19-AF19-AG19-AH19-AI19-AJ19-AL19)/AT19) -> 0 | AW19: =IF(OR(AT19=0,AU19=0),0,((AT19*AU19)-S19-U19-W19-Y19-AA19)/(AT19*AU19)) -> 0 | AX19: =IF(OR(AT19=0,AV19=0),0,((AT19*AV19)-AK19-AM19-AN19-AO19-AP19-T19-V19-X19-Z19-AB19)/(AT19*AV19)) -> 0 | AY19: =IF(K19=0,0,K19/(D19-Y19)/24) -> 0 | AZ19: =IF(L19=0,0,L19/(E19-Z19)/24) -> 0 | BA19: =ROUND(AS19-E19-AR19,4) -> 0
A20: HITACHI ZX-470 № 24 (Обр) | C20: 24 | D20: =AS20*AW20*AU20 -> 0 | E20: =ROUND(AS20*AV20*AX20,4) -> 0 | J20: м3 | AQ20: =M20+O20+S20+U20+W20+AA20+Q20+Y20 -> 0 | AR20: =N20+P20+R20+AC20+AD20+AE20+AF20+AG20+AH20+AI20+AJ20+AK20+AL20+AM20+AN20+AO20+AP20+T20+V20+AB20 -> 0 | AS20: =AT20 -> 0 | AU20: =IF(AT20-AQ20=0,0,(AT20-M20-O20-Q20)/AT20) -> 0 | AV20: =IF(AT20=0,0,(AT20-N20-P20-R20-AC20-AD20-AE20-AF20-AG20-AH20-AI20-AJ20-AL20)/AT20) -> 0 | AW20: =IF(OR(AT20=0,AU20=0),0,((AT20*AU20)-S20-U20-W20-Y20-AA20)/(AT20*AU20)) -> 0 | AX20: =IF(OR(AT20=0,AV20=0),0,((AT20*AV20)-AK20-AM20-AN20-AO20-AP20-T20-V20-X20-Z20-AB20)/(AT20*AV20)) -> 0 | AY20: =IF(K20=0,0,K20/(D20-Y20)/24) -> 0 | AZ20: =IF(L20=0,0,L20/(E20-Z20)/24) -> 0 | BA20: =ROUND(AS20-E20-AR20,4) -> 0
A21: HITACHI ZX-470 № 24 с гидромолотом | C21: 24 | D21: =AS21*AW21*AU21 -> 0 | E21: =ROUND(AS21*AV21*AX21,4) -> 0 | J21: м3 | AQ21: =M21+O21+S21+U21+W21+AA21+Q21+Y21 -> 0 | AR21: =N21+P21+R21+AC21+AD21+AE21+AF21+AG21+AH21+AI21+AJ21+AK21+AL21+AM21+AN21+AO21+AP21+T21+V21+AB21 -> 0 | AS21: =AT21 -> 0 | AU21: =IF(AT21-AQ21=0,0,(AT21-M21-O21-Q21)/AT21) -> 0 | AV21: =IF(AT21=0,0,(AT21-N21-P21-R21-AC21-AD21-AE21-AF21-AG21-AH21-AI21-AJ21-AL21)/AT21) -> 0 | AW21: =IF(OR(AT21=0,AU21=0),0,((AT21*AU21)-S21-U21-W21-Y21-AA21)/(AT21*AU21)) -> 0 | AX21: =IF(OR(AT21=0,AV21=0),0,((AT21*AV21)-AK21-AM21-AN21-AO21-AP21-T21-V21-X21-Z21-AB21)/(AT21*AV21)) -> 0 | AY21: =IF(K21=0,0,K21/(D21-Y21)/24) -> 0 | AZ21: =IF(L21=0,0,L21/(E21-Z21)/24) -> 0 | BA21: =ROUND(AS21-E21-AR21,4) -> 0
A22: HITACHI EX-1200 №25 (Обр) | C22: 25 | D22: =AS22*AW22*AU22 -> 0 | E22: =ROUND(AS22*AV22*AX22,4) -> 0 | J22: м3 | AQ22: =M22+O22+S22+U22+W22+AA22+Q22+Y22 -> 0 | AR22: =N22+P22+R22+AC22+AD22+AE22+AF22+AG22+AH22+AI22+AJ22+AK22+AL22+AM22+AN22+AO22+AP22+T22+V22+AB22 -> 0 | AS22: =AT22 -> 0 | AU22: =IF(AT22-AQ22=0,0,(AT22-M22-O22-Q22)/AT22) -> 0 | AV22: =IF(AT22=0,0,(AT22-N22-P22-R22-AC22-AD22-AE22-AF22-AG22-AH22-AI22-AJ22-AL22)/AT22) -> 0 | AW22: =IF(OR(AT22=0,AU22=0),0,((AT22*AU22)-S22-U22-W22-Y22-AA22)/(AT22*AU22)) -> 0 | AX22: =IF(OR(AT22=0,AV22=0),0,((AT22*AV22)-AK22-AM22-AN22-AO22-AP22-T22-V22-X22-Z22-AB22)/(AT22*AV22)) -> 0 | AY22: =IF(K22=0,0,K22/(D22-Y22)/24) -> 0 | AZ22: =IF(L22=0,0,L22/(E22-Z22)/24) -> 0 | BA22: =ROUND(AS22-E22-AR22,4) -> 0
A23: ЭШ 6/45 №17 | B23: ЗС001788 | C23: 17 | D23: =AS23*AW23*AU23 -> 0 | E23: =ROUND(AT23*AV23*AX23,4) -> 0 | J23: м3 | AQ23: =M23+O23+S23+U23+W23+AA23+Q23+Y23 -> 0 | AR23: =N23+P23+R23+AC23+AD23+AE23+AF23+AG23+AH23+AI23+AJ23+AK23+AL23+AM23+AN23+AO23+AP23+T23+V23+X23+Z23+AB23 -> 0 | AS23: =AT23 -> 0 | AU23: =IF(AT23-AQ23=0,0,(AT23-M23-O23-Q23)/AT23) -> 0 | AV23: =IF(AT23=0,0,(AT23-N23-P23-R23-AC23-AD23-AE23-AF23-AG23-AH23-AI23-AJ23-AL23)/AT23) -> 0 | AW23: =IF(OR(AT23=0,AU23=0),0,((AT23*AU23)-S23-U23-W23-Y23-AA23)/(AT23*AU23)) -> 0 | AX23: =IF(OR(AT23=0,AV23=0),0,((AT23*AV23)-AK23-AM23-AN23-AO23-AP23-T23-V23-X23-Z23-AB23)/(AT23*AV23)) -> 0 | AY23: =IF(D23=0,0,K23/D23/24) -> 0 | AZ23: =IF(E23=0,0,L23/E23/24) -> 0 | BA23: =ROUND(AT23-E23-AR23,4) -> 0
A24: Автосамосвалы | D24: =AT24*AW24*AU24 -> 0 | E24: =SUM(E26:E27) -> 0 | F24: =SUM(F25:F41) -> 0 | H24: =SUM(H25:H41) -> 0 | I24: =SUM(I25:I41) -> 0 | K24: =SUM(K25:K41) -> 0 | L24: =SUM(L25:L41) -> 0 | M24: =SUM(M25:M41) -> 0 | N24: =SUM(N25:N41) -> 0 | O24: =SUM(O25:O41) -> 0 | P24: =SUM(P25:P41) -> 0 | Q24: =SUM(Q25:Q41) -> 0 | R24: =SUM(R25:R41) -> 0 | ... AP24: =SUM(AP25:AP41) -> 0 | AQ24: =M24+O24+S24+U24+W24+AA24+Q24+Y24 -> 0 | AR24: =N24+P24+R24+AC24+AD24+AE24+AF24+AG24+AH24+AI24+AJ24+AK24+AL24+AM24+AN24+AO24+AP24+T24+V24+X24+Z24+AB24 -> 0 | AS24: =SUM(AS25:AS41) -> 0 | AT24: =SUM(AT25:AT41) -> 0 | AU24: =IF(AT24-AQ24=0,0,(AT24-M24-O24-Q24)/AT24) -> 0 | AV24: =IF(AT24=0,0,(AT24-N24-P24-R24-AC24-AD24-AE24-AF24-AG24-AH24-AI24-AJ24-AL24)/AT24) -> 0 | AW24: =IF(OR(AT24=0,AU24=0),0,((AT24*AU24)-S24-U24-W24-Y24-AA24)/(AT24*AU24)) -> 0 | AX24: =IF(OR(AT24=0,AV24=0),0,((AT24*AV24)-AK24-AM24-AN24-AO24-AP24-T24-V24-X24-Z24-AB24)/(AT24*AV24)) -> 0 | AY24: =IF(D24=0,0,K24/D24/24) -> 0 | AZ24: =IF(E24=0,0,L24/E24/24) -> 0 | BA24: =ROUND(AT24-E24-AR24,4) -> 0
A25: БелАЗ-754701 №30 | C25: 30 | D25: =AT25*AU25*AW25 -> 0 | E25: =ROUND(AS25*AV25*AX25,4) -> 0 | J25: т*км | AQ25: =M25+O25+S25+U25+W25+AA25+Q25+Y25 -> 0 | AR25: =N25+P25+R25+AC25+AD25+AE25+AF25+AG25+AH25+AI25+AJ25+AK25+AL25+AM25+AN25+AO25+AP25+T25+V25+X25+Z25+AB25 -> 0 | AU25: =IF(AT25-AQ25=0,0,(AT25-M25-O25-Q25)/AT25) -> 0 | AV25: =IF(AT25=0,0,(AT25-N25-P25-R25-AC25-AD25-AE25-AF25-AG25-AH25-AI25-AJ25-AL25)/AT25) -> 0 | AW25: =IF(OR(AT25=0,AU25=0),0,((AT25*AU25)-S25-U25-W25-Y25-AA25)/(AT25*AU25)) -> 0 | AX25: =IF(OR(AT25=0,AV25=0),0,((AT25*AV25)-AK25-AM25-AN25-AO25-AP25-T25-V25-X25-Z25-AB25)/(AT25*AV25)) -> 0 | AY25: =IF(D25=0,0,K25/D25/24) -> 0 | AZ25: =IF(E25=0,0,L25/E25/24) -> 0 | BA25: =ROUND(AT25-E25-AR25,4) -> 0
A26: БелАЗ-754701 №32 | B26: ЗС002871 | C26: 32 | D26: =AT26*AU26*AW26 -> 0 | E26: =ROUND(AT26*AV26*AX26,4) -> 0 | J26: т*км | AQ26: =M26+O26+S26+U26+W26+AA26+Q26+Y26 -> 0 | AR26: =N26+P26+R26+AC26+AD26+AE26+AF26+AG26+AH26+AI26+AJ26+AK26+AL26+AM26+AN26+AO26+AP26+T26+V26+X26+Z26+AB26 -> 0 | AU26: =IF(AT26-AQ26=0,0,(AT26-M26-O26-Q26)/AT26) -> 0 | AV26: =IF(AT26=0,0,(AT26-N26-P26-R26-AC26-AD26-AE26-AF26-AG26-AH26-AI26-AJ26-AL26)/AT26) -> 0 | AW26: =IF(OR(AT26=0,AU26=0),0,((AT26*AU26)-S26-U26-W26-Y26-AA26)/(AT26*AU26)) -> 0 | AX26: =IF(OR(AT26=0,AV26=0),0,((AT26*AV26)-AK26-AM26-AN26-AO26-AP26-T26-V26-X26-Z26-AB26)/(AT26*AV26)) -> 0 | AY26: =IF(D26=0,0,K26/D26/24) -> 0 | AZ26: =IF(E26=0,0,L26/E26/24) -> 0 | BA26: =ROUND(AT26-E26-AR26,4) -> 0
A27: БелАЗ-754701 №35 | B27: ЗС002828 | C27: 35 | D27: =AT27*AU27*AW27 -> 0 | E27: =ROUND(AT27*AV27*AX27,4) -> 0 | J27: т*км | AQ27: =M27+O27+S27+U27+W27+AA27+Q27+Y27 -> 0 | AR27: =N27+P27+R27+AC27+AD27+AE27+AF27+AG27+AH27+AI27+AJ27+AK27+AL27+AM27+AN27+AO27+AP27+T27+V27+X27+Z27+AB27 -> 0 | AU27: =IF(AT27-AQ27=0,0,(AT27-M27-O27-Q27)/AT27) -> 0 | AV27: =IF(AT27=0,0,(AT27-N27-P27-R27-AC27-AD27-AE27-AF27-AG27-AH27-AI27-AJ27-AL27)/AT27) -> 0 | AW27: =IF(OR(AT27=0,AU27=0),0,((AT27*AU27)-S27-U27-W27-Y27-AA27)/(AT27*AU27)) -> 0 | AX27: =IF(OR(AT27=0,AV27=0),0,((AT27*AV27)-AK27-AM27-AN27-AO27-AP27-T27-V27-X27-Z27-AB27)/(AT27*AV27)) -> 0 | AY27: =IF(D27=0,0,K27/D27/24) -> 0 | AZ27: =IF(E27=0,0,L27/E27/24) -> 0 | BA27: =ROUND(AT27-E27-AR27,4) -> 0
A28: Komatsu HD 465-7 №39 | C28: 39 | D28: =AT28*AU28*AW28 -> 0 | E28: =ROUND(AS28*AV28*AX28,4) -> 0 | J28: т*км | AQ28: =M28+O28+S28+U28+W28+AA28+Q28+Y28 -> 0 | AR28: =N28+P28+R28+AC28+AD28+AE28+AF28+AG28+AH28+AI28+AJ28+AK28+AL28+AM28+AN28+AO28+AP28+T28+V28+X28+Z28+AB28 -> 0 | AU28: =IF(AT28-AQ28=0,0,(AT28-M28-O28-Q28)/AT28) -> 0 | AV28: =IF(AT28=0,0,(AT28-N28-P28-R28-AC28-AD28-AE28-AF28-AG28-AH28-AI28-AJ28-AL28)/AT28) -> 0 | AW28: =IF(OR(AT28=0,AU28=0),0,((AT28*AU28)-S28-U28-W28-Y28-AA28)/(AT28*AU28)) -> 0 | AX28: =IF(OR(AT28=0,AV28=0),0,((AT28*AV28)-AK28-AM28-AN28-AO28-AP28-T28-V28-X28-Z28-AB28)/(AT28*AV28)) -> 0 | AY28: =IF(D28=0,0,K28/D28/24) -> 0 | AZ28: =IF(E28=0,0,L28/E28/24) -> 0 | BA28: =ROUND(AT28-E28-AR28,4) -> 0
A29: Komatsu HD 465-7 №40 | C29: 40 | D29: =AT29*AU29*AW29 -> 0 | E29: =ROUND(AS29*AV29*AX29,4) -> 0 | J29: т*км | AQ29: =M29+O29+S29+U29+W29+AA29+Q29+Y29 -> 0 | AR29: =N29+P29+R29+AC29+AD29+AE29+AF29+AG29+AH29+AI29+AJ29+AK29+AL29+AM29+AN29+AO29+AP29+T29+V29+X29+Z29+AB29 -> 0 | AU29: =IF(AT29-AQ29=0,0,(AT29-M29-O29-Q29)/AT29) -> 0 | AV29: =IF(AT29=0,0,(AT29-N29-P29-R29-AC29-AD29-AE29-AF29-AG29-AH29-AI29-AJ29-AL29)/AT29) -> 0 | AW29: =IF(OR(AT29=0,AU29=0),0,((AT29*AU29)-S29-U29-W29-Y29-AA29)/(AT29*AU29)) -> 0 | AX29: =IF(OR(AT29=0,AV29=0),0,((AT29*AV29)-AK29-AM29-AN29-AO29-AP29-T29-V29-X29-Z29-AB29)/(AT29*AV29)) -> 0 | AY29: =IF(D29=0,0,K29/D29/24) -> 0 | AZ29: =IF(E29=0,0,L29/E29/24) -> 0 | BA29: =ROUND(AT29-E29-AR29,4) -> 0
A30: Komatsu HD 465-7 №41 | C30: 41 | D30: =AT30*AU30*AW30 -> 0 | E30: =ROUND(AS30*AV30*AX30,4) -> 0 | J30: т*км | AQ30: =M30+O30+S30+U30+W30+AA30+Q30+Y30 -> 0 | AR30: =N30+P30+R30+AC30+AD30+AE30+AF30+AG30+AH30+AI30+AJ30+AK30+AL30+AM30+AN30+AO30+AP30+T30+V30+X30+Z30+AB30 -> 0 | AU30: =IF(AT30-AQ30=0,0,(AT30-M30-O30-Q30)/AT30) -> 0 | AV30: =IF(AT30=0,0,(AT30-N30-P30-R30-AC30-AD30-AE30-AF30-AG30-AH30-AI30-AJ30-AL30)/AT30) -> 0 | AW30: =IF(OR(AT30=0,AU30=0),0,((AT30*AU30)-S30-U30-W30-Y30-AA30)/(AT30*AU30)) -> 0 | AX30: =IF(OR(AT30=0,AV30=0),0,((AT30*AV30)-AK30-AM30-AN30-AO30-AP30-T30-V30-X30-Z30-AB30)/(AT30*AV30)) -> 0 | AY30: =IF(D30=0,0,K30/D30/24) -> 0 | AZ30: =IF(E30=0,0,L30/E30/24) -> 0 | BA30: =ROUND(AT30-E30-AR30,4) -> 0
A31: Komatsu HD 465-7 №42 | C31: 42 | D31: =AT31*AU31*AW31 -> 0 | E31: =ROUND(AS31*AV31*AX31,4) -> 0 | J31: т*км | AQ31: =M31+O31+S31+U31+W31+AA31+Q31+Y31 -> 0 | AR31: =N31+P31+R31+AC31+AD31+AE31+AF31+AG31+AH31+AI31+AJ31+AK31+AL31+AM31+AN31+AO31+AP31+T31+V31+X31+Z31+AB31 -> 0 | AU31: =IF(AT31-AQ31=0,0,(AT31-M31-O31-Q31)/AT31) -> 0 | AV31: =IF(AT31=0,0,(AT31-N31-P31-R31-AC31-AD31-AE31-AF31-AG31-AH31-AI31-AJ31-AL31)/AT31) -> 0 | AW31: =IF(OR(AT31=0,AU31=0),0,((AT31*AU31)-S31-U31-W31-Y31-AA31)/(AT31*AU31)) -> 0 | AX31: =IF(OR(AT31=0,AV31=0),0,((AT31*AV31)-AK31-AM31-AN31-AO31-AP31-T31-V31-X31-Z31-AB31)/(AT31*AV31)) -> 0 | AY31: =IF(D31=0,0,K31/D31/24) -> 0 | AZ31: =IF(E31=0,0,L31/E31/24) -> 0 | BA31: =ROUND(AT31-E31-AR31,4) -> 0
A32: Komatsu HD 465-7 №43 | C32: 43 | D32: =AT32*AU32*AW32 -> 0 | E32: =ROUND(AS32*AV32*AX32,4) -> 0 | J32: т*км | AQ32: =M32+O32+S32+U32+W32+AA32+Q32+Y32 -> 0 | AR32: =N32+P32+R32+AC32+AD32+AE32+AF32+AG32+AH32+AI32+AJ32+AK32+AL32+AM32+AN32+AO32+AP32+T32+V32+X32+Z32+AB32 -> 0 | AU32: =IF(AT32-AQ32=0,0,(AT32-M32-O32-Q32)/AT32) -> 0 | AV32: =IF(AT32=0,0,(AT32-N32-P32-R32-AC32-AD32-AE32-AF32-AG32-AH32-AI32-AJ32-AL32)/AT32) -> 0 | AW32: =IF(OR(AT32=0,AU32=0),0,((AT32*AU32)-S32-U32-W32-Y32-AA32)/(AT32*AU32)) -> 0 | AX32: =IF(OR(AT32=0,AV32=0),0,((AT32*AV32)-AK32-AM32-AN32-AO32-AP32-T32-V32-X32-Z32-AB32)/(AT32*AV32)) -> 0 | AY32: =IF(D32=0,0,K32/D32/24) -> 0 | AZ32: =IF(E32=0,0,L32/E32/24) -> 0 | BA32: =ROUND(AT32-E32-AR32,4) -> 0
A33: Komatsu HD 465-7 №44 | C33: 44 | D33: =AT33*AU33*AW33 -> 0 | E33: =ROUND(AS33*AV33*AX33,4) -> 0 | J33: т*км | AQ33: =M33+O33+S33+U33+W33+AA33+Q33+Y33 -> 0 | AR33: =N33+P33+R33+AC33+AD33+AE33+AF33+AG33+AH33+AI33+AJ33+AK33+AL33+AM33+AN33+AO33+AP33+T33+V33+X33+Z33+AB33 -> 0 | AU33: =IF(AT33-AQ33=0,0,(AT33-M33-O33-Q33)/AT33) -> 0 | AV33: =IF(AT33=0,0,(AT33-N33-P33-R33-AC33-AD33-AE33-AF33-AG33-AH33-AI33-AJ33-AL33)/AT33) -> 0 | AW33: =IF(OR(AT33=0,AU33=0),0,((AT33*AU33)-S33-U33-W33-Y33-AA33)/(AT33*AU33)) -> 0 | AX33: =IF(OR(AT33=0,AV33=0),0,((AT33*AV33)-AK33-AM33-AN33-AO33-AP33-T33-V33-X33-Z33-AB33)/(AT33*AV33)) -> 0 | AY33: =IF(D33=0,0,K33/D33/24) -> 0 | AZ33: =IF(E33=0,0,L33/E33/24) -> 0 | BA33: =ROUND(AT33-E33-AR33,4) -> 0
A34: Komatsu HD 465-7 №45 | C34: 45 | D34: =AT34*AU34*AW34 -> 0 | E34: =ROUND(AS34*AV34*AX34,4) -> 0 | J34: т*км | AQ34: =M34+O34+S34+U34+W34+AA34+Q34+Y34 -> 0 | AR34: =N34+P34+R34+AC34+AD34+AE34+AF34+AG34+AH34+AI34+AJ34+AK34+AL34+AM34+AN34+AO34+AP34+T34+V34+X34+Z34+AB34 -> 0 | AU34: =IF(AT34-AQ34=0,0,(AT34-M34-O34-Q34)/AT34) -> 0 | AV34: =IF(AT34=0,0,(AT34-N34-P34-R34-AC34-AD34-AE34-AF34-AG34-AH34-AI34-AJ34-AL34)/AT34) -> 0 | AW34: =IF(OR(AT34=0,AU34=0),0,((AT34*AU34)-S34-U34-W34-Y34-AA34)/(AT34*AU34)) -> 0 | AX34: =IF(OR(AT34=0,AV34=0),0,((AT34*AV34)-AK34-AM34-AN34-AO34-AP34-T34-V34-X34-Z34-AB34)/(AT34*AV34)) -> 0 | AY34: =IF(D34=0,0,K34/D34/24) -> 0 | AZ34: =IF(E34=0,0,L34/E34/24) -> 0 | BA34: =ROUND(AT34-E34-AR34,4) -> 0
A35: Komatsu HD 465-7 №46 | C35: 46 | D35: =AT35*AU35*AW35 -> 0 | E35: =ROUND(AS35*AV35*AX35,4) -> 0 | J35: т*км | AQ35: =M35+O35+S35+U35+W35+AA35+Q35+Y35 -> 0 | AR35: =N35+P35+R35+AC35+AD35+AE35+AF35+AG35+AH35+AI35+AJ35+AK35+AL35+AM35+AN35+AO35+AP35+T35+V35+X35+Z35+AB35 -> 0 | AU35: =IF(AT35-AQ35=0,0,(AT35-M35-O35-Q35)/AT35) -> 0 | AV35: =IF(AT35=0,0,(AT35-N35-P35-R35-AC35-AD35-AE35-AF35-AG35-AH35-AI35-AJ35-AL35)/AT35) -> 0 | AW35: =IF(OR(AT35=0,AU35=0),0,((AT35*AU35)-S35-U35-W35-Y35-AA35)/(AT35*AU35)) -> 0 | AX35: =IF(OR(AT35=0,AV35=0),0,((AT35*AV35)-AK35-AM35-AN35-AO35-AP35-T35-V35-X35-Z35-AB35)/(AT35*AV35)) -> 0 | AY35: =IF(D35=0,0,K35/D35/24) -> 0 | AZ35: =IF(E35=0,0,L35/E35/24) -> 0 | BA35: =ROUND(AT35-E35-AR35,4) -> 0
A36: Komatsu HD 465-7 №47 | C36: 47 | D36: =AT36*AU36*AW36 -> 0 | E36: =ROUND(AS36*AV36*AX36,4) -> 0 | J36: т*км | AQ36: =M36+O36+S36+U36+W36+AA36+Q36+Y36 -> 0 | AR36: =N36+P36+R36+AC36+AD36+AE36+AF36+AG36+AH36+AI36+AJ36+AK36+AL36+AM36+AN36+AO36+AP36+T36+V36+X36+Z36+AB36 -> 0 | AU36: =IF(AT36-AQ36=0,0,(AT36-M36-O36-Q36)/AT36) -> 0 | AV36: =IF(AT36=0,0,(AT36-N36-P36-R36-AC36-AD36-AE36-AF36-AG36-AH36-AI36-AJ36-AL36)/AT36) -> 0 | AW36: =IF(OR(AT36=0,AU36=0),0,((AT36*AU36)-S36-U36-W36-Y36-AA36)/(AT36*AU36)) -> 0 | AX36: =IF(OR(AT36=0,AV36=0),0,((AT36*AV36)-AK36-AM36-AN36-AO36-AP36-T36-V36-X36-Z36-AB36)/(AT36*AV36)) -> 0 | AY36: =IF(D36=0,0,K36/D36/24) -> 0 | AZ36: =IF(E36=0,0,L36/E36/24) -> 0 | BA36: =ROUND(AT36-E36-AR36,4) -> 0
A37: Komatsu HD 465-7 №48 | C37: 48 | D37: =AT37*AU37*AW37 -> 0 | E37: =ROUND(AS37*AV37*AX37,4) -> 0 | J37: т*км | AQ37: =M37+O37+S37+U37+W37+AA37+Q37+Y37 -> 0 | AR37: =N37+P37+R37+AC37+AD37+AE37+AF37+AG37+AH37+AI37+AJ37+AK37+AL37+AM37+AN37+AO37+AP37+T37+V37+X37+Z37+AB37 -> 0 | AU37: =IF(AT37-AQ37=0,0,(AT37-M37-O37-Q37)/AT37) -> 0 | AV37: =IF(AT37=0,0,(AT37-N37-P37-R37-AC37-AD37-AE37-AF37-AG37-AH37-AI37-AJ37-AL37)/AT37) -> 0 | AW37: =IF(OR(AT37=0,AU37=0),0,((AT37*AU37)-S37-U37-W37-Y37-AA37)/(AT37*AU37)) -> 0 | AX37: =IF(OR(AT37=0,AV37=0),0,((AT37*AV37)-AK37-AM37-AN37-AO37-AP37-T37-V37-X37-Z37-AB37)/(AT37*AV37)) -> 0 | AY37: =IF(D37=0,0,K37/D37/24) -> 0 | AZ37: =IF(E37=0,0,L37/E37/24) -> 0 | BA37: =ROUND(AT37-E37-AR37,4) -> 0
A38: Komatsu HD 465-7 №49 | C38: 49 | D38: =AT38*AU38*AW38 -> 0 | E38: =ROUND(AS38*AV38*AX38,4) -> 0 | J38: т*км | AQ38: =M38+O38+S38+U38+W38+AA38+Q38+Y38 -> 0 | AR38: =N38+P38+R38+AC38+AD38+AE38+AF38+AG38+AH38+AI38+AJ38+AK38+AL38+AM38+AN38+AO38+AP38+T38+V38+X38+Z38+AB38 -> 0 | AU38: =IF(AT38-AQ38=0,0,(AT38-M38-O38-Q38)/AT38) -> 0 | AV38: =IF(AT38=0,0,(AT38-N38-P38-R38-AC38-AD38-AE38-AF38-AG38-AH38-AI38-AJ38-AL38)/AT38) -> 0 | AW38: =IF(OR(AT38=0,AU38=0),0,((AT38*AU38)-S38-U38-W38-Y38-AA38)/(AT38*AU38)) -> 0 | AX38: =IF(OR(AT38=0,AV38=0),0,((AT38*AV38)-AK38-AM38-AN38-AO38-AP38-T38-V38-X38-Z38-AB38)/(AT38*AV38)) -> 0 | AY38: =IF(D38=0,0,K38/D38/24) -> 0 | AZ38: =IF(E38=0,0,L38/E38/24) -> 0 | BA38: =ROUND(AT38-E38-AR38,4) -> 0
A39: Komatsu HD 465-7 №50 | C39: 50 | D39: =AT39*AU39*AW39 -> 0 | E39: =ROUND(AS39*AV39*AX39,4) -> 0 | J39: т*км | AQ39: =M39+O39+S39+U39+W39+AA39+Q39+Y39 -> 0 | AR39: =N39+P39+R39+AC39+AD39+AE39+AF39+AG39+AH39+AI39+AJ39+AK39+AL39+AM39+AN39+AO39+AP39+T39+V39+X39+Z39+AB39 -> 0 | AU39: =IF(AT39-AQ39=0,0,(AT39-M39-O39-Q39)/AT39) -> 0 | AV39: =IF(AT39=0,0,(AT39-N39-P39-R39-AC39-AD39-AE39-AF39-AG39-AH39-AI39-AJ39-AL39)/AT39) -> 0 | AW39: =IF(OR(AT39=0,AU39=0),0,((AT39*AU39)-S39-U39-W39-Y39-AA39)/(AT39*AU39)) -> 0 | AX39: =IF(OR(AT39=0,AV39=0),0,((AT39*AV39)-AK39-AM39-AN39-AO39-AP39-T39-V39-X39-Z39-AB39)/(AT39*AV39)) -> 0 | AY39: =IF(D39=0,0,K39/D39/24) -> 0 | AZ39: =IF(E39=0,0,L39/E39/24) -> 0 | BA39: =ROUND(AT39-E39-AR39,4) -> 0
... A41: Komatsu HD 465-7 №52 | C41: 52 | D41: =AT41*AU41*AW41 -> 0 | E41: =ROUND(AS41*AV41*AX41,4) -> 0 | J41: т*км | AQ41: =M41+O41+S41+U41+W41+AA41+Q41+Y41 -> 0 | AR41: =N41+P41+R41+AC41+AD41+AE41+AF41+AG41+AH41+AI41+AJ41+AK41+AL41+AM41+AN41+AO41+AP41+T41+V41+X41+Z41+AB41 -> 0 | AU41: =IF(AT41-AQ41=0,0,(AT41-M41-O41-Q41)/AT41) -> 0 | AV41: =IF(AT41=0,0,(AT41-N41-P41-R41-AC41-AD41-AE41-AF41-AG41-AH41-AI41-AJ41-AL41)/AT41) -> 0 | AW41: =IF(OR(AT41=0,AU41=0),0,((AT41*AU41)-S41-U41-W41-Y41-AA41)/(AT41*AU41)) -> 0 | AX41: =IF(OR(AT41=0,AV41=0),0,((AT41*AV41)-AK41-AM41-AN41-AO41-AP41-T41-V41-X41-Z41-AB41)/(AT41*AV41)) -> 0 | AY41: =IF(D41=0,0,K41/D41/24) -> 0 | AZ41: =IF(E41=0,0,L41/E41/24) -> 0 | BA41: =ROUND(AT41-E41-AR41,4) -> 0
A42: Вспомогательная техника | D42: =SUM(D43:D45) -> 0 | E42: =SUM(E43:E45) -> 0 | F42: =SUM(F43:F45) -> 0 | H42: =SUM(H43:H45) -> 0 | I42: =SUM(I43:I45) -> 0 | M42: =SUM(M43:M45) -> 0 | N42: =SUM(N43:N45) -> 0 | O42: =SUM(O43:O45) -> 0 | P42: =SUM(P43:P45) -> 0 | Q42: =SUM(Q43:Q45) -> 0 | R42: =SUM(R43:R45) -> 0 | S42: =SUM(S43:S45) -> 0 | T42: =SUM(T43:T45) -> 0 | ... AP42: =SUM(AP43:AP45) -> 0 | AQ42: =M42+O42+S42+U42+W42+AA42+Q42+Y42 -> 0 | AR42: =N42+P42+R42+AC42+AD42+AE42+AF42+AG42+AH42+AI42+AJ42+AK42+AL42+AM42+AN42+AO42+AP42+T42+V42+X42+Z42+AB42 -> 0 | AT42: =SUM(AT43:AT45) -> 0 | AU42: =IF(AT42-AQ42=0,0,(AT42-M42-O42-Q42)/AT42) -> 0 | AV42: =IF(AT42=0,0,(AT42-N42-P42-R42-AC42-AD42-AE42-AF42-AG42-AH42-AI42-AJ42-AL42)/AT42) -> 0 | AW42: =IF(OR(AT42=0,AU42=0),0,((AT42*AU42)-S42-U42-W42-Y42-AA42)/(AT42*AU42)) -> 0 | AX42: =IF(OR(AT42=0,AV42=0),0,((AT42*AV42)-AK42-AM42-AN42-AO42-AP42-T42-V42-X42-Z42-AB42)/(AT42*AV42)) -> 0 | AY42: =IF(D42=0,0,K42/D42/24) -> 0 | AZ42: =IF(E42=0,0,L42/E42/24) -> 0 | BA42: =ROUND(AT42-E42-AR42,4) -> 0
A43: Трактор МТЗ-82 | B43: ЗС001682 | C43: 25 | D43: =AT43*AU43*AW43 -> 0 | E43: =ROUND(AT43*AV43*AX43,4) -> 0 | J43: м3 | AQ43: =M43+O43+S43+U43+W43+AA43+Q43+Y43 -> 0 | AR43: =N43+P43+R43+AC43+AD43+AE43+AF43+AG43+AH43+AI43+AJ43+AK43+AL43+AM43+AN43+AO43+AP43+T43+V43+X43+Z43+AB43 -> 0 | AU43: =IF(AT43-AQ43=0,0,(AT43-M43-O43-Q43)/AT43) -> 0 | AV43: =IF(AT43=0,0,(AT43-N43-P43-R43-AC43-AD43-AE43-AF43-AG43-AH43-AI43-AJ43-AL43)/AT43) -> 0 | AW43: =IF(OR(AT43=0,AU43=0),0,((AT43*AU43)-S43-U43-W43-Y43-AA43)/(AT43*AU43)) -> 0 | AX43: =IF(OR(AT43=0,AV43=0),0,((AT43*AV43)-AK43-AM43-AN43-AO43-AP43-T43-V43-X43-Z43-AB43)/(AT43*AV43)) -> 0 | AY43: =IF(D43=0,0,K43/D43/24) -> 0 | AZ43: =IF(E43=0,0,L43/E43/24) -> 0 | BA43: =ROUND(AT43-E43-AR43,4) -> 0
A44: Трактор с бульд.нав. ДТ-75 | C44: 31 | D44: =AT44*AU44*AW44 -> 0 | E44: =ROUND(AS44*AV44*AX44,4) -> 0 | J44: м3 | AQ44: =M44+O44+S44+U44+W44+AA44+Q44+Y44 -> 0 | AR44: =N44+P44+R44+AC44+AD44+AE44+AF44+AG44+AH44+AI44+AJ44+AK44+AL44+AM44+AN44+AO44+AP44+T44+V44+X44+Z44+AB44 -> 0 | AU44: =IF(AT44-AQ44=0,0,(AT44-M44-O44-Q44)/AT44) -> 0 | AV44: =IF(AT44=0,0,(AT44-N44-P44-R44-AC44-AD44-AE44-AF44-AG44-AH44-AI44-AJ44-AL44)/AT44) -> 0 | AW44: =IF(OR(AT44=0,AU44=0),0,((AT44*AU44)-S44-U44-W44-Y44-AA44)/(AT44*AU44)) -> 0 | AX44: =IF(OR(AT44=0,AV44=0),0,((AT44*AV44)-AK44-AM44-AN44-AO44-AP44-T44-V44-X44-Z44-AB44)/(AT44*AV44)) -> 0 | AY44: =IF(D44=0,0,K44/D44/24) -> 0 | AZ44: =IF(E44=0,0,L44/E44/24) -> 0 | BA44: =ROUND(AT44-E44-AR44,4) -> 0
A45: Трактор с бульд.нав. ДТ-75 | B45: УФ0001213 | C45: 38 | D45: =AT45*AU45*AW45 -> 0 | E45: =ROUND(AT45*AV45*AX45,4) -> 0 | J45: м3 | AQ45: =M45+O45+S45+U45+W45+AA45+Q45+Y45 -> 0 | AR45: =N45+P45+R45+AC45+AD45+AE45+AF45+AG45+AH45+AI45+AJ45+AK45+AL45+AM45+AN45+AO45+AP45+T45+V45+X45+Z45+AB45 -> 0 | AU45: =IF(AT45-AQ45=0,0,(AT45-M45-O45-Q45)/AT45) -> 0 | AV45: =IF(AT45=0,0,(AT45-N45-P45-R45-AC45-AD45-AE45-AF45-AG45-AH45-AI45-AJ45-AL45)/AT45) -> 0 | AW45: =IF(OR(AT45=0,AU45=0),0,((AT45*AU45)-S45-U45-W45-Y45-AA45)/(AT45*AU45)) -> 0 | AX45: =IF(OR(AT45=0,AV45=0),0,((AT45*AV45)-AK45-AM45-AN45-AO45-AP45-T45-V45-X45-Z45-AB45)/(AT45*AV45)) -> 0 | AY45: =IF(D45=0,0,K45/D45/24) -> 0 | AZ45: =IF(E45=0,0,L45/E45/24) -> 0 | BA45: =ROUND(AT45-E45-AR45,4) -> 0
A46: Бульдозеры | D46: =SUM(D47:D51) -> 0 | E46: =SUM(E47:E51) -> 0 | F46: =SUM(F47:F51) -> 0 | H46: =SUM(H47:H51) -> 0 | I46: =SUM(I47:I51) -> 0 | M46: =SUM(M47:M51) -> 0 | N46: =SUM(N47:N51) -> 0 | O46: =SUM(O47:O51) -> 0 | P46: =SUM(P47:P51) -> 0 | Q46: =SUM(Q47:Q51) -> 0 | R46: =SUM(R47:R51) -> 0 | S46: =SUM(S47:S51) -> 0 | T46: =SUM(T47:T51) -> 0 | ... AP46: =SUM(AP47:AP51) -> 0 | AQ46: =M46+O46+S46+U46+W46+AA46+Q46+Y46 -> 0 | AR46: =N46+P46+R46+AC46+AD46+AE46+AF46+AG46+AH46+AI46+AJ46+AK46+AL46+AM46+AN46+AO46+AP46+T46+V46+X46+Z46+AB46 -> 0 | AT46: =SUM(AT47:AT51) -> 0 | AU46: =IF(AT46-AQ46=0,0,(AT46-M46-O46-Q46)/AT46) -> 0 | AV46: =IF(AT46=0,0,(AT46-N46-P46-R46-AC46-AD46-AE46-AF46-AG46-AH46-AI46-AJ46-AL46)/AT46) -> 0 | AW46: =IF(OR(AT46=0,AU46=0),0,((AT46*AU46)-S46-U46-W46-Y46-AA46)/(AT46*AU46)) -> 0 | AX46: =IF(OR(AT46=0,AV46=0),0,((AT46*AV46)-AK46-AM46-AN46-AO46-AP46-T46-V46-X46-Z46-AB46)/(AT46*AV46)) -> 0 | AY46: =IF(D46=0,0,K46/D46/24) -> 0 | AZ46: =IF(E46=0,0,L46/E46/24) -> 0 | BA46: =ROUND(AT46-E46-AR46,4) -> 0
A47: Caterpillar D-6R №28 | B47: ЗС002874 | C47: 28 | D47: =AT47*AU47*AW47 -> 0 | E47: =ROUND(AT47*AV47*AX47,4) -> 0 | J47: м3 | AQ47: =M47+O47+S47+U47+W47+AA47+Q47+Y47 -> 0 | AR47: =N47+P47+R47+AC47+AD47+AE47+AF47+AG47+AH47+AI47+AJ47+AK47+AL47+AM47+AN47+AO47+AP47+T47+V47+X47+Z47+AB47 -> 0 | AU47: =IF(AT47-AQ47=0,0,(AT47-M47-O47-Q47)/AT47) -> 0 | AV47: =IF(AT47=0,0,(AT47-N47-P47-R47-AC47-AD47-AE47-AF47-AG47-AH47-AI47-AJ47-AL47)/AT47) -> 0 | AW47: =IF(OR(AT47=0,AU47=0),0,((AT47*AU47)-S47-U47-W47-Y47-AA47)/(AT47*AU47)) -> 0 | AX47: =IF(OR(AT47=0,AV47=0),0,((AT47*AV47)-AK47-AM47-AN47-AO47-AP47-T47-V47-X47-Z47-AB47)/(AT47*AV47)) -> 0 | AY47: =IF(D47=0,0,K47/D47/24) -> 0 | AZ47: =IF(E47=0,0,L47/E47/24) -> 0 | BA47: =ROUND(AT47-E47-AR47,4) -> 0
...

Sheet 2
A2: АО "Полиметалл УК" | AX2: Утверждаю:
A3: Форма ПО-6 | AX3: Управляющий директор
AX4: АО "Золото Северного Урала"
AX6: "_____"____________________ 20___ г.
A7: Отчёт по работе основного самоходного горного оборудования
A12: Тип оборудования, марка | B12: Инв. номер | C12: Хоз. номер | D12: Время в работе | F12: Наработка моточасов факт | H12: Пробег, км | J12: Ед. изм. | K12: Объем работ | M12: Простои, мтч | AQ12: Простои всего, час | AS12: Общий фонд времени | AU12: КТГ | AW12: КИО | AY12: Производительность | BA12: Проверка баланса | BB12: Пояснение по отклонениям
M13: Планируемые | AC13: Не планируемые
M14: ТО | O14: Тр | Q14: Кр | S14: Регламентированные технологические простои (заправка ГСМ, резерв) | U14: Перерывы на обед | W14: Приём-передача смены | Y14: Зачистка забоев/перегон | AA14: БВР | AC14: Аварийный ремонт | AK14: Отсутствие | AO14: Метеоусловия | AP14: Прочие
D15: План | E15: Факт | F15: ДВС | G15: Стрела | H15: Общий | I15: С грузом | K15: План | L15: Факт | M15: План | N15: Факт | O15: План | P15: Факт | Q15: План | R15: Факт | S15: План | T15: Факт | U15: План | V15: Факт | W15: План | X15: Факт | Y15: План | Z15: Факт | AA15: План | AB15: Факт | AC15: ДВС | AD15: Трансмиссия | AE15: Ходовая часть | AF15: Навесное об-ие | AG15: Электр. часть | AH15: Гидравл. часть | AI15: Прочие | AJ15: Автошины | AK15: Фронта работ | AL15: Зап.частей | AM15: ГСМ | AN15: Персонала | AQ15: План | AR15: Факт | AS15: План | AT15: Факт | AU15: План | AV15: Факт | AW15: План | AX15: Факт | AY15: План | AZ15: Факт
A16: 1 | B16: 2 | C16: 3 | D16: 4 | E16: 5 | F16: 6 | G16: 7 | H16: 8 | I16: 9 | J16: 10 | K16: 11 | L16: 12 | M16: 13 | N16: 14 | O16: 15 | P16: 16 | Q16: 17 | R16: 18 | S16: 19 | T16: 20 | U16: 21 | V16: 22 | W16: 23 | X16: 24 | Y16: 25 | Z16: 26 | AA16: 27 | AB16: 28 | AC16: 29 | AD16: 30 | AE16: 31 | AF16: 32 | AG16: 33 | AH16: 34 | AI16: 35 | AJ16: 36 | AK16: 37 | AL16: 38 | AM16: 39 | AN16: 40 | AO16: 41 | AP16: 42 | AQ16: 43 | AR16: 44 | AS16: 45 | AT16: 46 | AU16: 47 | AV16: 48 | AW16: 49 | AX16: 50 | AY16: 51 | AZ16: 52 | BA16: 53 | BB16: 54
A17: Экскаваторы | D17: =AT17*AW17*AU17 -> 0 | E17: =ROUND(AT17*AV17*AX17,4) -> 0 | H17: =SUM(H18:H23) -> 0 | I17: =SUM(I18:I23) -> 0 | K17: =SUM(K18:K23) -> 0 | L17: =SUM(L18:L23) -> 0 | M17: =SUM(M18:M23) -> 0 | N17: =SUM(N18:N23) -> 0 | O17: =SUM(O18:O23) -> 0 | P17: =SUM(P18:P23) -> 0 | Q17: =SUM(Q18:Q23) -> 0 | R17: =SUM(R18:R23) -> 0 | ... AP17: =SUM(AP18:AP23) -> 0 | AQ17: =M17+O17+S17+U17+W17+AA17+Q17+Y17 -> 0 | AR17: =N17+P17+R17+AC17+AD17+AE17+AF17+AG17+AH17+AI17+AJ17+AK17+AL17+AM17+AN17+AO17+AP17+T17+V17+AB17+X17+Z17 -> 0 | AS17: =SUM(AS18:AS23) -> 0 | AT17: =SUM(AT18:AT23) -> 0 | AU17: =IF(AT17-AQ17=0,0,(AT17-M17-O17-Q17)/AT17) -> 0 | AV17: =IF(AT17=0,0,(AT17-N17-P17-R17-AC17-AD17-AE17-AF17-AG17-AH17-AI17-AJ17-AL17)/AT17) -> 0 | AW17: =IF(OR(AT17=0,AU17=0),0,((AT17*AU17)-S17-U17-W17-Y17-AA17)/(AT17*AU17)) -> 0 | AX17: =IF(OR(AT17=0,AV17=0),0,((AT17*AV17)-AK17-AM17-AN17-AO17-AP17-T17-V17-X17-Z17-AB17)/(AT17*AV17)) -> 0 | AY17: =IF(K17=0,0,K17/(D17-Y17)/24) -> 0 | AZ17: =IF(L17=0,0,L17/(E17-Z17)/24) -> 0 | BA17: =ROUND(AT17-E17-AR17,4) -> 0
A18: HITACHI EX-1200 № 22 (Обр) | B18: 22 | C18: 22 | D18: =AS18*AW18*AU18 -> 0 | E18: =ROUND(AS18*AV18*AX18,4) -> 0 | J18: м3 | AQ18: =M18+O18+S18+U18+W18+AA18+Q18+Y18 -> 0 | AR18: =N18+P18+R18+AC18+AD18+AE18+AF18+AG18+AH18+AI18+AJ18+AK18+AL18+AM18+AN18+AO18+AP18+T18+V18+AB18+X18+Z18 -> 0 | AS18: =AT18 -> 0 | AU18: =IF(AT18-AQ18=0,0,(AT18-M18-O18-Q18)/AT18) -> 0 | AV18: =IF(AT18=0,0,(AT18-N18-P18-R18-AC18-AD18-AE18-AF18-AG18-AH18-AI18-AJ18-AL18)/AT18) -> 0 | AW18: =IF(OR(AT18=0,AU18=0),0,((AT18*AU18)-S18-U18-W18-Y18-AA18)/(AT18*AU18)) -> 0 | AX18: =IF(OR(AT18=0,AV18=0),0,((AT18*AV18)-AK18-AM18-AN18-AO18-AP18-T18-V18-X18-Z18-AB18)/(AT18*AV18)) -> 0 | AY18: =IF(K18=0,0,K18/(D18-Y18)/24) -> 0 | AZ18: =IF(L18=0,0,L18/(E18-Z18)/24) -> 0 | BA18: =ROUND(AS18-E18-AR18,4) -> 0
A19: HITACHI EX-1200 №23 (Обр) | B19: 23 | C19: 23 | D19: =AS19*AW19*AU19 -> 0 | E19: =ROUND(AS19*AV19*AX19,4) -> 0 | J19: м3 | AQ19: =M19+O19+S19+U19+W19+AA19+Q19+Y19 -> 0 | AR19: =N19+P19+R19+AC19+AD19+AE19+AF19+AG19+AH19+AI19+AJ19+AK19+AL19+AM19+AN19+AO19+AP19+T19+V19+AB19 -> 0 | AS19: =AT19 -> 0 | AU19: =IF(AT19-AQ19=0,0,(AT19-M19-O19-Q19)/AT19) -> 0 | AV19: =IF(AT19=0,0,(AT19-N19-P19-R19-AC19-AD19-AE19-AF19-AG19-AH19-AI19-AJ19-AL19)/AT19) -> 0 | AW19: =IF(OR(AT19=0,AU19=0),0,((AT19*AU19)-S19-U19-W19-Y19-AA19)/(AT19*AU19)) -> 0 | AX19: =IF(OR(AT19=0,AV19=0),0,((AT19*AV19)-AK19-AM19-AN19-AO19-AP19-T19-V19-X19-Z19-AB19)/(AT19*AV19)) -> 0 | AY19: =IF(K19=0,0,K19/(D19-Y19)/24) -> 0 | AZ19: =IF(L19=0,0,L19/(E19-Z19)/24) -> 0 | BA19: =ROUND(AS19-E19-AR19,4) -> 0
A20: HITACHI ZX-470 № 24 (Обр) | C20: 24 | D20: =AS20*AW20*AU20 -> 0 | E20: =ROUND(AS20*AV20*AX20,4) -> 0 | J20: м3 | AQ20: =M20+O20+S20+U20+W20+AA20+Q20+Y20 -> 0 | AR20: =N20+P20+R20+AC20+AD20+AE20+AF20+AG20+AH20+AI20+AJ20+AK20+AL20+AM20+AN20+AO20+AP20+T20+V20+AB20 -> 0 | AS20: =AT20 -> 0 | AU20: =IF(AT20-AQ20=0,0,(AT20-M20-O20-Q20)/AT20) -> 0 | AV20: =IF(AT20=0,0,(AT20-N20-P20-R20-AC20-AD20-AE20-AF20-AG20-AH20-AI20-AJ20-AL20)/AT20) -> 0 | AW20: =IF(OR(AT20=0,AU20=0),0,((AT20*AU20)-S20-U20-W20-Y20-AA20)/(AT20*AU20)) -> 0 | AX20: =IF(OR(AT20=0,AV20=0),0,((AT20*AV20)-AK20-AM20-AN20-AO20-AP20-T20-V20-X20-Z20-AB20)/(AT20*AV20)) -> 0 | AY20: =IF(K20=0,0,K20/(D20-Y20)/24) -> 0 | AZ20: =IF(L20=0,0,L20/(E20-Z20)/24) -> 0 | BA20: =ROUND(AS20-E20-AR20,4) -> 0
A21: HITACHI ZX-470 № 24 с гидромолотом | C21: 24 | D21: =AS21*AW21*AU21 -> 0 | E21: =ROUND(AS21*AV21*AX21,4) -> 0 | J21: м3 | AQ21: =M21+O21+S21+U21+W21+AA21+Q21+Y21 -> 0 | AR21: =N21+P21+R21+AC21+AD21+AE21+AF21+AG21+AH21+AI21+AJ21+AK21+AL21+AM21+AN21+AO21+AP21+T21+V21+AB21 -> 0 | AS21: =AT21 -> 0 | AU21: =IF(AT21-AQ21=0,0,(AT21-M21-O21-Q21)/AT21) -> 0 | AV21: =IF(AT21=0,0,(AT21-N21-P21-R21-AC21-AD21-AE21-AF21-AG21-AH21-AI21-AJ21-AL21)/AT21) -> 0 | AW21: =IF(OR(AT21=0,AU21=0),0,((AT21*AU21)-S21-U21-W21-Y21-AA21)/(AT21*AU21)) -> 0 | AX21: =IF(OR(AT21=0,AV21=0),0,((AT21*AV21)-AK21-AM21-AN21-AO21-AP21-T21-V21-X21-Z21-AB21)/(AT21*AV21)) -> 0 | AY21: =IF(K21=0,0,K21/(D21-Y21)/24) -> 0 | AZ21: =IF(L21=0,0,L21/(E21-Z21)/24) -> 0 | BA21: =ROUND(AS21-E21-AR21,4) -> 0
A22: HITACHI EX-1200 №25 (Обр) | C22: 25 | D22: =AS22*AW22*AU22 -> 0 | E22: =ROUND(AS22*AV22*AX22,4) -> 0 | J22: м3 | AQ22: =M22+O22+S22+U22+W22+AA22+Q22+Y22 -> 0 | AR22: =N22+P22+R22+AC22+AD22+AE22+AF22+AG22+AH22+AI22+AJ22+AK22+AL22+AM22+AN22+AO22+AP22+T22+V22+AB22 -> 0 | AS22: =AT22 -> 0 | AU22: =IF(AT22-AQ22=0,0,(AT22-M22-O22-Q22)/AT22) -> 0 | AV22: =IF(AT22=0,0,(AT22-N22-P22-R22-AC22-AD22-AE22-AF22-AG22-AH22-AI22-AJ22-AL22)/AT22) -> 0 | AW22: =IF(OR(AT22=0,AU22=0),0,((AT22*AU22)-S22-U22-W22-Y22-AA22)/(AT22*AU22)) -> 0 | AX22: =IF(OR(AT22=0,AV22=0),0,((AT22*AV22)-AK22-AM22-AN22-AO22-AP22-T22-V22-X22-Z22-AB22)/(AT22*AV22)) -> 0 | AY22: =IF(K22=0,0,K22/(D22-Y22)/24) -> 0 | AZ22: =IF(L22=0,0,L22/(E22-Z22)/24) -> 0 | BA22: =ROUND(AS22-E22-AR22,4) -> 0
A23: ЭШ 6/45 №17 | B23: ЗС001788 | C23: 17 | D23: =AS23*AW23*AU23 -> 0 | E23: =ROUND(AT23*AV23*AX23,4) -> 0 | J23: м3 | AQ23: =M23+O23+S23+U23+W23+AA23+Q23+Y23 -> 0 | AR23: =N23+P23+R23+AC23+AD23+AE23+AF23+AG23+AH23+AI23+AJ23+AK23+AL23+AM23+AN23+AO23+AP23+T23+V23+X23+Z23+AB23 -> 0 | AS23: =AT23 -> 0 | AU23: =IF(AT23-AQ23=0,0,(AT23-M23-O23-Q23)/AT23) -> 0 | AV23: =IF(AT23=0,0,(AT23-N23-P23-R23-AC23-AD23-AE23-AF23-AG23-AH23-AI23-AJ23-AL23)/AT23) -> 0 | AW23: =IF(OR(AT23=0,AU23=0),0,((AT23*AU23)-S23-U23-W23-Y23-AA23)/(AT23*AU23)) -> 0 | AX23: =IF(OR(AT23=0,AV23=0),0,((AT23*AV23)-AK23-AM23-AN23-AO23-AP23-T23-V23-X23-Z23-AB23)/(AT23*AV23)) -> 0 | AY23: =IF(D23=0,0,K23/D23/24) -> 0 | AZ23: =IF(E23=0,0,L23/E23/24) -> 0 | BA23: =ROUND(AT23-E23-AR23,4) -> 0
A24: Автосамосвалы | D24: =AT24*AW24*AU24 -> 0 | E24: =SUM(E26:E27) -> 0 | F24: =SUM(F25:F41) -> 0 | H24: =SUM(H25:H41) -> 0 | I24: =SUM(I25:I41) -> 0 | K24: =SUM(K25:K41) -> 0 | L24: =SUM(L25:L41) -> 0 | M24: =SUM(M25:M41) -> 0 | N24: =SUM(N25:N41) -> 0 | O24: =SUM(O25:O41) -> 0 | P24: =SUM(P25:P41) -> 0 | Q24: =SUM(Q25:Q41) -> 0 | R24: =SUM(R25:R41) -> 0 | ... AP24: =SUM(AP25:AP41) -> 0 | AQ24: =M24+O24+S24+U24+W24+AA24+Q24+Y24 -> 0 | AR24: =N24+P24+R24+AC24+AD24+AE24+AF24+AG24+AH24+AI24+AJ24+AK24+AL24+AM24+AN24+AO24+AP24+T24+V24+X24+Z24+AB24 -> 0 | AS24: =SUM(AS25:AS41) -> 0 | AT24: =SUM(AT25:AT41) -> 0 | AU24: =IF(AT24-AQ24=0,0,(AT24-M24-O24-Q24)/AT24) -> 0 | AV24: =IF(AT24=0,0,(AT24-N24-P24-R24-AC24-AD24-AE24-AF24-AG24-AH24-AI24-AJ24-AL24)/AT24) -> 0 | AW24: =IF(OR(AT24=0,AU24=0),0,((AT24*AU24)-S24-U24-W24-Y24-AA24)/(AT24*AU24)) -> 0 | AX24: =IF(OR(AT24=0,AV24=0),0,((AT24*AV24)-AK24-AM24-AN24-AO24-AP24-T24-V24-X24-Z24-AB24)/(AT24*AV24)) -> 0 | AY24: =IF(D24=0,0,K24/D24/24) -> 0 | AZ24: =IF(E24=0,0,L24/E24/24) -> 0 | BA24: =ROUND(AT24-E24-AR24,4) -> 0
A25: БелАЗ-754701 №30 | C25: 30 | D25: =AT25*AU25*AW25 -> 0 | E25: =ROUND(AS25*AV25*AX25,4) -> 0 | J25: т*км | AQ25: =M25+O25+S25+U25+W25+AA25+Q25+Y25 -> 0 | AR25: =N25+P25+R25+AC25+AD25+AE25+AF25+AG25+AH25+AI25+AJ25+AK25+AL25+AM25+AN25+AO25+AP25+T25+V25+X25+Z25+AB25 -> 0 | AU25: =IF(AT25-AQ25=0,0,(AT25-M25-O25-Q25)/AT25) -> 0 | AV25: =IF(AT25=0,0,(AT25-N25-P25-R25-AC25-AD25-AE25-AF25-AG25-AH25-AI25-AJ25-AL25)/AT25) -> 0 | AW25: =IF(OR(AT25=0,AU25=0),0,((AT25*AU25)-S25-U25-W25-Y25-AA25)/(AT25*AU25)) -> 0 | AX25: =IF(OR(AT25=0,AV25=0),0,((AT25*AV25)-AK25-AM25-AN25-AO25-AP25-T25-V25-X25-Z25-AB25)/(AT25*AV25)) -> 0 | AY25: =IF(D25=0,0,K25/D25/24) -> 0 | AZ25: =IF(E25=0,0,L25/E25/24) -> 0 | BA25: =ROUND(AT25-E25-AR25,4) -> 0
A26: БелАЗ-754701 №32 | B26: ЗС002871 | C26: 32 | D26: =AT26*AU26*AW26 -> 0 | E26: =ROUND(AT26*AV26*AX26,4) -> 0 | J26: т*км | AQ26: =M26+O26+S26+U26+W26+AA26+Q26+Y26 -> 0 | AR26: =N26+P26+R26+AC26+AD26+AE26+AF26+AG26+AH26+AI26+AJ26+AK26+AL26+AM26+AN26+AO26+AP26+T26+V26+X26+Z26+AB26 -> 0 | AU26: =IF(AT26-AQ26=0,0,(AT26-M26-O26-Q26)/AT26) -> 0 | AV26: =IF(AT26=0,0,(AT26-N26-P26-R26-AC26-AD26-AE26-AF26-AG26-AH26-AI26-AJ26-AL26)/AT26) -> 0 | AW26: =IF(OR(AT26=0,AU26=0),0,((AT26*AU26)-S26-U26-W26-Y26-AA26)/(AT26*AU26)) -> 0 | AX26: =IF(OR(AT26=0,AV26=0),0,((AT26*AV26)-AK26-AM26-AN26-AO26-AP26-T26-V26-X26-Z26-AB26)/(AT26*AV26)) -> 0 | AY26: =IF(D26=0,0,K26/D26/24) -> 0 | AZ26: =IF(E26=0,0,L26/E26/24) -> 0 | BA26: =ROUND(AT26-E26-AR26,4) -> 0
A27: БелАЗ-754701 №35 | B27: ЗС002828 | C27: 35 | D27: =AT27*AU27*AW27 -> 0 | E27: =ROUND(AT27*AV27*AX27,4) -> 0 | J27: т*км | AQ27: =M27+O27+S27+U27+W27+AA27+Q27+Y27 -> 0 | AR27: =N27+P27+R27+AC27+AD27+AE27+AF27+AG27+AH27+AI27+AJ27+AK27+AL27+AM27+AN27+AO27+AP27+T27+V27+X27+Z27+AB27 -> 0 | AU27: =IF(AT27-AQ27=0,0,(AT27-M27-O27-Q27)/AT27) -> 0 | AV27: =IF(AT27=0,0,(AT27-N27-P27-R27-AC27-AD27-AE27-AF27-AG27-AH27-AI27-AJ27-AL27)/AT27) -> 0 | AW27: =IF(OR(AT27=0,AU27=0),0,((AT27*AU27)-S27-U27-W27-Y27-AA27)/(AT27*AU27)) -> 0 | AX27: =IF(OR(AT27=0,AV27=0),0,((AT27*AV27)-AK27-AM27-AN27-AO27-AP27-T27-V27-X27-Z27-AB27)/(AT27*AV27)) -> 0 | AY27: =IF(D27=0,0,K27/D27/24) -> 0 | AZ27: =IF(E27=0,0,L27/E27/24) -> 0 | BA27: =ROUND(AT27-E27-AR27,4) -> 0
A28: Komatsu HD 465-7 №39 | C28: 39 | D28: =AT28*AU28*AW28 -> 0 | E28: =ROUND(AS28*AV28*AX28,4) -> 0 | J28: т*км | AQ28: =M28+O28+S28+U28+W28+AA28+Q28+Y28 -> 0 | AR28: =N28+P28+R28+AC28+AD28+AE28+AF28+AG28+AH28+AI28+AJ28+AK28+AL28+AM28+AN28+AO28+AP28+T28+V28+X28+Z28+AB28 -> 0 | AU28: =IF(AT28-AQ28=0,0,(AT28-M28-O28-Q28)/AT28) -> 0 | AV28: =IF(AT28=0,0,(AT28-N28-P28-R28-AC28-AD28-AE28-AF28-AG28-AH28-AI28-AJ28-AL28)/AT28) -> 0 | AW28: =IF(OR(AT28=0,AU28=0),0,((AT28*AU28)-S28-U28-W28-Y28-AA28)/(AT28*AU28)) -> 0 | AX28: =IF(OR(AT28=0,AV28=0),0,((AT28*AV28)-AK28-AM28-AN28-AO28-AP28-T28-V28-X28-Z28-AB28)/(AT28*AV28)) -> 0 | AY28: =IF(D28=0,0,K28/D28/24) -> 0 | AZ28: =IF(E28=0,0,L28/E28/24) -> 0 | BA28: =ROUND(AT28-E28-AR28,4) -> 0
A29: Komatsu HD 465-7 №40 | C29: 40 | D29: =AT29*AU29*AW29 -> 0 | E29: =ROUND(AS29*AV29*AX29,4) -> 0 | J29: т*км | AQ29: =M29+O29+S29+U29+W29+AA29+Q29+Y29 -> 0 | AR29: =N29+P29+R29+AC29+AD29+AE29+AF29+AG29+AH29+AI29+AJ29+AK29+AL29+AM29+AN29+AO29+AP29+T29+V29+X29+Z29+AB29 -> 0 | AU29: =IF(AT29-AQ29=0,0,(AT29-M29-O29-Q29)/AT29) -> 0 | AV29: =IF(AT29=0,0,(AT29-N29-P29-R29-AC29-AD29-AE29-AF29-AG29-AH29-AI29-AJ29-AL29)/AT29) -> 0 | AW29: =IF(OR(AT29=0,AU29=0),0,((AT29*AU29)-S29-U29-W29-Y29-AA29)/(AT29*AU29)) -> 0 | AX29: =IF(OR(AT29=0,AV29=0),0,((AT29*AV29)-AK29-AM29-AN29-AO29-AP29-T29-V29-X29-Z29-AB29)/(AT29*AV29)) -> 0 | AY29: =IF(D29=0,0,K29/D29/24) -> 0 | AZ29: =IF(E29=0,0,L29/E29/24) -> 0 | BA29: =ROUND(AT29-E29-AR29,4) -> 0
A30: Komatsu HD 465-7 №41 | C30: 41 | D30: =AT30*AU30*AW30 -> 0 | E30: =ROUND(AS30*AV30*AX30,4) -> 0 | J30: т*км | AQ30: =M30+O30+S30+U30+W30+AA30+Q30+Y30 -> 0 | AR30: =N30+P30+R30+AC30+AD30+AE30+AF30+AG30+AH30+AI30+AJ30+AK30+AL30+AM30+AN30+AO30+AP30+T30+V30+X30+Z30+AB30 -> 0 | AU30: =IF(AT30-AQ30=0,0,(AT30-M30-O30-Q30)/AT30) -> 0 | AV30: =IF(AT30=0,0,(AT30-N30-P30-R30-AC30-AD30-AE30-AF30-AG30-AH30-AI30-AJ30-AL30)/AT30) -> 0 | AW30: =IF(OR(AT30=0,AU30=0),0,((AT30*AU30)-S30-U30-W30-Y30-AA30)/(AT30*AU30)) -> 0 | AX30: =IF(OR(AT30=0,AV30=0),0,((AT30*AV30)-AK30-AM30-AN30-AO30-AP30-T30-V30-X30-Z30-AB30)/(AT30*AV30)) -> 0 | AY30: =IF(D30=0,0,K30/D30/24) -> 0 | AZ30: =IF(E30=0,0,L30/E30/24) -> 0 | BA30: =ROUND(AT30-E30-AR30,4) -> 0
A31: Komatsu HD 465-7 №42 | C31: 42 | D31: =AT31*AU31*AW31 -> 0 | E31: =ROUND(AS31*AV31*AX31,4) -> 0 | J31: т*км | AQ31: =M31+O31+S31+U31+W31+AA31+Q31+Y31 -> 0 | AR31: =N31+P31+R31+AC31+AD31+AE31+AF31+AG31+AH31+AI31+AJ31+AK31+AL31+AM31+AN31+AO31+AP31+T31+V31+X31+Z31+AB31 -> 0 | AU31: =IF(AT31-AQ31=0,0,(AT31-M31-O31-Q31)/AT31) -> 0 | AV31: =IF(AT31=0,0,(AT31-N31-P31-R31-AC31-AD31-AE31-AF31-AG31-AH31-AI31-AJ31-AL31)/AT31) -> 0 | AW31: =IF(OR(AT31=0,AU31=0),0,((AT31*AU31)-S31-U31-W31-Y31-AA31)/(AT31*AU31)) -> 0 | AX31: =IF(OR(AT31=0,AV31=0),0,((AT31*AV31)-AK31-AM31-AN31-AO31-AP31-T31-V31-X31-Z31-AB31)/(AT31*AV31)) -> 0 | AY31: =IF(D31=0,0,K31/D31/24) -> 0 | AZ31: =IF(E31=0,0,L31/E31/24) -> 0 | BA31: =ROUND(AT31-E31-AR31,4) -> 0
A32: Komatsu HD 465-7 №43 | C32: 43 | D32: =AT32*AU32*AW32 -> 0 | E32: =ROUND(AS32*AV32*AX32,4) -> 0 | J32: т*км | AQ32: =M32+O32+S32+U32+W32+AA32+Q32+Y32 -> 0 | AR32: =N32+P32+R32+AC32+AD32+AE32+AF32+AG32+AH32+AI32+AJ32+AK32+AL32+AM32+AN32+AO32+AP32+T32+V32+X32+Z32+AB32 -> 0 | AU32: =IF(AT32-AQ32=0,0,(AT32-M32-O32-Q32)/AT32) -> 0 | AV32: =IF(AT32=0,0,(AT32-N32-P32-R32-AC32-AD32-AE32-AF32-AG32-AH32-AI32-AJ32-AL32)/AT32) -> 0 | AW32: =IF(OR(AT32=0,AU32=0),0,((AT32*AU32)-S32-U32-W32-Y32-AA32)/(AT32*AU32)) -> 0 | AX32: =IF(OR(AT32=0,AV32=0),0,((AT32*AV32)-AK32-AM32-AN32-AO32-AP32-T32-V32-X32-Z32-AB32)/(AT32*AV32)) -> 0 | AY32: =IF(D32=0,0,K32/D32/24) -> 0 | AZ32: =IF(E32=0,0,L32/E32/24) -> 0 | BA32: =ROUND(AT32-E32-AR32,4) -> 0
A33: Komatsu HD 465-7 №44 | C33: 44 | D33: =AT33*AU33*AW33 -> 0 | E33: =ROUND(AS33*AV33*AX33,4) -> 0 | J33: т*км | AQ33: =M33+O33+S33+U33+W33+AA33+Q33+Y33 -> 0 | AR33: =N33+P33+R33+AC33+AD33+AE33+AF33+AG33+AH33+AI33+AJ33+AK33+AL33+AM33+AN33+AO33+AP33+T33+V33+X33+Z33+AB33 -> 0 | AU33: =IF(AT33-AQ33=0,0,(AT33-M33-O33-Q33)/AT33) -> 0 | AV33: =IF(AT33=0,0,(AT33-N33-P33-R33-AC33-AD33-AE33-AF33-AG33-AH33-AI33-AJ33-AL33)/AT33) -> 0 | AW33: =IF(OR(AT33=0,AU33=0),0,((AT33*AU33)-S33-U33-W33-Y33-AA33)/(AT33*AU33)) -> 0 | AX33: =IF(OR(AT33=0,AV33=0),0,((AT33*AV33)-AK33-AM33-AN33-AO33-AP33-T33-V33-X33-Z33-AB33)/(AT33*AV33)) -> 0 | AY33: =IF(D33=0,0,K33/D33/24) -> 0 | AZ33: =IF(E33=0,0,L33/E33/24) -> 0 | BA33: =ROUND(AT33-E33-AR33,4) -> 0
A34: Komatsu HD 465-7 №45 | C34: 45 | D34: =AT34*AU34*AW34 -> 0 | E34: =ROUND(AS34*AV34*AX34,4) -> 0 | J34: т*км | AQ34: =M34+O34+S34+U34+W34+AA34+Q34+Y34 -> 0 | AR34: =N34+P34+R34+AC34+AD34+AE34+AF34+AG34+AH34+AI34+AJ34+AK34+AL34+AM34+AN34+AO34+AP34+T34+V34+X34+Z34+AB34 -> 0 | AU34: =IF(AT34-AQ34=0,0,(AT34-M34-O34-Q34)/AT34) -> 0 | AV34: =IF(AT34=0,0,(AT34-N34-P34-R34-AC34-AD34-AE34-AF34-AG34-AH34-AI34-AJ34-AL34)/AT34) -> 0 | AW34: =IF(OR(AT34=0,AU34=0),0,((AT34*AU34)-S34-U34-W34-Y34-AA34)/(AT34*AU34)) -> 0 | AX34: =IF(OR(AT34=0,AV34=0),0,((AT34*AV34)-AK34-AM34-AN34-AO34-AP34-T34-V34-X34-Z34-AB34)/(AT34*AV34)) -> 0 | AY34: =IF(D34=0,0,K34/D34/24) -> 0 | AZ34: =IF(E34=0,0,L34/E34/24) -> 0 | BA34: =ROUND(AT34-E34-AR34,4) -> 0
A35: Komatsu HD 465-7 №46 | C35: 46 | D35: =AT35*AU35*AW35 -> 0 | E35: =ROUND(AS35*AV35*AX35,4) -> 0 | J35: т*км | AQ35: =M35+O35+S35+U35+W35+AA35+Q35+Y35 -> 0 | AR35: =N35+P35+R35+AC35+AD35+AE35+AF35+AG35+AH35+AI35+AJ35+AK35+AL35+AM35+AN35+AO35+AP35+T35+V35+X35+Z35+AB35 -> 0 | AU35: =IF(AT35-AQ35=0,0,(AT35-M35-O35-Q35)/AT35) -> 0 | AV35: =IF(AT35=0,0,(AT35-N35-P35-R35-AC35-AD35-AE35-AF35-AG35-AH35-AI35-AJ35-AL35)/AT35) -> 0 | AW35: =IF(OR(AT35=0,AU35=0),0,((AT35*AU35)-S35-U35-W35-Y35-AA35)/(AT35*AU35)) -> 0 | AX35: =IF(OR(AT35=0,AV35=0),0,((AT35*AV35)-AK35-AM35-AN35-AO35-AP35-T35-V35-X35-Z35-AB35)/(AT35*AV35)) -> 0 | AY35: =IF(D35=0,0,K35/D35/24) -> 0 | AZ35: =IF(E35=0,0,L35/E35/24) -> 0 | BA35: =ROUND(AT35-E35-AR35,4) -> 0
A36: Komatsu HD 465-7 №47 | C36: 47 | D36: =AT36*AU36*AW36 -> 0 | E36: =ROUND(AS36*AV36*AX36,4) -> 0 | J36: т*км | AQ36: =M36+O36+S36+U36+W36+AA36+Q36+Y36 -> 0 | AR36: =N36+P36+R36+AC36+AD36+AE36+AF36+AG36+AH36+AI36+AJ36+AK36+AL36+AM36+AN36+AO36+AP36+T36+V36+X36+Z36+AB36 -> 0 | AU36: =IF(AT36-AQ36=0,0,(AT36-M36-O36-Q36)/AT36) -> 0 | AV36: =IF(AT36=0,0,(AT36-N36-P36-R36-AC36-AD36-AE36-AF36-AG36-AH36-AI36-AJ36-AL36)/AT36) -> 0 | AW36: =IF(OR(AT36=0,AU36=0),0,((AT36*AU36)-S36-U36-W36-Y36-AA36)/(AT36*AU36)) -> 0 | AX36: =IF(OR(AT36=0,AV36=0),0,((AT36*AV36)-AK36-AM36-AN36-AO36-AP36-T36-V36-X36-Z36-AB36)/(AT36*AV36)) -> 0 | AY36: =IF(D36=0,0,K36/D36/24) -> 0 | AZ36: =IF(E36=0,0,L36/E36/24) -> 0 | BA36: =ROUND(AT36-E36-AR36,4) -> 0
A37: Komatsu HD 465-7 №48 | C37: 48 | D37: =AT37*AU37*AW37 -> 0 | E37: =ROUND(AS37*AV37*AX37,4) -> 0 | J37: т*км | AQ37: =M37+O37+S37+U37+W37+AA37+Q37+Y37 -> 0 | AR37: =N37+P37+R37+AC37+AD37+AE37+AF37+AG37+AH37+AI37+AJ37+AK37+AL37+AM37+AN37+AO37+AP37+T37+V37+X37+Z37+AB37 -> 0 | AU37: =IF(AT37-AQ37=0,0,(AT37-M37-O37-Q37)/AT37) -> 0 | AV37: =IF(AT37=0,0,(AT37-N37-P37-R37-AC37-AD37-AE37-AF37-AG37-AH37-AI37-AJ37-AL37)/AT37) -> 0 | AW37: =IF(OR(AT37=0,AU37=0),0,((AT37*AU37)-S37-U37-W37-Y37-AA37)/(AT37*AU37)) -> 0 | AX37: =IF(OR(AT37=0,AV37=0),0,((AT37*AV37)-AK37-AM37-AN37-AO37-AP37-T37-V37-X37-Z37-AB37)/(AT37*AV37)) -> 0 | AY37: =IF(D37=0,0,K37/D37/24) -> 0 | AZ37: =IF(E37=0,0,L37/E37/24) -> 0 | BA37: =ROUND(AT37-E37-AR37,4) -> 0
A38: Komatsu HD 465-7 №49 | C38: 49 | D38: =AT38*AU38*AW38 -> 0 | E38: =ROUND(AS38*AV38*AX38,4) -> 0 | J38: т*км | AQ38: =M38+O38+S38+U38+W38+AA38+Q38+Y38 -> 0 | AR38: =N38+P38+R38+AC38+AD38+AE38+AF38+AG38+AH38+AI38+AJ38+AK38+AL38+AM38+AN38+AO38+AP38+T38+V38+X38+Z38+AB38 -> 0 | AU38: =IF(AT38-AQ38=0,0,(AT38-M38-O38-Q38)/AT38) -> 0 | AV38: =IF(AT38=0,0,(AT38-N38-P38-R38-AC38-AD38-AE38-AF38-AG38-AH38-AI38-AJ38-AL38)/AT38) -> 0 | AW38: =IF(OR(AT38=0,AU38=0),0,((AT38*AU38)-S38-U38-W38-Y38-AA38)/(AT38*AU38)) -> 0 | AX38: =IF(OR(AT38=0,AV38=0),0,((AT38*AV38)-AK38-AM38-AN38-AO38-AP38-T38-V38-X38-Z38-AB38)/(AT38*AV38)) -> 0 | AY38: =IF(D38=0,0,K38/D38/24) -> 0 | AZ38: =IF(E38=0,0,L38/E38/24) -> 0 | BA38: =ROUND(AT38-E38-AR38,4) -> 0
A39: Komatsu HD 465-7 №50 | C39: 50 | D39: =AT39*AU39*AW39 -> 0 | E39: =ROUND(AS39*AV39*AX39,4) -> 0 | J39: т*км | AQ39: =M39+O39+S39+U39+W39+AA39+Q39+Y39 -> 0 | AR39: =N39+P39+R39+AC39+AD39+AE39+AF39+AG39+AH39+AI39+AJ39+AK39+AL39+AM39+AN39+AO39+AP39+T39+V39+X39+Z39+AB39 -> 0 | AU39: =IF(AT39-AQ39=0,0,(AT39-M39-O39-Q39)/AT39) -> 0 | AV39: =IF(AT39=0,0,(AT39-N39-P39-R39-AC39-AD39-AE39-AF39-AG39-AH39-AI39-AJ39-AL39)/AT39) -> 0 | AW39: =IF(OR(AT39=0,AU39=0),0,((AT39*AU39)-S39-U39-W39-Y39-AA39)/(AT39*AU39)) -> 0 | AX39: =IF(OR(AT39=0,AV39=0),0,((AT39*AV39)-AK39-AM39-AN39-AO39-AP39-T39-V39-X39-Z39-AB39)/(AT39*AV39)) -> 0 | AY39: =IF(D39=0,0,K39/D39/24) -> 0 | AZ39: =IF(E39=0,0,L39/E39/24) -> 0 | BA39: =ROUND(AT39-E39-AR39,4) -> 0
... A41: Komatsu HD 465-7 №52 | C41: 52 | D41: =AT41*AU41*AW41 -> 0 | E41: =ROUND(AS41*AV41*AX41,4) -> 0 | J41: т*км | AQ41: =M41+O41+S41+U41+W41+AA41+Q41+Y41 -> 0 | AR41: =N41+P41+R41+AC41+AD41+AE41+AF41+AG41+AH41+AI41+AJ41+AK41+AL41+AM41+AN41+AO41+AP41+T41+V41+X41+Z41+AB41 -> 0 | AU41: =IF(AT41-AQ41=0,0,(AT41-M41-O41-Q41)/AT41) -> 0 | AV41: =IF(AT41=0,0,(AT41-N41-P41-R41-AC41-AD41-AE41-AF41-AG41-AH41-AI41-AJ41-AL41)/AT41) -> 0 | AW41: =IF(OR(AT41=0,AU41=0),0,((AT41*AU41)-S41-U41-W41-Y41-AA41)/(AT41*AU41)) -> 0 | AX41: =IF(OR(AT41=0,AV41=0),0,((AT41*AV41)-AK41-AM41-AN41-AO41-AP41-T41-V41-X41-Z41-AB41)/(AT41*AV41)) -> 0 | AY41: =IF(D41=0,0,K41/D41/24) -> 0 | AZ41: =IF(E41=0,0,L41/E41/24) -> 0 | BA41: =ROUND(AT41-E41-AR41,4) -> 0
A42: Вспомогательная техника | D42: =SUM(D43:D45) -> 0 | E42: =SUM(E43:E45) -> 0 | F42: =SUM(F43:F45) -> 0 | H42: =SUM(H43:H45) -> 0 | I42: =SUM(I43:I45) -> 0 | M42: =SUM(M43:M45) -> 0 | N42: =SUM(N43:N45) -> 0 | O42: =SUM(O43:O45) -> 0 | P42: =SUM(P43:P45) -> 0 | Q42: =SUM(Q43:Q45) -> 0 | R42: =SUM(R43:R45) -> 0 | S42: =SUM(S43:S45) -> 0 | T42: =SUM(T43:T45) -> 0 | ... AP42: =SUM(AP43:AP45) -> 0 | AQ42: =M42+O42+S42+U42+W42+AA42+Q42+Y42 -> 0 | AR42: =N42+P42+R42+AC42+AD42+AE42+AF42+AG42+AH42+AI42+AJ42+AK42+AL42+AM42+AN42+AO42+AP42+T42+V42+X42+Z42+AB42 -> 0 | AT42: =SUM(AT43:AT45) -> 0 | AU42: =IF(AT42-AQ42=0,0,(AT42-M42-O42-Q42)/AT42) -> 0 | AV42: =IF(AT42=0,0,(AT42-N42-P42-R42-AC42-AD42-AE42-AF42-AG42-AH42-AI42-AJ42-AL42)/AT42) -> 0 | AW42: =IF(OR(AT42=0,AU42=0),0,((AT42*AU42)-S42-U42-W42-Y42-AA42)/(AT42*AU42)) -> 0 | AX42: =IF(OR(AT42=0,AV42=0),0,((AT42*AV42)-AK42-AM42-AN42-AO42-AP42-T42-V42-X42-Z42-AB42)/(AT42*AV42)) -> 0 | AY42: =IF(D42=0,0,K42/D42/24) -> 0 | AZ42: =IF(E42=0,0,L42/E42/24) -> 0 | BA42: =ROUND(AT42-E42-AR42,4) -> 0
A43: Трактор МТЗ-82 | B43: ЗС001682 | C43: 25 | D43: =AT43*AU43*AW43 -> 0 | E43: =ROUND(AT43*AV43*AX43,4) -> 0 | J43: м3 | AQ43: =M43+O43+S43+U43+W43+AA43+Q43+Y43 -> 0 | AR43: =N43+P43+R43+AC43+AD43+AE43+AF43+AG43+AH43+AI43+AJ43+AK43+AL43+AM43+AN43+AO43+AP43+T43+V43+X43+Z43+AB43 -> 0 | AU43: =IF(AT43-AQ43=0,0,(AT43-M43-O43-Q43)/AT43) -> 0 | AV43: =IF(AT43=0,0,(AT43-N43-P43-R43-AC43-AD43-AE43-AF43-AG43-AH43-AI43-AJ43-AL43)/AT43) -> 0 | AW43: =IF(OR(AT43=0,AU43=0),0,((AT43*AU43)-S43-U43-W43-Y43-AA43)/(AT43*AU43)) -> 0 | AX43: =IF(OR(AT43=0,AV43=0),0,((AT43*AV43)-AK43-AM43-AN43-AO43-AP43-T43-V43-X43-Z43-AB43)/(AT43*AV43)) -> 0 | AY43: =IF(D43=0,0,K43/D43/24) -> 0 | AZ43: =IF(E43=0,0,L43/E43/24) -> 0 | BA43: =ROUND(AT43-E43-AR43,4) -> 0
A44: Трактор с бульд.нав. ДТ-75 | C44: 31 | D44: =AT44*AU44*AW44 -> 0 | E44: =ROUND(AS44*AV44*AX44,4) -> 0 | J44: м3 | AQ44: =M44+O44+S44+U44+W44+AA44+Q44+Y44 -> 0 | AR44: =N44+P44+R44+AC44+AD44+AE44+AF44+AG44+AH44+AI44+AJ44+AK44+AL44+AM44+AN44+AO44+AP44+T44+V44+X44+Z44+AB44 -> 0 | AU44: =IF(AT44-AQ44=0,0,(AT44-M44-O44-Q44)/AT44) -> 0 | AV44: =IF(AT44=0,0,(AT44-N44-P44-R44-AC44-AD44-AE44-AF44-AG44-AH44-AI44-AJ44-AL44)/AT44) -> 0 | AW44: =IF(OR(AT44=0,AU44=0),0,((AT44*AU44)-S44-U44-W44-Y44-AA44)/(AT44*AU44)) -> 0 | AX44: =IF(OR(AT44=0,AV44=0),0,((AT44*AV44)-AK44-AM44-AN44-AO44-AP44-T44-V44-X44-Z44-AB44)/(AT44*AV44)) -> 0 | AY44: =IF(D44=0,0,K44/D44/24) -> 0 | AZ44: =IF(E44=0,0,L44/E44/24) -> 0 | BA44: =ROUND(AT44-E44-AR44,4) -> 0
A45: Трактор с бульд.нав. ДТ-75 | B45: УФ0001213 | C45: 38 | D45: =AT45*AU45*AW45 -> 0 | E45: =ROUND(AT45*AV45*AX45,4) -> 0 | J45: м3 | AQ45: =M45+O45+S45+U45+W45+AA45+Q45+Y45 -> 0 | AR45: =N45+P45+R45+AC45+AD45+AE45+AF45+AG45+AH45+AI45+AJ45+AK45+AL45+AM45+AN45+AO45+AP45+T45+V45+X45+Z45+AB45 -> 0 | AU45: =IF(AT45-AQ45=0,0,(AT45-M45-O45-Q45)/AT45) -> 0 | AV45: =IF(AT45=0,0,(AT45-N45-P45-R45-AC45-AD45-AE45-AF45-AG45-AH45-AI45-AJ45-AL45)/AT45) -> 0 | AW45: =IF(OR(AT45=0,AU45=0),0,((AT45*AU45)-S45-U45-W45-Y45-AA45)/(AT45*AU45)) -> 0 | AX45: =IF(OR(AT45=0,AV45=0),0,((AT45*AV45)-AK45-AM45-AN45-AO45-AP45-T45-V45-X45-Z45-AB45)/(AT45*AV45)) -> 0 | AY45: =IF(D45=0,0,K45/D45/24) -> 0 | AZ45: =IF(E45=0,0,L45/E45/24) -> 0 | BA45: =ROUND(AT45-E45-AR45,4) -> 0
A46: Бульдозеры | D46: =SUM(D47:D51) -> 0 | E46: =SUM(E47:E51) -> 0 | F46: =SUM(F47:F51) -> 0 | H46: =SUM(H47:H51) -> 0 | I46: =SUM(I47:I51) -> 0 | M46: =SUM(M47:M51) -> 0 | N46: =SUM(N47:N51) -> 0 | O46: =SUM(O47:O51) -> 0 | P46: =SUM(P47:P51) -> 0 | Q46: =SUM(Q47:Q51) -> 0 | R46: =SUM(R47:R51) -> 0 | S46: =SUM(S47:S51) -> 0 | T46: =SUM(T47:T51) -> 0 | ... AP46: =SUM(AP47:AP51) -> 0 | AQ46: =M46+O46+S46+U46+W46+AA46+Q46+Y46 -> 0 | AR46: =N46+P46+R46+AC46+AD46+AE46+AF46+AG46+AH46+AI46+AJ46+AK46+AL46+AM46+AN46+AO46+AP46+T46+V46+X46+Z46+AB46 -> 0 | AT46: =SUM(AT47:AT51) -> 0 | AU46: =IF(AT46-AQ46=0,0,(AT46-M46-O46-Q46)/AT46) -> 0 | AV46: =IF(AT46=0,0,(AT46-N46-P46-R46-AC46-AD46-AE46-AF46-AG46-AH46-AI46-AJ46-AL46)/AT46) -> 0 | AW46: =IF(OR(AT46=0,AU46=0),0,((AT46*AU46)-S46-U46-W46-Y46-AA46)/(AT46*AU46)) -> 0 | AX46: =IF(OR(AT46=0,AV46=0),0,((AT46*AV46)-AK46-AM46-AN46-AO46-AP46-T46-V46-X46-Z46-AB46)/(AT46*AV46)) -> 0 | AY46: =IF(D46=0,0,K46/D46/24) -> 0 | AZ46: =IF(E46=0,0,L46/E46/24) -> 0 | BA46: =ROUND(AT46-E46-AR46,4) -> 0
A47: Caterpillar D-6R №28 | B47: ЗС002874 | C47: 28 | D47: =AT47*AU47*AW47 -> 0 | E47: =ROUND(AT47*AV47*AX47,4) -> 0 | J47: м3 | AQ47: =M47+O47+S47+U47+W47+AA47+Q47+Y47 -> 0 | AR47: =N47+P47+R47+AC47+AD47+AE47+AF47+AG47+AH47+AI47+AJ47+AK47+AL47+AM47+AN47+AO47+AP47+T47+V47+X47+Z47+AB47 -> 0 | AU47: =IF(AT47-AQ47=0,0,(AT47-M47-O47-Q47)/AT47) -> 0 | AV47: =IF(AT47=0,0,(AT47-N47-P47-R47-AC47-AD47-AE47-AF47-AG47-AH47-AI47-AJ47-AL47)/AT47) -> 0 | AW47: =IF(OR(AT47=0,AU47=0),0,((AT47*AU47)-S47-U47-W47-Y47-AA47)/(AT47*AU47)) -> 0 | AX47: =IF(OR(AT47=0,AV47=0),0,((AT47*AV47)-AK47-AM47-AN47-AO47-AP47-T47-V47-X47-Z47-AB47)/(AT47*AV47)) -> 0 | AY47: =IF(D47=0,0,K47/D47/24) -> 0 | AZ47: =IF(E47=0,0,L47/E47/24) -> 0 | BA47: =ROUND(AT47-E47-AR47,4) -> 0
...

Sheet 3
A2: АО "Полиметалл УК" | AX2: Утверждаю:
A3: Форма ПО-6 | AX3: Управляющий директор
AX4: АО "Золото Северного Урала"
AX6: "_____"____________________ 20___ г.
A7: Отчёт по работе основного самоходного горного оборудования
A12: Тип оборудования, марка | B12: Инв. номер | C12: Хоз. номер | D12: Время в работе | F12: Наработка моточасов факт | H12: Пробег, км | J12: Ед. изм. | K12: Объем работ | M12: Простои, мтч | AQ12: Простои всего, час | AS12: Общий фонд времени | AU12: КТГ | AW12: КИО | AY12: Производительность | BA12: Проверка баланса | BB12: Пояснение по отклонениям
M13: Планируемые | AC13: Не планируемые
M14: ТО | O14: Тр | Q14: Кр | S14: Регламентированные технологические простои (заправка ГСМ, резерв) | U14: Перерывы на обед | W14: Приём-передача смены | Y14: Зачистка забоев/перегон | AA14: БВР | AC14: Аварийный ремонт | AK14: Отсутствие | AO14: Метеоусловия | AP14: Прочие
D15: План | E15: Факт | F15: ДВС | G15: Стрела | H15: Общий | I15: С грузом | K15: План | L15: Факт | M15: План | N15: Факт | O15: План | P15: Факт | Q15: План | R15: Факт | S15: План | T15: Факт | U15: План | V15: Факт | W15: План | X15: Факт | Y15: План | Z15: Факт | AA15: План | AB15: Факт | AC15: ДВС | AD15: Трансмиссия | AE15: Ходовая часть | AF15: Навесное об-ие | AG15: Электр. часть | AH15: Гидравл. часть | AI15: Прочие | AJ15: Автошины | AK15: Фронта работ | AL15: Зап.частей | AM15: ГСМ | AN15: Персонала | AQ15: План | AR15: Факт | AS15: План | AT15: Факт | AU15: План | AV15: Факт | AW15: План | AX15: Факт | AY15: План | AZ15: Факт
A16: 1 | B16: 2 | C16: 3 | D16: 4 | E16: 5 | F16: 6 | G16: 7 | H16: 8 | I16: 9 | J16: 10 | K16: 11 | L16: 12 | M16: 13 | N16: 14 | O16: 15 | P16: 16 | Q16: 17 | R16: 18 | S16: 19 | T16: 20 | U16: 21 | V16: 22 | W16: 23 | X16: 24 | Y16: 25 | Z16: 26 | AA16: 27 | AB16: 28 | AC16: 29 | AD16: 30 | AE16: 31 | AF16: 32 | AG16: 33 | AH16: 34 | AI16: 35 | AJ16: 36 | AK16: 37 | AL16: 38 | AM16: 39 | AN16: 40 | AO16: 41 | AP16: 42 | AQ16: 43 | AR16: 44 | AS16: 45 | AT16: 46 | AU16: 47 | AV16: 48 | AW16: 49 | AX16: 50 | AY16: 51 | AZ16: 52 | BA16: 53 | BB16: 54
A17: Экскаваторы | D17: =AT17*AW17*AU17 -> 0 | E17: =ROUND(AT17*AV17*AX17,4) -> 0 | H17: =SUM(H18:H23) -> 0 | I17: =SUM(I18:I23) -> 0 | K17: =SUM(K18:K23) -> 0 | L17: =SUM(L18:L23) -> 0 | M17: =SUM(M18:M23) -> 0 | N17: =SUM(N18:N23) -> 0 | O17: =SUM(O18:O23) -> 0 | P17: =SUM(P18:P23) -> 0 | Q17: =SUM(Q18:Q23) -> 0 | R17: =SUM(R18:R23) -> 0 | ... AP17: =SUM(AP18:AP23) -> 0 | AQ17: =M17+O17+S17+U17+W17+AA17+Q17+Y17 -> 0 | AR17: =N17+P17+R17+AC17+AD17+AE17+AF17+AG17+AH17+AI17+AJ17+AK17+AL17+AM17+AN17+AO17+AP17+T17+V17+AB17+X17+Z17 -> 0 | AS17: =SUM(AS18:AS23) -> 0 | AT17: =SUM(AT18:AT23) -> 0 | AU17: =IF(AT17-AQ17=0,0,(AT17-M17-O17-Q17)/AT17) -> 0 | AV17: =IF(AT17=0,0,(AT17-N17-P17-R17-AC17-AD17-AE17-AF17-AG17-AH17-AI17-AJ17-AL17)/AT17) -> 0 | AW17: =IF(OR(AT17=0,AU17=0),0,((AT17*AU17)-S17-U17-W17-Y17-AA17)/(AT17*AU17)) -> 0 | AX17: =IF(OR(AT17=0,AV17=0),0,((AT17*AV17)-AK17-AM17-AN17-AO17-AP17-T17-V17-X17-Z17-AB17)/(AT17*AV17)) -> 0 | AY17: =IF(K17=0,0,K17/(D17-Y17)/24) -> 0 | AZ17: =IF(L17=0,0,L17/(E17-Z17)/24) -> 0 | BA17: =ROUND(AT17-E17-AR17,4) -> 0
A18: HITACHI EX-1200 № 22 (Обр) | B18: 22 | C18: 22 | D18: =AS18*AW18*AU18 -> 0 | E18: =ROUND(AS18*AV18*AX18,4) -> 0 | J18: м3 | AQ18: =M18+O18+S18+U18+W18+AA18+Q18+Y18 -> 0 | AR18: =N18+P18+R18+AC18+AD18+AE18+AF18+AG18+AH18+AI18+AJ18+AK18+AL18+AM18+AN18+AO18+AP18+T18+V18+AB18+X18+Z18 -> 0 | AS18: =AT18 -> 0 | AU18: =IF(AT18-AQ18=0,0,(AT18-M18-O18-Q18)/AT18) -> 0 | AV18: =IF(AT18=0,0,(AT18-N18-P18-R18-AC18-AD18-AE18-AF18-AG18-AH18-AI18-AJ18-AL18)/AT18) -> 0 | AW18: =IF(OR(AT18=0,AU18=0),0,((AT18*AU18)-S18-U18-W18-Y18-AA18)/(AT18*AU18)) -> 0 | AX18: =IF(OR(AT18=0,AV18=0),0,((AT18*AV18)-AK18-AM18-AN18-AO18-AP18-T18-V18-X18-Z18-AB18)/(AT18*AV18)) -> 0 | AY18: =IF(K18=0,0,K18/(D18-Y18)/24) -> 0 | AZ18: =IF(L18=0,0,L18/(E18-Z18)/24) -> 0 | BA18: =ROUND(AS18-E18-AR18,4) -> 0
A19: HITACHI EX-1200 №23 (Обр) | B19: 23 | C19: 23 | D19: =AS19*AW19*AU19 -> 0 | E19: =ROUND(AS19*AV19*AX19,4) -> 0 | J19: м3 | AQ19: =M19+O19+S19+U19+W19+AA19+Q19+Y19 -> 0 | AR19: =N19+P19+R19+AC19+AD19+AE19+AF19+AG19+AH19+AI19+AJ19+AK19+AL19+AM19+AN19+AO19+AP19+T19+V19+AB19 -> 0 | AS19: =AT19 -> 0 | AU19: =IF(AT19-AQ19=0,0,(AT19-M19-O19-Q19)/AT19) -> 0 | AV19: =IF(AT19=0,0,(AT19-N19-P19-R19-AC19-AD19-AE19-AF19-AG19-AH19-AI19-AJ19-AL19)/AT19) -> 0 | AW19: =IF(OR(AT19=0,AU19=0),0,((AT19*AU19)-S19-U19-W19-Y19-AA19)/(AT19*AU19)) -> 0 | AX19: =IF(OR(AT19=0,AV19=0),0,((AT19*AV19)-AK19-AM19-AN19-AO19-AP19-T19-V19-X19-Z19-AB19)/(AT19*AV19)) -> 0 | AY19: =IF(K19=0,0,K19/(D19-Y19)/24) -> 0 | AZ19: =IF(L19=0,0,L19/(E19-Z19)/24) -> 0 | BA19: =ROUND(AS19-E19-AR19,4) -> 0
A20: HITACHI ZX-470 № 24 (Обр) | C20: 24 | D20: =AS20*AW20*AU20 -> 0 | E20: =ROUND(AS20*AV20*AX20,4) -> 0 | J20: м3 | AQ20: =M20+O20+S20+U20+W20+AA20+Q20+Y20 -> 0 | AR20: =N20+P20+R20+AC20+AD20+AE20+AF20+AG20+AH20+AI20+AJ20+AK20+AL20+AM20+AN20+AO20+AP20+T20+V20+AB20 -> 0 | AS20: =AT20 -> 0 | AU20: =IF(AT20-AQ20=0,0,(AT20-M20-O20-Q20)/AT20) -> 0 | AV20: =IF(AT20=0,0,(AT20-N20-P20-R20-AC20-AD20-AE20-AF20-AG20-AH20-AI20-AJ20-AL20)/AT20) -> 0 | AW20: =IF(OR(AT20=0,AU20=0),0,((AT20*AU20)-S20-U20-W20-Y20-AA20)/(AT20*AU20)) -> 0 | AX20: =IF(OR(AT20=0,AV20=0),0,((AT20*AV20)-AK20-AM20-AN20-AO20-AP20-T20-V20-X20-Z20-AB20)/(AT20*AV20)) -> 0 | AY20: =IF(K20=0,0,K20/(D20-Y20)/24) -> 0 | AZ20: =IF(L20=0,0,L20/(E20-Z20)/24) -> 0 | BA20: =ROUND(AS20-E20-AR20,4) -> 0
A21: HITACHI ZX-470 № 24 с гидромолотом | C21: 24 | D21: =AS21*AW21*AU21 -> 0 | E21: =ROUND(AS21*AV21*AX21,4) -> 0 | J21: м3 | AQ21: =M21+O21+S21+U21+W21+AA21+Q21+Y21 -> 0 | AR21: =N21+P21+R21+AC21+AD21+AE21+AF21+AG21+AH21+AI21+AJ21+AK21+AL21+AM21+AN21+AO21+AP21+T21+V21+AB21 -> 0 | AS21: =AT21 -> 0 | AU21: =IF(AT21-AQ21=0,0,(AT21-M21-O21-Q21)/AT21) -> 0 | AV21: =IF(AT21=0,0,(AT21-N21-P21-R21-AC21-AD21-AE21-AF21-AG21-AH21-AI21-AJ21-AL21)/AT21) -> 0 | AW21: =IF(OR(AT21=0,AU21=0),0,((AT21*AU21)-S21-U21-W21-Y21-AA21)/(AT21*AU21)) -> 0 | AX21: =IF(OR(AT21=0,AV21=0),0,((AT21*AV21)-AK21-AM21-AN21-AO21-AP21-T21-V21-X21-Z21-AB21)/(AT21*AV21)) -> 0 | AY21: =IF(K21=0,0,K21/(D21-Y21)/24) -> 0 | AZ21: =IF(L21=0,0,L21/(E21-Z21)/24) -> 0 | BA21: =ROUND(AS21-E21-AR21,4) -> 0
A22: HITACHI EX-1200 №25 (Обр) | C22: 25 | D22: =AS22*AW22*AU22 -> 0 | E22: =ROUND(AS22*AV22*AX22,4) -> 0 | J22: м3 | AQ22: =M22+O22+S22+U22+W22+AA22+Q22+Y22 -> 0 | AR22: =N22+P22+R22+AC22+AD22+AE22+AF22+AG22+AH22+AI22+AJ22+AK22+AL22+AM22+AN22+AO22+AP22+T22+V22+AB22 -> 0 | AS22: =AT22 -> 0 | AU22: =IF(AT22-AQ22=0,0,(AT22-M22-O22-Q22)/AT22) -> 0 | AV22: =IF(AT22=0,0,(AT22-N22-P22-R22-AC22-AD22-AE22-AF22-AG22-AH22-AI22-AJ22-AL22)/AT22) -> 0 | AW22: =IF(OR(AT22=0,AU22=0),0,((AT22*AU22)-S22-U22-W22-Y22-AA22)/(AT22*AU22)) -> 0 | AX22: =IF(OR(AT22=0,AV22=0),0,((AT22*AV22)-AK22-AM22-AN22-AO22-AP22-T22-V22-X22-Z22-AB22)/(AT22*AV22)) -> 0 | AY22: =IF(K22=0,0,K22/(D22-Y22)/24) -> 0 | AZ22: =IF(L22=0,0,L22/(E22-Z22)/24) -> 0 | BA22: =ROUND(AS22-E22-AR22,4) -> 0
A23: ЭШ 6/45 №17 | B23: ЗС001788 | C23: 17 | D23: =AS23*AW23*AU23 -> 0 | E23: =ROUND(AT23*AV23*AX23,4) -> 0 | J23: м3 | AQ23: =M23+O23+S23+U23+W23+AA23+Q23+Y23 -> 0 | AR23: =N23+P23+R23+AC23+AD23+AE23+AF23+AG23+AH23+AI23+AJ23+AK23+AL23+AM23+AN23+AO23+AP23+T23+V23+X23+Z23+AB23 -> 0 | AS23: =AT23 -> 0 | AU23: =IF(AT23-AQ23=0,0,(AT23-M23-O23-Q23)/AT23) -> 0 | AV23: =IF(AT23=0,0,(AT23-N23-P23-R23-AC23-AD23-AE23-AF23-AG23-AH23-AI23-AJ23-AL23)/AT23) -> 0 | AW23: =IF(OR(AT23=0,AU23=0),0,((AT23*AU23)-S23-U23-W23-Y23-AA23)/(AT23*AU23)) -> 0 | AX23: =IF(OR(AT23=0,AV23=0),0,((AT23*AV23)-AK23-AM23-AN23-AO23-AP23-T23-V23-X23-Z23-AB23)/(AT23*AV23)) -> 0 | AY23: =IF(D23=0,0,K23/D23/24) -> 0 | AZ23: =IF(E23=0,0,L23/E23/24) -> 0 | BA23: =ROUND(AT23-E23-AR23,4) -> 0
