Workbook

Sheet Техника new
A1: № п/п | B1: Тип оборудования, марка, бортовой (хоз.) номер | E1: Простои, час
C2: Выполненная работа за сутки | D2: Отработано за сутки, м/ч | E2: В простое тех.исправных, м/ч | F2: Планируемые | G2: Не планируемые
G3: Всего простои | H3: Дата начала простоя | I3: Дата окончания простоя | J3: Причина простоя
F4: ППР, ТО
A6: 1 | B6: Экскаваторы, всего | C6: =SUM(C7:C9) -> 0 | D6: =SUM(D7:D9) -> 0 | E6: =SUM(E7:E9) -> 0 | F6: =SUM(F7:F9) -> 0 | G6: =SUM(G7:G9) -> 0
B7: =Техника!A7 -> HITACHI ZX-470 № 24 (Обр) | C7: =Техника!F7 -> 0 | D7: =Техника!W7 -> 0 | E7: =Техника!Z7+Техника!AR7+Техника!AU7+Техника!AV7+Техника!Y7+Техника!X7-Техника!AO7-Техника!AP7 -> 0 | F7: =Техника!AA7+Техника!AB7 -> 0 | G7: =Техника!AL7+Техника!AO7+Техника!AP7 -> 0 | K7: =G7+F7+E7+D7 -> 0 | L7: 150
B8: =Техника!A8 -> HITACHI EX-1200 № 25 (Обр) | C8: =Техника!F8 -> 0 | D8: =Техника!W8 -> 0 | E8: =Техника!Z8+Техника!AR8+Техника!AU8+Техника!AV8+Техника!Y8+Техника!X8-Техника!AO8-Техника!AP8 -> 0 | F8: =Техника!AA8+Техника!AB8 -> 0 | G8: =Техника!AL8+Техника!AO8+Техника!AP8 -> 0 | K8: =G8+F8+E8+D8 -> 0
B9: =Техника!A9 -> ЭШ 6/45 №17 | C9: =Техника!F9 -> 0 | D9: =Техника!W9 -> 0 | E9: =Техника!Z9+Техника!AR9+Техника!AU9+Техника!AV9+Техника!Y9+Техника!X9-Техника!AO9-Техника!AP9 -> 0 | F9: =Техника!AA9+Техника!AB9 -> 0 | G9: =Техника!AL9+Техника!AO9+Техника!AP9 -> 0 | K9: =G9+F9+E9+D9 -> 0 | L9: 45
B10: Автосамосвалы, всего | C10: =SUM(C11:C13) -> 0 | D10: =SUM(D11:D13) -> 0 | E10: =SUM(E11:E13) -> 0 | F10: =SUM(F11:F13) -> 0 | G10: =SUM(G11:G13) -> 0 | K10: =G10+F10+E10+D10 -> 0
B11: =Техника!A10 -> БелАЗ-754701 №30 | C11: =Техника!F10 -> 0 | D11: =Техника!W10 -> 0 | E11: =Техника!Z10+Техника!AR10+Техника!AU10+Техника!AV10+Техника!Y10+Техника!X10-Техника!AO10-Техника!AP10 -> 0 | F11: =Техника!AA10+Техника!AB10 -> 0 | G11: =Техника!AL10+Техника!AO10+Техника!AP10 -> 0 | K11: =G11+F11+E11+D11 -> 0 | L11: 26
B12: =Техника!A11 -> БелАЗ-754701 №32 | C12: =Техника!F11 -> 0 | D12: =Техника!W11 -> 0 | E12: =Техника!Z11+Техника!AR11+Техника!AU11+Техника!AV11+Техника!Y11+Техника!X11-Техника!AO11-Техника!AP11 -> 0 | F12: =Техника!AA11+Техника!AB11 -> 0 | G12: =Техника!AL11+Техника!AO11+Техника!AP11 -> 0 | K12: =G12+F12+E12+D12 -> 0 | L12: 28
B13: =Техника!A12 -> БелАЗ-754701 №35 | C13: =Техника!F12 -> 0 | D13: =Техника!W12 -> 0 | E13: =Техника!Z12+Техника!AR12+Техника!AU12+Техника!AV12+Техника!Y12+Техника!X12-Техника!AO12-Техника!AP12 -> 0 | F13: =Техника!AA12+Техника!AB12 -> 0 | G13: =Техника!AL12+Техника!AO12+Техника!AP12 -> 0 | K13: =G13+F13+E13+D13 -> 0 | L13: 31
B14: Бульдозеры, всего | C14: =SUM(C15:C16) -> 0 | D14: =SUM(D15:D16) -> 0 | E14: =SUM(E15:E16) -> 0 | F14: =SUM(F15:F16) -> 0 | G14: =SUM(G15:G16) -> 0 | K14: =G14+F14+E14+D14 -> 0
B15: =Техника!A15 -> Caterpillar D-9R №36 | C15: =Техника!F15 -> 0 | D15: =Техника!W15 -> 0 | E15: =Техника!Z15+Техника!AR15+Техника!AU15+Техника!AV15+Техника!Y15+Техника!X15-Техника!AO15-Техника!AP15 -> 0 | F15: =Техника!AA15+Техника!AB15 -> 0 | G15: =Техника!AL15+Техника!AO15+Техника!AP15 -> 0 | K15: =G15+F15+E15+D15 -> 0 | L15: 10
B16: =Техника!A16 -> Caterpillar D-6R №28 | C16: =Техника!F16 -> 0 | D16: =Техника!W16 -> 0 | E16: =Техника!Z16+Техника!AR16+Техника!AU16+Техника!AV16+Техника!Y16+Техника!X16-Техника!AO16-Техника!AP16 -> 0 | F16: =Техника!AA16+Техника!AB16 -> 0 | G16: =Техника!AL16+Техника!AO16+Техника!AP16 -> 0 | K16: =G16+F16+E16+D16 -> 0 | L16: 9
B17: Автогрейдер, всего | C17: =SUM(C18:C18) -> 0 | D17: =SUM(D18:D18) -> 0 | E17: =SUM(E18:E18) -> 0 | F17: =SUM(F18:F18) -> 0 | G17: =SUM(G18:G18) -> 0 | K17: =G17+F17+E17+D17 -> 0
B18: =Техника!A18 -> Caterpillar 140М №4 | C18: =Техника!F18 -> 0 | D18: =Техника!W18 -> 0 | E18: =Техника!Z18+Техника!AR18+Техника!AU18+Техника!AV18+Техника!Y18+Техника!X18-Техника!AO18-Техника!AP18 -> 0 | F18: =Техника!AA18+Техника!AB18 -> 0 | G18: =Техника!AL18+Техника!AO18+Техника!AP18 -> 0 | K18: =G18+F18+E18+D18 -> 0 | L18: 4
B19: =Техника!A19 -> Komatsu-825 №5 | C19: =Техника!F19 -> 0 | D19: =Техника!W19 -> 0 | E19: =Техника!Z19+Техника!AR19+Техника!AU19+Техника!AV19+Техника!Y19+Техника!X19-Техника!AO19-Техника!AP19 -> 0 | F19: =Техника!AA19+Техника!AB19 -> 0 | G19: =Техника!AL19+Техника!AO19+Техника!AP19 -> 0 | K19: =G19+F19+E19+D19 -> 0
B20: Фронтальные погрузчики, всего | C20: =SUM(C21:C24) -> 0 | D20: =SUM(D21:D24) -> 0 | E20: =SUM(E21:E24) -> 0 | F20: =SUM(F21:F24) -> 0 | G20: =SUM(G21:G24) -> 0 | K20: =G20+F20+E20+D20 -> 0
B21: =Техника!A21 -> CAT-962H №15 | C21: =Техника!F21 -> 0 | D21: =Техника!W21 -> 0 | E21: =Техника!Z21+Техника!AR21+Техника!AU21+Техника!AV21+Техника!Y21+Техника!X21-Техника!AO21-Техника!AP21 -> 0 | F21: =Техника!AA21+Техника!AB21 -> 0 | G21: =Техника!AL21+Техника!AO21+Техника!AP21 -> 0 | K21: =G21+F21+E21+D21 -> 0 | L21: 58
B22: =Техника!A22 -> Shantui SL60W №26 | C22: =Техника!F22 -> 0 | D22: =Техника!W22 -> 0 | E22: =Техника!Z22+Техника!AR22+Техника!AU22+Техника!AV22+Техника!Y22+Техника!X22-Техника!AO22-Техника!AP22 -> 0 | F22: =Техника!AA22+Техника!AB22 -> 0 | G22: =Техника!AL22+Техника!AO22+Техника!AP22 -> 0 | K22: =G22+F22+E22+D22 -> 0 | L22: 283
B23: =Техника!A23 -> CAT-962H №24 | C23: =Техника!F23 -> 0 | D23: =Техника!W23 -> 0 | E23: =Техника!Z23+Техника!AR23+Техника!AU23+Техника!AV23+Техника!Y23+Техника!X23-Техника!AO23-Техника!AP23 -> 0 | F23: =Техника!AA23+Техника!AB23 -> 0 | G23: =Техника!AL23+Техника!AO23+Техника!AP23 -> 0 | K23: =G23+F23+E23+D23 -> 0 | L23: 280
B24: =Техника!A24 -> CAT-988Н №16 | C24: =Техника!F24 -> 0 | D24: =Техника!W24 -> 0 | E24: =Техника!Z24+Техника!AR24+Техника!AU24+Техника!AV24+Техника!Y24+Техника!X24-Техника!AO24-Техника!AP24 -> 0 | F24: =Техника!AA24+Техника!AB24 -> 0 | G24: =Техника!AL24+Техника!AO24+Техника!AP24 -> 0 | K24: =G24+F24+E24+D24 -> 0 | L24: 43
B25: =Техника!A25 -> Shantui SL60W №30 | C25: =Техника!F25 -> 0 | D25: =Техника!W25 -> 0 | E25: =Техника!Z25+Техника!AR25+Техника!AU25+Техника!AV25+Техника!Y25+Техника!X25-Техника!AO25-Техника!AP25 -> 0 | F25: =Техника!AA25+Техника!AB25 -> 0 | G25: =Техника!AL25+Техника!AO25+Техника!AP25 -> 0 | K25: =G25+F25+E25+D25 -> 0 | L25: 284
B26: =Техника!A26 -> CAT-988Н №31 | C26: =Техника!F26 -> 0 | D26: =Техника!W26 -> 0 | E26: =Техника!Z26+Техника!AR26+Техника!AU26+Техника!AV26+Техника!Y26+Техника!X26-Техника!AO26-Техника!AP26 -> 0 | F26: =Техника!AA26+Техника!AB26 -> 0 | G26: =Техника!AL26+Техника!AO26+Техника!AP26 -> 0 | K26: =G26+F26+E26+D26 -> 0
B27: =Техника!A27 -> Shantui L58K-B5 №32 | C27: =Техника!F27 -> 0 | D27: =Техника!W27 -> 0 | E27: =Техника!Z27+Техника!AR27+Техника!AU27+Техника!AV27+Техника!Y27+Техника!X27-Техника!AO27-Техника!AP27 -> 0 | F27: =Техника!AA27+Техника!AB27 -> 0 | G27: =Техника!AL27+Техника!AO27+Техника!AP27 -> 0 | K27: =G27+F27+E27+D27 -> 0

Sheet Техника
A1: Тип оборудования, марка, бортовой (хоз.) номер | B1: Количество, ед | C1: Кол-во рейсов | D1: Дальность возки, км | E1: Ед. изм работы | F1: Выполненная работа за сутки | G1: Инженерные работы | H1: Погрузка горной массы | I1: Отработано за сутки, м/ч | J1: Время работы двигателя (ВИСТ) | K1: Расход ДТ (ВИСТ), л | L1: Норма расхода ДТ, л (факт) | M1: Норма расхода ДТ, л (план) | N1: Отклонение нормы факт от плана | O1: Пробег, км | P1: Технологические перерывы | W1: ИТОГО на линии | X1: Простои, час. | AX1: ИТОГО ПРОСТОИ | AY1: Всего (д.б.24ч)
P2: Взрывные работы | Q2: Заправка | R2: Перегоны | S2: Отсутствие погрузки | T2: Планировка подъездов, подготовка забоев | U2: Чистка | V2: Итого технологические перерывы | X2: Планируемые | AC2: Итого планируемые простои | AD2: Не планируемые | AW2: Итого не планируемые простои
X3: Приём - передачи смены, ежесменное обслуживание | Y3: Обед | Z3: Резерв, без бригады | AA3: ППР | AB3: ТО | AD3: Аварийный ремонт | AL3: Итого аварийный ремонт | AM3: Отсутствие | AR3: Итого отсутствие | AS3: Условия | AU3: Итого условия | AV3: Прочие
AD4: ДВС | AE4: Трансмиссия | AF4: Ходовая часть | AG4: Навесное оборудование | AH4: Электрич. часть | AI4: Гидравлич. часть | AJ4: Автошины | AK4: Прочие | AM4: Отсутствие транспорта | AN4: Отсутствие фронта работ | AO4: Отсутствие запчастей | AP4: Отсутствие рем. Персонала | AQ4: Отсутствие эл.энергии, ГСМ | AS4: Климатические | AT4: Дорожные
A5: 1 | B5: 2 | C5: 3 | D5: 4 | E5: 5 | F5: 6 | G5: 7 | H5: 8 | I5: 9 | J5: 10 | K5: 11 | L5: 12 | M5: 13 | N5: 14 | O5: 15 | P5: 16 | Q5: 17 | R5: 18 | S5: 19 | T5: 20 | U5: 21 | V5: 22 | W5: 23 | X5: 24 | Y5: 25 | Z5: 26 | AA5: 27 | AB5: 28 | AC5: 29 | AD5: 30 | AE5: 31 | AF5: 32 | AG5: 33 | AH5: 34 | AI5: 35 | AJ5: 36 | AK5: 37 | AL5: 38 | AM5: 39 | AN5: 40 | AO5: 41 | AP5: 42 | AQ5: 43 | AR5: 44 | AS5: 45 | AT5: 46 | AU5: 47 | AV5: 48 | AW5: 49 | AX5: 50 | AY5: 51
A6: Экскаваторы всего | B6: =SUM(B7:B9) -> 0 | E6: м3 | F6: =SUM(F7:F9) -> 0 | G6: =SUM(G7:G9) -> 0 | H6: =SUM(H7:H9) -> 0 | I6: =SUM(I7:I9) -> 0 | J6: =SUM(J7:J9) -> 0 | K6: =SUM(K7:K9) -> 0 | O6: =SUM(O7:O9) -> 0 | P6: =SUM(P7:P9) -> 0 | Q6: =SUM(Q7:Q9) -> 0 | R6: =SUM(R7:R9) -> 0 | T6: =SUM(T7:T9) -> 0 | U6: =SUM(U7:U9) -> 0 | V6: =SUM(V7:V9) -> 0 | W6: =SUM(W7:W9) -> 0 | X6: =SUM(X7:X9) -> 0 | Y6: =SUM(Y7:Y9) -> 0 | Z6: =SUM(Z7:Z9) -> 0 | AA6: =SUM(AA7:AA9) -> 0 | ... AY6: =SUM(AY7:AY9) -> 0
A7: =Экскаваторы!C39 -> HITACHI ZX-470 № 24 (Обр) | B7: =IF(Экскаваторы!AB39>0,1,0) -> 0 | E7: м3 | F7: =(Экскаваторы!J39+Экскаваторы!F39)*'Сводка внутр.'!$P$1 -> 0 | G7: =Экскаваторы!S39+Экскаваторы!T39 -> 0 | H7: =Экскаваторы!Q39 -> 0 | I7: =G7+H7 -> 0 | J7: =Экскаваторы!N39 -> 0 | K7: =Экскаваторы!O39 -> 0 | L7: =IF(K7=0,0,K7/J7) -> 0 | M7: =IF($B$29="зима",C35,E35) -> 26.190476 | N7: =IF(L7=0,0,(1-L7/M7)*100) -> 0 | P7: =Экскаваторы!V39 -> 0 | Q7: =Экскаваторы!W39 -> 0 | R7: =Экскаваторы!X39 -> 0 | T7: =Экскаваторы!Y39 -> 0 | U7: =Экскаваторы!Z39 -> 0 | V7: =SUM(P7:U7) -> 0 | W7: =V7+I7 -> 0 | X7: =Экскаваторы!AC39 -> 0 | Y7: =Экскаваторы!AD39 -> 0 | Z7: =Экскаваторы!AE39 -> 0 | AA7: =Экскаваторы!AF39 -> 0 | AB7: =Экскаваторы!AG39 -> 0 | AC7: =SUM(X7:AB7) -> 0 | AD7: =Экскаваторы!AI39 -> 0 | AE7: =Экскаваторы!AJ39 -> 0 | AF7: =Экскаваторы!AK39 -> 0 | AG7: =Экскаваторы!AL39 -> 0 | AH7: =Экскаваторы!AM39 -> 0 | AI7: =Экскаваторы!AN39 -> 0 | AJ7: =Экскаваторы!AO39 -> 0 | AK7: =Экскаваторы!AP39 -> 0 | AL7: =SUM(AD7:AK7) -> 0 | AM7: =Экскаваторы!AR39 -> 0 | AN7: =Экскаваторы!AS39 -> 0 | AO7: =Экскаваторы!AT39 -> 0 | AP7: =Экскаваторы!AU39 -> 0 | AQ7: =Экскаваторы!AV39 -> 0 | AR7: =SUM(AM7:AQ7) -> 0 | AS7: =Экскаваторы!AX39 -> 0 | AT7: =Экскаваторы!AY39 -> 0 | AU7: =SUM(AS7:AT7) -> 0 | AV7: =Экскаваторы!BA39 -> 0 | AW7: =AV7+AU7+AR7+AL7 -> 0 | AX7: =AW7+AC7 -> 0 | AY7: =AX7+W7 -> 0
A8: =Экскаваторы!C38 -> HITACHI EX-1200 № 25 (Обр) | B8: =IF(Экскаваторы!AB38>0,1,0) -> 0 | E8: м3 | F8: =(Экскаваторы!J38+Экскаваторы!F38)*'Сводка внутр.'!$P$1 -> 0 | G8: =Экскаваторы!S38+Экскаваторы!T38 -> 0 | H8: =Экскаваторы!Q38 -> 0 | I8: =G8+H8 -> 0 | J8: =Экскаваторы!N38 -> 0 | K8: =Экскаваторы!O38 -> 0 | L8: =IF(K8=0,0,K8/J8) -> 0 | M8: =IF($B$29="зима",C37,E37) -> 85.714286 | N8: =IF(L8=0,0,(1-L8/M8)*100) -> 0 | P8: =Экскаваторы!V38 -> 0 | Q8: =Экскаваторы!W38 -> 0 | R8: =Экскаваторы!X38 -> 0 | T8: =Экскаваторы!Y38 -> 0 | U8: =Экскаваторы!Z38 -> 0 | V8: =SUM(P8:U8) -> 0 | W8: =V8+I8 -> 0 | X8: =Экскаваторы!AC38 -> 0 | Y8: =Экскаваторы!AD38 -> 0 | Z8: =Экскаваторы!AE38 -> 0 | AA8: =Экскаваторы!AF38 -> 0 | AB8: =Экскаваторы!AG38 -> 0 | AC8: =SUM(X8:AB8) -> 0 | AD8: =Экскаваторы!AI38 -> 0 | AE8: =Экскаваторы!AJ38 -> 0 | AF8: =Экскаваторы!AK38 -> 0 | AG8: =Экскаваторы!AL38 -> 0 | AH8: =Экскаваторы!AM38 -> 0 | AI8: =Экскаваторы!AN38 -> 0 | AJ8: =Экскаваторы!AO38 -> 0 | AK8: =Экскаваторы!AP38 -> 0 | AL8: =SUM(AD8:AK8) -> 0 | AM8: =Экскаваторы!AR38 -> 0 | AN8: =Экскаваторы!AS38 -> 0 | AO8: =Экскаваторы!AT38 -> 0 | AP8: =Экскаваторы!AU38 -> 0 | AQ8: =Экскаваторы!AV38 -> 0 | AR8: =SUM(AM8:AQ8) -> 0 | AS8: =Экскаваторы!AX38 -> 0 | AT8: =Экскаваторы!AY38 -> 0 | AU8: =SUM(AS8:AT8) -> 0 | AV8: =Экскаваторы!BA38 -> 0 | AW8: =AV8+AU8+AR8+AL8 -> 0 | AX8: =AW8+AC8 -> 0 | AY8: =AX8+W8 -> 0
A9: =Экскаваторы!C40 -> ЭШ 6/45 №17 | B9: =IF(Экскаваторы!AB40>0,1,0) -> 0 | E9: м3 | F9: =Экскаваторы!J40 -> 0 | G9: =Экскаваторы!S40+Экскаваторы!T40 -> 0 | H9: =Экскаваторы!Q40 -> 0 | I9: =G9+H9 -> 0 | P9: =Экскаваторы!V40 -> 0 | Q9: =Экскаваторы!W40 -> 0 | R9: =Экскаваторы!X40 -> 0 | T9: =Экскаваторы!Y40 -> 0 | U9: =Экскаваторы!Z40 -> 0 | V9: =SUM(P9:U9) -> 0 | W9: =V9+I9 -> 0 | X9: =Экскаваторы!AC40 -> 0 | Y9: =Экскаваторы!AD40 -> 0 | Z9: =Экскаваторы!AE40 -> 0 | AA9: =Экскаваторы!AF40 -> 0 | AB9: =Экскаваторы!AG40 -> 0 | AC9: =SUM(X9:AB9) -> 0 | AD9: =Экскаваторы!AI40 -> 0 | AE9: =Экскаваторы!AJ40 -> 0 | AF9: =Экскаваторы!AK40 -> 0 | AG9: =Экскаваторы!AL40 -> 0 | AH9: =Экскаваторы!AM40 -> 0 | AI9: =Экскаваторы!AN40 -> 0 | AJ9: =Экскаваторы!AO40 -> 0 | AK9: =Экскаваторы!AP40 -> 0 | AL9: =SUM(AD9:AK9) -> 0 | AM9: =Экскаваторы!AR40 -> 0 | AN9: =Экскаваторы!AS40 -> 0 | AO9: =Экскаваторы!AT40 -> 0 | AP9: =Экскаваторы!AU40 -> 0 | AQ9: =Экскаваторы!AV40 -> 0 | AR9: =SUM(AM9:AQ9) -> 0 | AS9: =Экскаваторы!AX40 -> 0 | AT9: =Экскаваторы!AY40 -> 0 | AU9: =SUM(AS9:AT9) -> 0 | AV9: =Экскаваторы!BA40 -> 0 | AW9: =AV9+AU9+AR9+AL9 -> 0 | AX9: =AW9+AC9 -> 0 | AY9: =AX9+W9 -> 0
A10: БелАЗ-754701 №30 | B10: =IF(('БелАЗы '!W7+'БелАЗы '!W18)>0,1,0) -> 0 | C10: ='БелАЗы '!K7+'БелАЗы '!K18 -> 0 | D10: =IF(('БелАЗы '!K7+'БелАЗы '!K18)=0,0,('БелАЗы '!K7*'БелАЗы '!L7+'БелАЗы '!K18*'БелАЗы '!L18)/('БелАЗы '!K7+'БелАЗы '!K18)) -> 0 | E10: м3хкм | F10: ='БелАЗы '!H7*'БелАЗы '!L7+'БелАЗы '!H18*'БелАЗы '!L18 -> 0 | I10: ='БелАЗы '!Q7+'БелАЗы '!Q18 -> 0 | J10: ='БелАЗы '!M7+'БелАЗы '!M18 -> 0 | K10: ='БелАЗы '!N7+'БелАЗы '!N18 -> 0 | L10: =IF(K10=0,0,K10/J10*100) -> 0 | M10: =IF($B$29="зима",C38,E38) -> 214.28571 | N10: =IF(L10=0,0,(1-L10/M10)*100) -> 0 | O10: ='БелАЗы '!O7+'БелАЗы '!O18 -> 0 | P10: ='БелАЗы '!R7+'БелАЗы '!R18 -> 0 | Q10: ='БелАЗы '!S7+'БелАЗы '!S18 -> 0 | S10: ='БелАЗы '!T7+'БелАЗы '!T18 -> 0 | U10: ='БелАЗы '!U7+'БелАЗы '!U18 -> 0 | V10: =SUM(P10:U10) -> 0 | W10: =V10+I10 -> 0 | X10: ='БелАЗы '!X7+'БелАЗы '!X18 -> 0 | Y10: ='БелАЗы '!Y7+'БелАЗы '!Y18 -> 0 | Z10: ='БелАЗы '!Z7+'БелАЗы '!Z18 -> 0 | AA10: ='БелАЗы '!AA7+'БелАЗы '!AA18 -> 0 | AB10: ='БелАЗы '!AB7+'БелАЗы '!AB18 -> 0 | AC10: =SUM(X10:AB10) -> 0 | AD10: ='БелАЗы '!AD7+'БелАЗы '!AD18 -> 0 | AE10: ='БелАЗы '!AE7+'БелАЗы '!AE18 -> 0 | AF10: ='БелАЗы '!AF7+'БелАЗы '!AF18 -> 0 | AG10: ='БелАЗы '!AG7+'БелАЗы '!AG18 -> 0 | AH10: ='БелАЗы '!AH7+'БелАЗы '!AH18 -> 0 | AI10: ='БелАЗы '!AI7+'БелАЗы '!AI18 -> 0 | AJ10: ='БелАЗы '!AJ7+'БелАЗы '!AJ18 -> 0 | AK10: ='БелАЗы '!AK7+'БелАЗы '!AK18 -> 0 | AL10: =SUM(AD10:AK10) -> 0 | AN10: ='БелАЗы '!AM7+'БелАЗы '!AM18 -> 0 | AO10: ='БелАЗы '!AN7+'БелАЗы '!AN18 -> 0 | AP10: ='БелАЗы '!AO7+'БелАЗы '!AO18 -> 0 | AQ10: ='БелАЗы '!AP7+'БелАЗы '!AP18 -> 0 | AR10: =SUM(AM10:AQ10) -> 0 | AS10: ='БелАЗы '!AR7+'БелАЗы '!AR18 -> 0 | AT10: ='БелАЗы '!AS7+'БелАЗы '!AS18 -> 0 | AU10: =SUM(AS10:AT10) -> 0 | AV10: ='БелАЗы '!AU7+'БелАЗы '!AU18 -> 0 | AW10: =AV10+AU10+AR10+AL10 -> 0 | AX10: =AW10+AC10 -> 0 | AY10: =AX10+W10 -> 0
A11: БелАЗ-754701 №32 | B11: =IF(('БелАЗы '!W8+'БелАЗы '!W19)>0,1,0) -> 0 | C11: ='БелАЗы '!K8+'БелАЗы '!K19 -> 0 | D11: =IF(('БелАЗы '!K8+'БелАЗы '!K19)=0,0,('БелАЗы '!K8*'БелАЗы '!L8+'БелАЗы '!K19*'БелАЗы '!L19)/('БелАЗы '!K8+'БелАЗы '!K19)) -> 0 | E11: м3хкм | F11: ='БелАЗы '!H8*'БелАЗы '!L8+'БелАЗы '!H19*'БелАЗы '!L19 -> 0 | I11: ='БелАЗы '!Q8+'БелАЗы '!Q19 -> 0 | J11: ='БелАЗы '!M8+'БелАЗы '!M19 -> 0 | K11: ='БелАЗы '!N8+'БелАЗы '!N19 -> 0 | L11: =IF(K11=0,0,K11/J11*100) -> 0 | M11: =IF($B$29="зима",C39,E39) -> 214.28571 | N11: =IF(L11=0,0,(1-L11/M11)*100) -> 0 | O11: ='БелАЗы '!O8+'БелАЗы '!O19 -> 0 | P11: ='БелАЗы '!R8+'БелАЗы '!R19 -> 0 | Q11: ='БелАЗы '!S8+'БелАЗы '!S19 -> 0 | S11: ='БелАЗы '!T8+'БелАЗы '!T19 -> 0 | U11: ='БелАЗы '!U8+'БелАЗы '!U19 -> 0 | V11: =SUM(P11:U11) -> 0 | W11: =V11+I11 -> 0 | X11: ='БелАЗы '!X8+'БелАЗы '!X19 -> 0 | Y11: ='БелАЗы '!Y8+'БелАЗы '!Y19 -> 0 | Z11: ='БелАЗы '!Z8+'БелАЗы '!Z19 -> 0 | AA11: ='БелАЗы '!AA8+'БелАЗы '!AA19 -> 0 | AB11: ='БелАЗы '!AB8+'БелАЗы '!AB19 -> 0 | AC11: =SUM(X11:AB11) -> 0 | AD11: ='БелАЗы '!AD8+'БелАЗы '!AD19 -> 0 | AE11: ='БелАЗы '!AE8+'БелАЗы '!AE19 -> 0 | AF11: ='БелАЗы '!AF8+'БелАЗы '!AF19 -> 0 | AG11: ='БелАЗы '!AG8+'БелАЗы '!AG19 -> 0 | AH11: ='БелАЗы '!AH8+'БелАЗы '!AH19 -> 0 | AI11: ='БелАЗы '!AI8+'БелАЗы '!AI19 -> 0 | AJ11: ='БелАЗы '!AJ8+'БелАЗы '!AJ19 -> 0 | AK11: ='БелАЗы '!AK8+'БелАЗы '!AK19 -> 0 | AL11: =SUM(AD11:AK11) -> 0 | AN11: ='БелАЗы '!AM8+'БелАЗы '!AM19 -> 0 | AO11: ='БелАЗы '!AN8+'БелАЗы '!AN19 -> 0 | AP11: ='БелАЗы '!AO8+'БелАЗы '!AO19 -> 0 | AQ11: ='БелАЗы '!AP8+'БелАЗы '!AP19 -> 0 | AR11: =SUM(AM11:AQ11) -> 0 | AS11: ='БелАЗы '!AR8+'БелАЗы '!AR19 -> 0 | AT11: ='БелАЗы '!AS8+'БелАЗы '!AS19 -> 0 | AU11: =SUM(AS11:AT11) -> 0 | AV11: ='БелАЗы '!AU8+'БелАЗы '!AU19 -> 0 | AW11: =AV11+AU11+AR11+AL11 -> 0 | AX11: =AW11+AC11 -> 0 | AY11: =AX11+W11 -> 0
A12: БелАЗ-754701 №35 | B12: =IF(('БелАЗы '!W9+'БелАЗы '!W20)>0,1,0) -> 0 | C12: ='БелАЗы '!K9+'БелАЗы '!K20 -> 0 | D12: =IF(('БелАЗы '!K9+'БелАЗы '!K20)=0,0,('БелАЗы '!K9*'БелАЗы '!L9+'БелАЗы '!K20*'БелАЗы '!L20)/('БелАЗы '!K9+'БелАЗы '!K20)) -> 0 | E12: м3хкм | F12: ='БелАЗы '!H9*'БелАЗы '!L9+'БелАЗы '!H20*'БелАЗы '!L20 -> 0 | I12: ='БелАЗы '!Q9+'БелАЗы '!Q20 -> 0 | J12: ='БелАЗы '!M9+'БелАЗы '!M20 -> 0 | K12: ='БелАЗы '!N9+'БелАЗы '!N20 -> 0 | L12: =IF(K12=0,0,K12/J12*100) -> 0 | M12: =IF($B$29="зима",C39,E39) -> 214.28571 | N12: =IF(L12=0,0,(1-L12/M12)*100) -> 0 | O12: ='БелАЗы '!O9+'БелАЗы '!O20 -> 0 | P12: ='БелАЗы '!R9+'БелАЗы '!R20 -> 0 | Q12: ='БелАЗы '!S9+'БелАЗы '!S20 -> 0 | S12: ='БелАЗы '!T9+'БелАЗы '!T20 -> 0 | U12: ='БелАЗы '!U9+'БелАЗы '!U20 -> 0 | V12: =SUM(P12:U12) -> 0 | W12: =V12+I12 -> 0 | X12: ='БелАЗы '!X9+'БелАЗы '!X20 -> 0 | Y12: ='БелАЗы '!Y9+'БелАЗы '!Y20 -> 0 | Z12: ='БелАЗы '!Z9+'БелАЗы '!Z20 -> 0 | AA12: ='БелАЗы '!AA9+'БелАЗы '!AA20 -> 0 | AB12: ='БелАЗы '!AB9+'БелАЗы '!AB20 -> 0 | AC12: =SUM(X12:AB12) -> 0 | AD12: ='БелАЗы '!AD9+'БелАЗы '!AD20 -> 0 | AE12: ='БелАЗы '!AE9+'БелАЗы '!AE20 -> 0 | AF12: ='БелАЗы '!AF9+'БелАЗы '!AF20 -> 0 | AG12: ='БелАЗы '!AG9+'БелАЗы '!AG20 -> 0 | AH12: ='БелАЗы '!AH9+'БелАЗы '!AH20 -> 0 | AI12: ='БелАЗы '!AI9+'БелАЗы '!AI20 -> 0 | AJ12: ='БелАЗы '!AJ9+'БелАЗы '!AJ20 -> 0 | AK12: ='БелАЗы '!AK9+'БелАЗы '!AK20 -> 0 | AL12: =SUM(AD12:AK12) -> 0 | AN12: ='БелАЗы '!AM9+'БелАЗы '!AM20 -> 0 | AO12: ='БелАЗы '!AN9+'БелАЗы '!AN20 -> 0 | AP12: ='БелАЗы '!AO9+'БелАЗы '!AO20 -> 0 | AQ12: ='БелАЗы '!AP9+'БелАЗы '!AP20 -> 0 | AR12: =SUM(AM12:AQ12) -> 0 | AS12: ='БелАЗы '!AR9+'БелАЗы '!AR20 -> 0 | AT12: ='БелАЗы '!AS9+'БелАЗы '!AS20 -> 0 | AU12: =SUM(AS12:AT12) -> 0 | AV12: ='БелАЗы '!AU9+'БелАЗы '!AU20 -> 0 | AW12: =AV12+AU12+AR12+AL12 -> 0 | AX12: =AW12+AC12 -> 0 | AY12: =AX12+W12 -> 0
A13: Всего БелАЗы | B13: =SUM(B10:B12) -> 0 | C13: =SUM(C10:C12) -> 0 | D13: =IF('БелАЗы '!K30=0,0,('БелАЗы '!K7*'БелАЗы '!L7+'БелАЗы '!K9*'БелАЗы '!L9+'БелАЗы '!K18*'БелАЗы '!L18+'БелАЗы '!K20*'БелАЗы '!L20)/'БелАЗы '!K30) -> 0 | E13: м3хкм | F13: =SUM(F10:F12) -> 0 | I13: =SUM(I10:I12) -> 0 | J13: =SUM(J10:J12) -> 0 | K13: =SUM(K10:K12) -> 0 | O13: =SUM(O10:O12) -> 0 | P13: =SUM(P10:P12) -> 0 | Q13: =SUM(Q10:Q12) -> 0 | S13: =SUM(S10:S12) -> 0 | U13: =SUM(U10:U12) -> 0 | V13: =SUM(V10:V12) -> 0 | W13: =SUM(W10:W12) -> 0 | X13: =SUM(X10:X12) -> 0 | Y13: =SUM(Y10:Y12) -> 0 | Z13: =SUM(Z10:Z12) -> 0 | AA13: =SUM(AA10:AA12) -> 0 | AB13: =SUM(AB10:AB12) -> 0 | ... AL13: =SUM(AL10:AL12) -> 0 | AN13: =SUM(AN10:AN12) -> 0 | AO13: =SUM(AO10:AO12) -> 0 | AP13: =SUM(AP10:AP12) -> 0 | AQ13: =SUM(AQ10:AQ12) -> 0 | AR13: =SUM(AR10:AR12) -> 0 | AS13: =SUM(AS10:AS12) -> 0 | AT13: =SUM(AT10:AT12) -> 0 | AU13: =SUM(AU10:AU12) -> 0 | ... AY13: =SUM(AY10:AY12) -> 0
A14: Бульдозеры всего | B14: =SUM(B15:B16) -> 0 | F14: =SUM(F15:F16) -> 0 | I14: =SUM(I15:I16) -> 0 | J14: =SUM(J15:J16) -> 0 | K14: =SUM(K15:K16) -> 0 | O14: =SUM(O15:O16) -> 0 | P14: =SUM(P15:P16) -> 0 | Q14: =SUM(Q15:Q16) -> 0 | R14: =SUM(R15:R16) -> 0 | U14: =SUM(U15:U16) -> 0 | V14: =SUM(V15:V16) -> 0 | W14: =SUM(W15:W16) -> 0 | X14: =SUM(X15:X16) -> 0 | Y14: =SUM(Y15:Y16) -> 0 | Z14: =SUM(Z15:Z16) -> 0 | AA14: =SUM(AA15:AA16) -> 0 | AB14: =SUM(AB15:AB16) -> 0 | ... AI14: =SUM(AI15:AI16) -> 0 | AK14: =SUM(AK15:AK16) -> 0 | AL14: =SUM(AL15:AL16) -> 0 | AN14: =SUM(AN15:AN16) -> 0 | AO14: =SUM(AO15:AO16) -> 0 | AP14: =SUM(AP15:AP16) -> 0 | AQ14: =SUM(AQ15:AQ16) -> 0 | AR14: =SUM(AR15:AR16) -> 0 | AS14: =SUM(AS15:AS16) -> 0 | AT14: =SUM(AT15:AT16) -> 0 | AU14: =SUM(AU15:AU16) -> 0 | ... AY14: =SUM(AY15:AY16) -> 0
A15: =Бульдозеры!C15 -> Caterpillar D-9R №36 | B15: =IF(Бульдозеры!N15>0,1,0) -> 0 | F15: =Бульдозеры!AQ15+Бульдозеры!AR15 -> 0 | I15: =Бульдозеры!H15 -> 0 | J15: =Бульдозеры!D15 -> 0 | K15: =Бульдозеры!E15 -> 0 | L15: =IF(K15=0,0,K15/J15) -> 0 | M15: =IF($B$29="зима",C54,E54) -> 32.142857 | N15: =IF(L15=0,0,(1-L15/M15)*100) -> 0 | O15: =Бульдозеры!F15 -> 0 | P15: =Бульдозеры!I15 -> 0 | Q15: =Бульдозеры!J15 -> 0 | R15: =Бульдозеры!K15 -> 0 | U15: =Бульдозеры!L15 -> 0 | V15: =SUM(P15:Q15)+U15 -> 0 | W15: =V15+I15+R15 -> 0 | X15: =Бульдозеры!O15 -> 0 | Y15: =Бульдозеры!P15 -> 0 | Z15: =Бульдозеры!Q15 -> 0 | AA15: =Бульдозеры!R15 -> 0 | AB15: =Бульдозеры!S15 -> 0 | AC15: =SUM(X15:AB15) -> 0 | AD15: =Бульдозеры!U15 -> 0 | AE15: =Бульдозеры!V15 -> 0 | AF15: =Бульдозеры!W15 -> 0 | AG15: =Бульдозеры!X15 -> 0 | AH15: =Бульдозеры!Y15 -> 0 | AI15: =Бульдозеры!Z15 -> 0 | AK15: =Бульдозеры!AA15 -> 0 | AL15: =SUM(AD15:AK15) -> 0 | AN15: =Бульдозеры!AC15 -> 0 | AO15: =Бульдозеры!AD15 -> 0 | AP15: =Бульдозеры!AE15 -> 0 | AQ15: =Бульдозеры!AF15 -> 0 | AR15: =SUM(AM15:AQ15) -> 0 | AS15: =Бульдозеры!AH15 -> 0 | AT15: =Бульдозеры!AI15 -> 0 | AU15: =SUM(AS15:AT15) -> 0 | AV15: =Бульдозеры!AK15 -> 0 | AW15: =AV15+AU15+AR15+AL15 -> 0 | AX15: =AW15+AC15 -> 0 | AY15: =AX15+W15 -> 0
A16: =Бульдозеры!C16 -> Caterpillar D-6R №28 | B16: =IF(Бульдозеры!N16>0,1,0) -> 0 | F16: =Бульдозеры!AQ16+Бульдозеры!AR16 -> 0 | I16: =Бульдозеры!H16 -> 0 | J16: =Бульдозеры!D16 -> 0 | K16: =Бульдозеры!E16 -> 0 | L16: =IF(K16=0,0,K16/J16) -> 0 | M16: =IF($B$29="зима",C57,E57) -> 16.666667 | N16: =IF(L16=0,0,(1-L16/M16)*100) -> 0 | O16: =Бульдозеры!F16 -> 0 | P16: =Бульдозеры!I16 -> 0 | Q16: =Бульдозеры!J16 -> 0 | R16: =Бульдозеры!K16 -> 0 | U16: =Бульдозеры!L16 -> 0 | V16: =SUM(P16:Q16)+U16 -> 0 | W16: =V16+I16+R16 -> 0 | X16: =Бульдозеры!O16 -> 0 | Y16: =Бульдозеры!P16 -> 0 | Z16: =Бульдозеры!Q16 -> 0 | AA16: =Бульдозеры!R16 -> 0 | AB16: =Бульдозеры!S16 -> 0 | AC16: =SUM(X16:AB16) -> 0 | AD16: =Бульдозеры!U16 -> 0 | AE16: =Бульдозеры!V16 -> 0 | AF16: =Бульдозеры!W16 -> 0 | AG16: =Бульдозеры!X16 -> 0 | AH16: =Бульдозеры!Y16 -> 0 | AI16: =Бульдозеры!Z16 -> 0 | AK16: =Бульдозеры!AA16 -> 0 | AL16: =SUM(AD16:AK16) -> 0 | AN16: =Бульдозеры!AC16 -> 0 | AO16: =Бульдозеры!AD16 -> 0 | AP16: =Бульдозеры!AE16 -> 0 | AQ16: =Бульдозеры!AF16 -> 0 | AR16: =SUM(AM16:AQ16) -> 0 | AS16: =Бульдозеры!AH16 -> 0 | AT16: =Бульдозеры!AI16 -> 0 | AU16: =SUM(AS16:AT16) -> 0 | AV16: =Бульдозеры!AK16 -> 0 | AW16: =AV16+AU16+AR16+AL16 -> 0 | AX16: =AW16+AC16 -> 0 | AY16: =AX16+W16 -> 0
A17: Автогрейдеры всего | B17: =SUM(B18:B18) -> 0 | E17: км | F17: =SUM(F18:F18) -> 0 | I17: =SUM(I18:I18) -> 0 | J17: =SUM(J18:J18) -> 0 | K17: =SUM(K18:K18) -> 0 | O17: =SUM(O18:O18) -> 0 | P17: =SUM(P18:P18) -> 0 | Q17: =SUM(Q18:Q18) -> 0 | R17: =SUM(R18:R18) -> 0 | U17: =SUM(U18:U18) -> 0 | V17: =SUM(V18:V18) -> 0 | W17: =SUM(W18:W18) -> 0 | X17: =SUM(X18:X18) -> 0 | Y17: =SUM(Y18:Y18) -> 0 | Z17: =SUM(Z18:Z18) -> 0 | AA17: =SUM(AA18:AA18) -> 0 | AB17: =SUM(AB18:AB18) -> 0 | ... AI17: =SUM(AI18:AI18) -> 0 | AK17: =SUM(AK18:AK18) -> 0 | AL17: =SUM(AL18:AL18) -> 0 | AN17: =SUM(AN18:AN18) -> 0 | AO17: =SUM(AO18:AO18) -> 0 | AP17: =SUM(AP18:AP18) -> 0 | AQ17: =SUM(AQ18:AQ18) -> 0 | AR17: =SUM(AR18:AR18) -> 0 | AS17: =SUM(AS18:AS18) -> 0 | AT17: =SUM(AT18:AT18) -> 0 | AU17: =SUM(AU18:AU18) -> 0 | ... AY17: =SUM(AY18:AY18) -> 0
A18: =Бульдозеры!C9 -> Caterpillar 140М №4 | B18: =IF(Бульдозеры!N17>0,1,0) -> 0 | E18: км | F18: =Бульдозеры!AQ18+Бульдозеры!AR17 -> 0 | I18: =Бульдозеры!H17 -> 0 | J18: =Бульдозеры!D17 -> 0 | K18: =Бульдозеры!E17 -> 0 | L18: =IF(K18=0,0,K18/J18) -> 0 | M18: =IF($B$29="зима",C61,E61) -> 12.738095 | N18: =IF(L18=0,0,(1-L18/M18)*100) -> 0 | O18: =Бульдозеры!F17 -> 0 | P18: =Бульдозеры!I17 -> 0 | Q18: =Бульдозеры!J17 -> 0 | R18: =Бульдозеры!K17 -> 0 | U18: =Бульдозеры!L17 -> 0 | V18: =SUM(P18:Q18)+U18 -> 0 | W18: =V18+I18 -> 0 | X18: =Бульдозеры!O17 -> 0 | Y18: =Бульдозеры!P17 -> 0 | Z18: =Бульдозеры!Q17 -> 0 | AA18: =Бульдозеры!R17 -> 0 | AB18: =Бульдозеры!S17 -> 0 | AC18: =SUM(X18:AB18) -> 0 | AD18: =Бульдозеры!U17 -> 0 | AE18: =Бульдозеры!V17 -> 0 | AF18: =Бульдозеры!W17 -> 0 | AG18: =Бульдозеры!X17 -> 0 | AH18: =Бульдозеры!Y17 -> 0 | AI18: =Бульдозеры!Z17 -> 0 | AK18: =Бульдозеры!AA17 -> 0 | AL18: =SUM(AD18:AK18) -> 0 | AN18: =Бульдозеры!AC17 -> 0 | AO18: =Бульдозеры!AD17 -> 0 | AP18: =Бульдозеры!AE17 -> 0 | AQ18: =Бульдозеры!AF17 -> 0 | AR18: =SUM(AM18:AQ18) -> 0 | AS18: =Бульдозеры!AH17 -> 0 | AT18: =Бульдозеры!AI17 -> 0 | AU18: =SUM(AS18:AT18) -> 0 | AV18: =Бульдозеры!AK17 -> 0 | AW18: =AV18+AU18+AR18+AL18 -> 0 | AX18: =AW18+AC18 -> 0 | AY18: =AX18+W18 -> 0
A19: =Бульдозеры!C10 -> Komatsu-825 №5 | B19: =IF(Бульдозеры!N18>0,1,0) -> 0 | E19: км | F19: =Бульдозеры!AQ19+Бульдозеры!AR18 -> 0 | I19: =Бульдозеры!H18 -> 0 | J19: =Бульдозеры!D18 -> 0 | K19: =Бульдозеры!E18 -> 0 | L19: =IF(K19=0,0,K19/J19) -> 0 | M19: =IF($B$29="зима",C60,E60) -> 17.261905 | N19: =IF(L19=0,0,(1-L19/M19)*100) -> 0 | O19: =Бульдозеры!F18 -> 0 | P19: =Бульдозеры!I18 -> 0 | Q19: =Бульдозеры!J18 -> 0 | R19: =Бульдозеры!K18 -> 0 | U19: =Бульдозеры!L18 -> 0 | V19: =SUM(P19:Q19)+U19 -> 0 | W19: =V19+I19 -> 0 | X19: =Бульдозеры!O18 -> 0 | Y19: =Бульдозеры!P18 -> 0 | Z19: =Бульдозеры!Q18 -> 0 | AA19: =Бульдозеры!R18 -> 0 | AB19: =Бульдозеры!S18 -> 0 | AC19: =SUM(X19:AB19) -> 0 | AD19: =Бульдозеры!U18 -> 0 | AE19: =Бульдозеры!V18 -> 0 | AF19: =Бульдозеры!W18 -> 0 | AG19: =Бульдозеры!X18 -> 0 | AH19: =Бульдозеры!Y18 -> 0 | AI19: =Бульдозеры!Z18 -> 0 | AK19: =Бульдозеры!AA18 -> 0 | AL19: =SUM(AD19:AK19) -> 0 | AN19: =Бульдозеры!AC18 -> 0 | AO19: =Бульдозеры!AD18 -> 0 | AP19: =Бульдозеры!AE18 -> 0 | AQ19: =Бульдозеры!AF18 -> 0 | AR19: =SUM(AM19:AQ19) -> 0 | AS19: =Бульдозеры!AH18 -> 0 | AT19: =Бульдозеры!AI18 -> 0 | AU19: =SUM(AS19:AT19) -> 0 | AV19: =Бульдозеры!AK18 -> 0 | AW19: =AV19+AU19+AR19+AL19 -> 0 | AX19: =AW19+AC19 -> 0 | AY19: =AX19+W19 -> 0
A20: Погрузчики всего | B20: =SUM(B21:B27) -> 0 | E20: м3 | F20: =SUM(F21:F27) -> 0 | G20: =SUM(G21:G27) -> 0 | H20: =SUM(H21:H27) -> 0 | I20: =SUM(I21:I27) -> 0 | J20: =SUM(J21:J27) -> 0 | K20: =SUM(K21:K27) -> 0 | O20: =SUM(O21:O27) -> 0 | P20: =SUM(P21:P27) -> 0 | Q20: =SUM(Q21:Q27) -> 0 | R20: =SUM(R21:R27) -> 0 | T20: =SUM(T21:T27) -> 0 | U20: =SUM(U21:U27) -> 0 | V20: =SUM(V21:V27) -> 0 | W20: =SUM(W21:W27) -> 0 | X20: =SUM(X21:X27) -> 0 | Y20: =SUM(Y21:Y27) -> 0 | Z20: =SUM(Z21:Z27) -> 0 | AA20: =SUM(AA21:AA27) -> 0 | ... AY20: =SUM(AY21:AY27) -> 0
A21: CAT-962H №15 | B21: =IF(Экскаваторы!AB41>0,1,0) -> 0 | E21: м3 | F21: =(Экскаваторы!J41+Экскаваторы!F41)*'Сводка внутр.'!$P$1 -> 0 | G21: =Экскаваторы!S41+Экскаваторы!T41 -> 0 | H21: =Экскаваторы!Q41 -> 0 | I21: =G21+H21 -> 0 | J21: =Экскаваторы!N41 -> 0 | K21: =Экскаваторы!O41 -> 0 | L21: =IF(K21=0,0,K21/J21) -> 0 | M21: =IF($B$29="зима",C62,E62) -> 10.714286 | N21: =IF(L21=0,0,(1-L21/M21)*100) -> 0 | P21: =Экскаваторы!V41 -> 0 | Q21: =Экскаваторы!W41 -> 0 | R21: =Экскаваторы!X41 -> 0 | T21: =Экскаваторы!Y41 -> 0 | U21: =Экскаваторы!Z41 -> 0 | V21: =SUM(P21:U21) -> 0 | W21: =V21+I21 -> 0 | X21: =Экскаваторы!AC41 -> 0 | Y21: =Экскаваторы!AD41 -> 0 | Z21: =Экскаваторы!AE41 -> 0 | AA21: =Экскаваторы!AF41 -> 0 | AB21: =Экскаваторы!AG41 -> 0 | AC21: =SUM(X21:AB21) -> 0 | AD21: =Экскаваторы!AI41 -> 0 | AE21: =Экскаваторы!AJ41 -> 0 | AF21: =Экскаваторы!AK41 -> 0 | AG21: =Экскаваторы!AL41 -> 0 | AH21: =Экскаваторы!AM41 -> 0 | AI21: =Экскаваторы!AN41 -> 0 | AJ21: =Экскаваторы!AO41 -> 0 | AK21: =Экскаваторы!AP41 -> 0 | AL21: =SUM(AD21:AK21) -> 0 | AM21: =Экскаваторы!AR41 -> 0 | AN21: =Экскаваторы!AS41 -> 0 | AO21: =Экскаваторы!AT41 -> 0 | AP21: =Экскаваторы!AU41 -> 0 | AQ21: =Экскаваторы!AV41 -> 0 | AR21: =SUM(AM21:AQ21) -> 0 | AS21: =Экскаваторы!AX41 -> 0 | AT21: =Экскаваторы!AY41 -> 0 | AU21: =SUM(AS21:AT21) -> 0 | AV21: =Экскаваторы!BA41 -> 0 | AW21: =AV21+AU21+AR21+AL21 -> 0 | AX21: =AW21+AC21 -> 0 | AY21: =AX21+W21 -> 0
A22: Shantui SL60W №26 | B22: =IF(Экскаваторы!AB42>0,1,0) -> 0 | E22: м3 | F22: =(Экскаваторы!J42+Экскаваторы!F42)*'Сводка внутр.'!$P$1 -> 0 | G22: =Экскаваторы!S42+Экскаваторы!T42 -> 0 | H22: =Экскаваторы!Q42 -> 0 | I22: =G22+H22 -> 0 | J22: =Экскаваторы!N42 -> 0 | K22: =Экскаваторы!O42 -> 0 | L22: =IF(K22=0,0,K22/J22) -> 0 | M22: =IF($B$29="зима",C63,E63) -> 10.714286 | N22: =IF(L22=0,0,(1-L22/M22)*100) -> 0 | P22: =Экскаваторы!V42 -> 0 | Q22: =Экскаваторы!W42 -> 0 | R22: =Экскаваторы!X42 -> 0 | T22: =Экскаваторы!Y42 -> 0 | U22: =Экскаваторы!Z42 -> 0 | V22: =SUM(P22:U22) -> 0 | W22: =V22+I22 -> 0 | X22: =Экскаваторы!AC42 -> 0 | Y22: =Экскаваторы!AD42 -> 0 | Z22: =Экскаваторы!AE42 -> 0 | AA22: =Экскаваторы!AF42 -> 0 | AB22: =Экскаваторы!AG42 -> 0 | AC22: =SUM(X22:AB22) -> 0 | AD22: =Экскаваторы!AI42 -> 0 | AE22: =Экскаваторы!AJ42 -> 0 | AF22: =Экскаваторы!AK42 -> 0 | AG22: =Экскаваторы!AL42 -> 0 | AH22: =Экскаваторы!AM42 -> 0 | AI22: =Экскаваторы!AN42 -> 0 | AJ22: =Экскаваторы!AO42 -> 0 | AK22: =Экскаваторы!AP42 -> 0 | AL22: =SUM(AD22:AK22) -> 0 | AM22: =Экскаваторы!AR42 -> 0 | AN22: =Экскаваторы!AS42 -> 0 | AO22: =Экскаваторы!AT42 -> 0 | AP22: =Экскаваторы!AU42 -> 0 | AQ22: =Экскаваторы!AV42 -> 0 | AR22: =SUM(AM22:AQ22) -> 0 | AS22: =Экскаваторы!AX42 -> 0 | AT22: =Экскаваторы!AY42 -> 0 | AU22: =SUM(AS22:AT22) -> 0 | AV22: =Экскаваторы!BA42 -> 0 | AW22: =AV22+AU22+AR22+AL22 -> 0 | AX22: =AW22+AC22 -> 0 | AY22: =AX22+W22 -> 0
A23: CAT-962H №24 | B23: =IF(Экскаваторы!AB43>0,1,0) -> 0 | E23: м3 | F23: =(Экскаваторы!J43+Экскаваторы!F43)*'Сводка внутр.'!$P$1 -> 0 | G23: =Экскаваторы!S43+Экскаваторы!T43 -> 0 | H23: =Экскаваторы!Q43 -> 0 | I23: =G23+H23 -> 0 | J23: =Экскаваторы!N43 -> 0 | K23: =Экскаваторы!O43 -> 0 | L23: =IF(K23=0,0,K23/J23) -> 0 | M23: =IF($B$29="зима",C64,E64) -> 32.142857 | N23: =IF(L23=0,0,(1-L23/M23)*100) -> 0 | P23: =Экскаваторы!V43 -> 0 | Q23: =Экскаваторы!W43 -> 0 | R23: =Экскаваторы!X43 -> 0 | T23: =Экскаваторы!Y43 -> 0 | U23: =Экскаваторы!Z43 -> 0 | V23: =SUM(P23:U23) -> 0 | W23: =V23+I23 -> 0 | X23: =Экскаваторы!AC43 -> 0 | Y23: =Экскаваторы!AD43 -> 0 | Z23: =Экскаваторы!AE43 -> 0 | AA23: =Экскаваторы!AF43 -> 0 | AB23: =Экскаваторы!AG43 -> 0 | AC23: =SUM(X23:AB23) -> 0 | AD23: =Экскаваторы!AI43 -> 0 | AE23: =Экскаваторы!AJ43 -> 0 | AF23: =Экскаваторы!AK43 -> 0 | AG23: =Экскаваторы!AL43 -> 0 | AH23: =Экскаваторы!AM43 -> 0 | AI23: =Экскаваторы!AN43 -> 0 | AJ23: =Экскаваторы!AO43 -> 0 | AK23: =Экскаваторы!AP43 -> 0 | AL23: =SUM(AD23:AK23) -> 0 | AM23: =Экскаваторы!AR43 -> 0 | AN23: =Экскаваторы!AS43 -> 0 | AO23: =Экскаваторы!AT43 -> 0 | AP23: =Экскаваторы!AU43 -> 0 | AQ23: =Экскаваторы!AV43 -> 0 | AR23: =SUM(AM23:AQ23) -> 0 | AS23: =Экскаваторы!AX43 -> 0 | AT23: =Экскаваторы!AY43 -> 0 | AU23: =SUM(AS23:AT23) -> 0 | AV23: =Экскаваторы!BA43 -> 0 | AW23: =AV23+AU23+AR23+AL23 -> 0 | AX23: =AW23+AC23 -> 0 | AY23: =AX23+W23 -> 0
A24: CAT-988Н №16 | B24: =IF(Экскаваторы!AB44>0,1,0) -> 0 | E24: м3 | F24: =(Экскаваторы!J44+Экскаваторы!F44)*'Сводка внутр.'!$P$1 -> 0 | G24: =Экскаваторы!S44+Экскаваторы!T44 -> 0 | H24: =Экскаваторы!Q44 -> 0 | I24: =G24+H24 -> 0 | J24: =Экскаваторы!N44 -> 0 | K24: =Экскаваторы!O44 -> 0 | L24: =IF(K24=0,0,K24/J24) -> 0 | M24: =IF($B$29="зима",C66,E66) -> 32.142857 | N24: =IF(L24=0,0,(1-L24/M24)*100) -> 0 | P24: =Экскаваторы!V44 -> 0 | Q24: =Экскаваторы!W44 -> 0 | R24: =Экскаваторы!X44 -> 0 | T24: =Экскаваторы!Y44 -> 0 | U24: =Экскаваторы!Z44 -> 0 | V24: =SUM(P24:U24) -> 0 | W24: =V24+I24 -> 0 | X24: =Экскаваторы!AC44 -> 0 | Y24: =Экскаваторы!AD44 -> 0 | Z24: =Экскаваторы!AE44 -> 0 | AA24: =Экскаваторы!AF44 -> 0 | AB24: =Экскаваторы!AG44 -> 0 | AC24: =SUM(X24:AB24) -> 0 | AD24: =Экскаваторы!AI44 -> 0 | AE24: =Экскаваторы!AJ44 -> 0 | AF24: =Экскаваторы!AK44 -> 0 | AG24: =Экскаваторы!AL44 -> 0 | AH24: =Экскаваторы!AM44 -> 0 | AI24: =Экскаваторы!AN44 -> 0 | AJ24: =Экскаваторы!AO44 -> 0 | AK24: =Экскаваторы!AP44 -> 0 | AL24: =SUM(AD24:AK24) -> 0 | AM24: =Экскаваторы!AR44 -> 0 | AN24: =Экскаваторы!AS44 -> 0 | AO24: =Экскаваторы!AT44 -> 0 | AP24: =Экскаваторы!AU44 -> 0 | AQ24: =Экскаваторы!AV44 -> 0 | AR24: =SUM(AM24:AQ24) -> 0 | AS24: =Экскаваторы!AX44 -> 0 | AT24: =Экскаваторы!AY44 -> 0 | AU24: =SUM(AS24:AT24) -> 0 | AV24: =Экскаваторы!BA44 -> 0 | AW24: =AV24+AU24+AR24+AL24 -> 0 | AX24: =AW24+AC24 -> 0 | AY24: =AX24+W24 -> 0
A25: Shantui SL60W №30 | B25: =IF(Экскаваторы!AB45>0,1,0) -> 0 | E25: м3 | F25: =(Экскаваторы!J45+Экскаваторы!F45)*'Сводка внутр.'!$P$1 -> 0 | G25: =Экскаваторы!S45+Экскаваторы!T45 -> 0 | H25: =Экскаваторы!Q45 -> 0 | I25: =G25+H25 -> 0 | J25: =Экскаваторы!N45 -> 0 | K25: =Экскаваторы!O45 -> 0 | L25: =IF(K25=0,0,K25/J25) -> 0 | M25: =IF($B$29="зима",C66,E66) -> 32.142857 | N25: =IF(L25=0,0,(1-L25/M25)*100) -> 0 | P25: =Экскаваторы!V45 -> 0 | Q25: =Экскаваторы!W45 -> 0 | R25: =Экскаваторы!X45 -> 0 | T25: =Экскаваторы!Y45 -> 0 | U25: =Экскаваторы!Z45 -> 0 | V25: =SUM(P25:U25) -> 0 | W25: =V25+I25 -> 0 | X25: =Экскаваторы!AC45 -> 0 | Y25: =Экскаваторы!AD45 -> 0 | Z25: =Экскаваторы!AE45 -> 0 | AA25: =Экскаваторы!AF45 -> 0 | AB25: =Экскаваторы!AG45 -> 0 | AC25: =SUM(X25:AB25) -> 0 | AD25: =Экскаваторы!AI45 -> 0 | AE25: =Экскаваторы!AJ45 -> 0 | AF25: =Экскаваторы!AK45 -> 0 | AG25: =Экскаваторы!AL45 -> 0 | AH25: =Экскаваторы!AM45 -> 0 | AI25: =Экскаваторы!AN45 -> 0 | AJ25: =Экскаваторы!AO45 -> 0 | AK25: =Экскаваторы!AP45 -> 0 | AL25: =SUM(AD25:AK25) -> 0 | AM25: =Экскаваторы!AR45 -> 0 | AN25: =Экскаваторы!AS45 -> 0 | AO25: =Экскаваторы!AT45 -> 0 | AP25: =Экскаваторы!AU45 -> 0 | AQ25: =Экскаваторы!AV45 -> 0 | AR25: =SUM(AM25:AQ25) -> 0 | AS25: =Экскаваторы!AX45 -> 0 | AT25: =Экскаваторы!AY45 -> 0 | AU25: =SUM(AS25:AT25) -> 0 | AV25: =Экскаваторы!BA45 -> 0 | AW25: =AV25+AU25+AR25+AL25 -> 0 | AX25: =AW25+AC25 -> 0 | AY25: =AX25+W25 -> 0
A26: CAT-988Н №31 | B26: =IF(Экскаваторы!AB46>0,1,0) -> 0 | E26: м3 | F26: =(Экскаваторы!J46+Экскаваторы!F46)*'Сводка внутр.'!$P$1 -> 0 | G26: =Экскаваторы!S46+Экскаваторы!T46 -> 0 | H26: =Экскаваторы!Q46 -> 0 | I26: =G26+H26 -> 0 | J26: =Экскаваторы!N46 -> 0 | K26: =Экскаваторы!O46 -> 0 | L26: =IF(K26=0,0,K26/J26) -> 0 | M26: =IF($B$29="зима",C67,E67) -> 32.142857 | N26: =IF(L26=0,0,(1-L26/M26)*100) -> 0 | P26: =Экскаваторы!V46 -> 0 | Q26: =Экскаваторы!W46 -> 0 | R26: =Экскаваторы!X46 -> 0 | T26: =Экскаваторы!Y46 -> 0 | U26: =Экскаваторы!Z46 -> 0 | V26: =SUM(P26:U26) -> 0 | W26: =V26+I26 -> 0 | X26: =Экскаваторы!AC46 -> 0 | Y26: =Экскаваторы!AD46 -> 0 | Z26: =Экскаваторы!AE46 -> 0 | AA26: =Экскаваторы!AF46 -> 0 | AB26: =Экскаваторы!AG46 -> 0 | AC26: =SUM(X26:AB26) -> 0 | AD26: =Экскаваторы!AI46 -> 0 | AE26: =Экскаваторы!AJ46 -> 0 | AF26: =Экскаваторы!AK46 -> 0 | AG26: =Экскаваторы!AL46 -> 0 | AH26: =Экскаваторы!AM46 -> 0 | AI26: =Экскаваторы!AN46 -> 0 | AJ26: =Экскаваторы!AO46 -> 0 | AK26: =Экскаваторы!AP46 -> 0 | AL26: =SUM(AD26:AK26) -> 0 | AM26: =Экскаваторы!AR46 -> 0 | AN26: =Экскаваторы!AS46 -> 0 | AO26: =Экскаваторы!AT46 -> 0 | AP26: =Экскаваторы!AU46 -> 0 | AQ26: =Экскаваторы!AV46 -> 0 | AR26: =SUM(AM26:AQ26) -> 0 | AS26: =Экскаваторы!AX46 -> 0 | AT26: =Экскаваторы!AY46 -> 0 | AU26: =SUM(AS26:AT26) -> 0 | AV26: =Экскаваторы!BA46 -> 0 | AW26: =AV26+AU26+AR26+AL26 -> 0 | AX26: =AW26+AC26 -> 0 | AY26: =AX26+W26 -> 0
A27: Shantui L58K-B5 №32 | B27: =IF(Экскаваторы!AB47>0,1,0) -> 0 | E27: м3 | F27: =(Экскаваторы!J47+Экскаваторы!F47)*'Сводка внутр.'!$P$1 -> 0 | G27: =Экскаваторы!S47+Экскаваторы!T47 -> 0 | H27: =Экскаваторы!Q47 -> 0 | I27: =G27+H27 -> 0 | J27: =Экскаваторы!N47 -> 0 | K27: =Экскаваторы!O47 -> 0 | L27: =IF(K27=0,0,K27/J27) -> 0 | M27: =IF($B$29="зима",C67,E67) -> 32.142857 | N27: =IF(L27=0,0,(1-L27/M27)*100) -> 0 | P27: =Экскаваторы!V47 -> 0 | Q27: =Экскаваторы!W47 -> 0 | R27: =Экскаваторы!X47 -> 0 | T27: =Экскаваторы!Y47 -> 0 | U27: =Экскаваторы!Z47 -> 0 | V27: =SUM(P27:U27) -> 0 | W27: =V27+I27 -> 0 | X27: =Экскаваторы!AC47 -> 0 | Y27: =Экскаваторы!AD47 -> 0 | Z27: =Экскаваторы!AE47 -> 0 | AA27: =Экскаваторы!AF47 -> 0 | AB27: =Экскаваторы!AG47 -> 0 | AC27: =SUM(X27:AB27) -> 0 | AD27: =Экскаваторы!AI47 -> 0 | AE27: =Экскаваторы!AJ47 -> 0 | AF27: =Экскаваторы!AK47 -> 0 | AG27: =Экскаваторы!AL47 -> 0 | AH27: =Экскаваторы!AM47 -> 0 | AI27: =Экскаваторы!AN47 -> 0 | AJ27: =Экскаваторы!AO47 -> 0 | AK27: =Экскаваторы!AP47 -> 0 | AL27: =SUM(AD27:AK27) -> 0 | AM27: =Экскаваторы!AR47 -> 0 | AN27: =Экскаваторы!AS47 -> 0 | AO27: =Экскаваторы!AT47 -> 0 | AP27: =Экскаваторы!AU47 -> 0 | AQ27: =Экскаваторы!AV47 -> 0 | AR27: =SUM(AM27:AQ27) -> 0 | AS27: =Экскаваторы!AX47 -> 0 | AT27: =Экскаваторы!AY47 -> 0 | AU27: =SUM(AS27:AT27) -> 0 | AV27: =Экскаваторы!BA47 -> 0 | AW27: =AV27+AU27+AR27+AL27 -> 0 | AX27: =AW27+AC27 -> 0 | AY27: =AX27+W27 -> 0
A29: сейчас | B29: зима
B30: зима | D30: лето
A31: нормы расхода на 2014г | B31: кг | C31: л | D31: кг | E31: л
A32: HITACHI EX-1200 № 22 (Обр) | B32: 72 | C32: =B32/0.84 -> 85.714286 | D32: 76 | E32: =D32/0.84 -> 90.47619
A33: HITACHI EX-1200 № 23 (Обр.) | B33: 72 | C33: =B33/0.84 -> 85.714286 | D33: 76 | E33: =D33/0.84 -> 90.47619
A34: HITACHI EX-1200 № 19 (Обр) | B34: 72 | C34: =B34/0.84 -> 85.714286 | D34: 76 | E34: =D34/0.84 -> 90.47619
A35: HITACHI ZX-470 № 24 (Обр) | B35: 22 | C35: =B35/0.84 -> 26.190476 | D35: 24 | E35: =D35/0.84 -> 28.571429
A36: HITACHI ZX-470 № 24 с гидромолотом | B36: 22 | C36: =B36/0.84 -> 26.190476 | D36: 24 | E36: =D36/0.84 -> 28.571429
A37: HITACHI EX-1200 №19 (Обр) с гидромолотом | B37: 72 | C37: =B37/0.84 -> 85.714286 | D37: 76 | E37: =D37/0.84 -> 90.47619
A38: БелАЗ-754701 №30 | B38: 180 | C38: =B38/0.84 -> 214.28571 | D38: 180 | E38: =D38/0.84 -> 214.28571
A39: БелАЗ-754701 №35 | B39: 180 | C39: =B39/0.84 -> 214.28571 | D39: 180 | E39: =D39/0.84 -> 214.28571
A40: Komatsu HD 465-7 №39 | B40: 350 | C40: =B40/0.84 -> 416.66667 | D40: 350 | E40: =D40/0.84 -> 416.66667
A41: Komatsu HD 465-7 №40 | B41: 350 | C41: =B41/0.84 -> 416.66667 | D41: 350 | E41: =D41/0.84 -> 416.66667
...

Sheet рапорт по руде
C1: "Движение руды по складам
C2: Дата | J2: коды | K2: 15 | L2: 1 | M2: 2 | N2: 3 | O2: 4 | P2: 5 | Q2: 6 | R2: 7 | S2: 8 | T2: 9 | U2: 10 | V2: 11 | W2: 12 | X2: 13 | Y2: 14 | AE2: код | AF2: 1 | AG2: 2 | AH2: 3 | AN2: код | AO2: 1 | AP2: 2 | AQ2: 3 | AW2: код | AX2: 1 | AY2: 2 | AZ2: 3 | BF2: код | BG2: 1 | BH2: 2 | BI2: 3 | BO2: код | BP2: 1 | BQ2: 2 | BW2: код | BX2: 1 | BY2: 2 | CE2: код | CF2: 1 | CG2: 2
A4: Смена | B4: Карьер | C4: Выемка руды из карьера | F4: Содержание , г/т | H4: Металл,кг | J4: код мест разгрузки | K4: Вес руды из карьера разгруженной на местах разгрузки ,т | Z4: Вывозка с шихтовочной площадки №1 | AI4: Вывозка с шихтовочной площадки №2 | AR4: Вывозка с шихтовочной площадки №3 | BA4: Вывозка с шихтовочной площадки №4 | BJ4: Вывозка заб руды с заб отвала №1 | BR4: Вывозка заб руды с заб отвала №2 | BZ4: Вывозка с перегрузочного южного склада | CH4: 1
C5: № блока | D5: Сорт руды | E5: Руда, т (сух) | F5: СAu | G5: СAg | H5: Au | I5: Ag | K5: пирог | L5: Шихтовочная площадка | P5: склад негабар | Q5: Южный перегрузочный склад | R5: склад бедной первич.руды | T5: забалансовый отвал | U5: ЗИФ УВП | X5: ЗИФ КВ | Z5: Склад бедной первич.руды | AE5: код мест разгрузки | AF5: Место разгрузки | AI5: Склад бедной первич.руды | AN5: код мест разгрузки | AO5: Место разгрузки | AR5: Склад бедной первич.руды | AW5: код мест разгрузки | AX5: Место разгрузки | BA5: Склад бедной первич.руды | BF5: код мест разгрузки | BG5: Место разгрузки | BJ5: Склад бедной первич.руды | BO5: код мест разгрузки | BP5: Место разгрузки | BR5: Склад бедной первич.руды | BW5: код мест разгрузки | BX5: Место разгрузки | BZ5: Склад бедной первич.руды | CE5: код мест разгрузки | CF5: Место разгрузки
U6: ККД, тн | V6: Склад ЗИФ-УВП, тн | W6: МПСИ, тн | X6: Склад ЗИФ КВ, тн | Y6: Бункер ЗИФ КВ, тн | Z6: Руда, тн (вл.вес) | AA6: содержание, г/т | AC6: Металл,кг | AF6: ККД, тн | AG6: Склад ЗИФ-УВП, тн | AH6: МПСИ, тн | AI6: Руда, тн (вл.вес) | AJ6: содержание, г/т | AL6: Металл,кг | AO6: ККД, тн | AP6: Склад ЗИФ-УВП, тн | AQ6: МПСИ, тн | AR6: Руда, тн (вл.вес) | AS6: содержание, г/т | AU6: Металл,кг | AX6: ККД, тн | AY6: Склад ЗИФ-УВП, тн | AZ6: МПСИ, тн | BA6: Руда, тн (вл.вес) | BB6: содержание, г/т | BD6: Металл,кг | BG6: ККД, тн | BH6: Склад ЗИФ-УВП, тн | BI6: МПСИ, тн | BJ6: Руда, тн (вл.вес) | BK6: содержание, г/т | BM6: Металл,кг | BP6: Склад ЗИФ КВ, тн | BQ6: Бункер ЗИФ КВ, тн | BR6: Руда, тн (вл.вес) | BS6: содержание, г/т | BU6: Металл,кг | BX6: Склад ЗИФ КВ, тн | BY6: Бункер ЗИФ КВ, тн | BZ6: Руда, тн (вл.вес) | CA6: содержание, г/т | CC6: Металл,кг | CF6: Склад ЗИФ КВ, тн | CG6: Бункер ЗИФ КВ, тн
L7: 1 | M7: 2 | N7: 3 | O7: 4 | R7: просто склад | S7: пирог | AA7: СAu | AB7: СAg | AC7: Au | AD7: Ag | AJ7: СAu | AK7: СAg | AL7: Au | AM7: Ag | AS7: СAu | AT7: СAg | AU7: Au | AV7: Ag | BB7: СAu | BC7: СAg | BD7: Au | BE7: Ag | BK7: СAu | BL7: СAg | BM7: Au | BN7: Ag | BS7: СAu | BT7: СAg | BU7: Au | BV7: Ag | CA7: СAu | CB7: СAg | CC7: Au | CD7: Ag
A8: 1 | C8: =A8+1 -> 2 | D8: =C8+1 -> 3 | E8: =D8+1 -> 4 | F8: =E8+1 -> 5 | G8: =F8+1 -> 6 | H8: =G8+1 -> 7 | I8: =H8+1 -> 8 | J8: =I8+1 -> 9 | K8: =J8+1 -> 10 | ... P8: =O8+1 -> 15 | Q8: 16 | R8: =Q8+1 -> 17 | S8: 17 | T8: =S8+1 -> 18 | U8: 18 | V8: =U8+1 -> 19 | W8: 19 | X8: =W8+1 -> 20 | Y8: 20 | Z8: =Y8+1 -> 21 | AA8: =Z8+1 -> 22 | AB8: =AA8+1 -> 23 | AC8: =AB8+1 -> 24 | AD8: =AC8+1 -> 25 | AE8: =AD8+1 -> 26 | AF8: =AE8+1 -> 27 | AG8: =AF8+1 -> 28 | ... CG8: =CF8+1 -> 80
A9: 1 | B9: Воронцовский | D9: Добыча первичной руды | H9: =E9*F9/1000 -> 0 | I9: =E9*G9/1000 -> 0 | K9: =IF($J9=15,$E9,0) -> 0 | L9: =IF($J9=1,$E9,0) -> 0 | M9: =IF($J9=2,$E9,0) -> 0 | N9: =IF($J9=3,$E9,0) -> 0 | O9: =IF($J9=4,$E9,0) -> 0 | P9: =IF($J9=5,$E9,0) -> 0 | Q9: =IF($J9=6,$E9,0) -> 0 | R9: =IF($J9=7,$E9,0) -> 0 | S9: =IF($J9=8,$E9,0) -> 0 | T9: =IF($J9=9,$E9,0) -> 0 | U9: =IF($J9=10,$E9,0) -> 0 | V9: =IF($J9=11,$E9,0) -> 0 | W9: =IF($J9=12,$E9,0) -> 0 | X9: =IF($J9=13,$E9,0) -> 0 | Y9: =IF($J9=14,$E9,0) -> 0 | AC9: =Z9*0.97*AA9/1000 -> 0 | AD9: =Z9*0.97*AB9/1000 -> 0 | AF9: =IF($AE9=1,$Z9,0) -> 0 | AG9: =IF($AE9=2,$Z9,0) -> 0 | AH9: =IF($AE9=3,$Z9,0) -> 0 | AL9: =AI9*0.97*AJ9/1000 -> 0 | AM9: =AI9*0.97*AK9/1000 -> 0 | AO9: =IF($AN9=1,$AI9,0) -> 0 | AP9: =IF($AN9=2,$AI9,0) -> 0 | AQ9: =IF($AN9=3,$AI9,0) -> 0 | AU9: =AR9*0.97*AS9/1000 -> 0 | AV9: =AR9*0.97*AT9/1000 -> 0 | AX9: =IF($AW9=1,$AR9,0) -> 0 | AY9: =IF($AW9=2,$AR9,0) -> 0 | AZ9: =IF($AW9=3,$AR9,0) -> 0 | BD9: =BA9*0.97*BB9/1000 -> 0 | BE9: =BA9*0.97*BC9/1000 -> 0 | BG9: =IF($BF9=1,$BA9,0) -> 0 | BH9: =IF($BF9=2,$BA9,0) -> 0 | BI9: =IF($BF9=3,$BA9,0) -> 0 | BM9: =BJ9*0.84*BK9/1000 -> 0 | BN9: =BJ9*0.84*BL9/1000 -> 0 | BP9: =IF($BO9=1,$BJ9,0) -> 0 | BQ9: =IF($BO9=2,$BJ9,0) -> 0 | BU9: =BR9*0.84*BS9/1000 -> 0 | BV9: =BR9*0.84*BT9/1000 -> 0 | BX9: =IF($BW9=1,$BR9,0) -> 0 | BY9: =IF($BW9=2,$BR9,0) -> 0 | CC9: =BZ9*0.84*CA9/1000 -> 0 | CD9: =BZ9*0.84*CB9/1000 -> 0 | CF9: =IF($CE9=1,$BZ9,0) -> 0 | CG9: =IF($CE9=2,$BZ9,0) -> 0
D10: Добыча первичной руды | H10: =E10*F10/1000 -> 0 | I10: =E10*G10/1000 -> 0 | K10: =IF($J10=15,$E10,0) -> 0 | L10: =IF($J10=1,$E10,0) -> 0 | M10: =IF($J10=2,$E10,0) -> 0 | N10: =IF($J10=3,$E10,0) -> 0 | O10: =IF($J10=4,$E10,0) -> 0 | P10: =IF($J10=5,$E10,0) -> 0 | Q10: =IF($J10=6,$E10,0) -> 0 | R10: =IF($J10=7,$E10,0) -> 0 | S10: =IF($J10=8,$E10,0) -> 0 | T10: =IF($J10=9,$E10,0) -> 0 | U10: =IF($J10=10,$E10,0) -> 0 | V10: =IF($J10=11,$E10,0) -> 0 | W10: =IF($J10=12,$E10,0) -> 0 | X10: =IF($J10=13,$E10,0) -> 0 | Y10: =IF($J10=14,$E10,0) -> 0 | AC10: =Z10*0.97*AA10/1000 -> 0 | AD10: =Z10*0.97*AB10/1000 -> 0 | AF10: =IF($AE10=1,$Z10,0) -> 0 | AG10: =IF($AE10=2,$Z10,0) -> 0 | AH10: =IF($AE10=3,$Z10,0) -> 0 | AL10: =AI10*0.97*AJ10/1000 -> 0 | AM10: =AI10*0.97*AK10/1000 -> 0 | AO10: =IF($AN10=1,$AI10,0) -> 0 | AP10: =IF($AN10=2,$AI10,0) -> 0 | AQ10: =IF($AN10=3,$AI10,0) -> 0 | AU10: =AR10*0.97*AS10/1000 -> 0 | AV10: =AR10*0.97*AT10/1000 -> 0 | AX10: =IF($AW10=1,$AR10,0) -> 0 | AY10: =IF($AW10=2,$AR10,0) -> 0 | AZ10: =IF($AW10=3,$AR10,0) -> 0 | BD10: =BA10*0.97*BB10/1000 -> 0 | BE10: =BA10*0.97*BC10/1000 -> 0 | BG10: =IF($BF10=1,$BA10,0) -> 0 | BH10: =IF($BF10=2,$BA10,0) -> 0 | BI10: =IF($BF10=3,$BA10,0) -> 0 | BM10: =BJ10*0.84*BK10/1000 -> 0 | BN10: =BJ10*0.84*BL10/1000 -> 0 | BP10: =IF($BO10=1,$BJ10,0) -> 0 | BQ10: =IF($BO10=2,$BJ10,0) -> 0 | BU10: =BR10*0.84*BS10/1000 -> 0 | BV10: =BR10*0.84*BT10/1000 -> 0 | BX10: =IF($BW10=1,$BR10,0) -> 0 | BY10: =IF($BW10=2,$BR10,0) -> 0 | CC10: =BZ10*0.84*CA10/1000 -> 0 | CD10: =BZ10*0.84*CB10/1000 -> 0 | CF10: =IF($CE10=1,$BZ10,0) -> 0 | CG10: =IF($CE10=2,$BZ10,0) -> 0
D11: Добыча первичной руды | H11: =E11*F11/1000 -> 0 | I11: =E11*G11/1000 -> 0 | K11: =IF($J11=15,$E11,0) -> 0 | L11: =IF($J11=1,$E11,0) -> 0 | M11: =IF($J11=2,$E11,0) -> 0 | N11: =IF($J11=3,$E11,0) -> 0 | O11: =IF($J11=4,$E11,0) -> 0 | P11: =IF($J11=5,$E11,0) -> 0 | Q11: =IF($J11=6,$E11,0) -> 0 | R11: =IF($J11=7,$E11,0) -> 0 | S11: =IF($J11=8,$E11,0) -> 0 | T11: =IF($J11=9,$E11,0) -> 0 | U11: =IF($J11=10,$E11,0) -> 0 | V11: =IF($J11=11,$E11,0) -> 0 | W11: =IF($J11=12,$E11,0) -> 0 | X11: =IF($J11=13,$E11,0) -> 0 | Y11: =IF($J11=14,$E11,0) -> 0 | AC11: =Z11*0.97*AA11/1000 -> 0 | AD11: =Z11*0.97*AB11/1000 -> 0 | AF11: =IF($AE11=1,$Z11,0) -> 0 | AG11: =IF($AE11=2,$Z11,0) -> 0 | AH11: =IF($AE11=3,$Z11,0) -> 0 | AL11: =AI11*0.97*AJ11/1000 -> 0 | AM11: =AI11*0.97*AK11/1000 -> 0 | AO11: =IF($AN11=1,$AI11,0) -> 0 | AP11: =IF($AN11=2,$AI11,0) -> 0 | AQ11: =IF($AN11=3,$AI11,0) -> 0 | AU11: =AR11*0.97*AS11/1000 -> 0 | AV11: =AR11*0.97*AT11/1000 -> 0 | AX11: =IF($AW11=1,$AR11,0) -> 0 | AY11: =IF($AW11=2,$AR11,0) -> 0 | AZ11: =IF($AW11=3,$AR11,0) -> 0 | BD11: =BA11*0.97*BB11/1000 -> 0 | BE11: =BA11*0.97*BC11/1000 -> 0 | BG11: =IF($BF11=1,$BA11,0) -> 0 | BH11: =IF($BF11=2,$BA11,0) -> 0 | BI11: =IF($BF11=3,$BA11,0) -> 0 | BM11: =BJ11*0.84*BK11/1000 -> 0 | BN11: =BJ11*0.84*BL11/1000 -> 0 | BP11: =IF($BO11=1,$BJ11,0) -> 0 | BQ11: =IF($BO11=2,$BJ11,0) -> 0 | BU11: =BR11*0.84*BS11/1000 -> 0 | BV11: =BR11*0.84*BT11/1000 -> 0 | BX11: =IF($BW11=1,$BR11,0) -> 0 | BY11: =IF($BW11=2,$BR11,0) -> 0 | CC11: =BZ11*0.84*CA11/1000 -> 0 | CD11: =BZ11*0.84*CB11/1000 -> 0 | CF11: =IF($CE11=1,$BZ11,0) -> 0 | CG11: =IF($CE11=2,$BZ11,0) -> 0
B12: ЮВК | D12: Добыча первичной руды | H12: =E12*F12/1000 -> 0 | I12: =E12*G12/1000 -> 0 | K12: =IF($J102=15,$E102,0) -> 0 | L12: =IF($J12=1,$E12,0) -> 0 | M12: =IF($J12=2,$E12,0) -> 0 | N12: =IF($J12=3,$E12,0) -> 0 | O12: =IF($J12=4,$E12,0) -> 0 | P12: =IF($J12=5,$E12,0) -> 0 | Q12: =IF($J12=6,$E12,0) -> 0 | R12: =IF($J12=7,$E12,0) -> 0 | S12: =IF($J12=8,$E12,0) -> 0 | T12: =IF($J12=9,$E12,0) -> 0 | U12: =IF($J12=10,$E12,0) -> 0 | V12: =IF($J12=11,$E12,0) -> 0 | W12: =IF($J12=12,$E12,0) -> 0 | X12: =IF($J12=13,$E12,0) -> 0 | Y12: =IF($J12=14,$E12,0) -> 0 | AC12: =Z12*0.97*AA12/1000 -> 0 | AD12: =Z12*0.97*AB12/1000 -> 0 | AF12: =IF($AE12=1,$Z12,0) -> 0 | AG12: =IF($AE12=2,$Z12,0) -> 0 | AH12: =IF($AE12=3,$Z12,0) -> 0 | AL12: =AI12*0.97*AJ12/1000 -> 0 | AM12: =AI12*0.97*AK12/1000 -> 0 | AO12: =IF($AN12=1,$AI12,0) -> 0 | AP12: =IF($AN12=2,$AI12,0) -> 0 | AQ12: =IF($AN12=3,$AI12,0) -> 0 | AU12: =AR12*0.97*AS12/1000 -> 0 | AV12: =AR12*0.97*AT12/1000 -> 0 | AX12: =IF($AW12=1,$AR12,0) -> 0 | AY12: =IF($AW12=2,$AR12,0) -> 0 | AZ12: =IF($AW12=3,$AR12,0) -> 0 | BD12: =BA12*0.97*BB12/1000 -> 0 | BE12: =BA12*0.97*BC12/1000 -> 0 | BG12: =IF($BF12=1,$BA12,0) -> 0 | BH12: =IF($BF12=2,$BA12,0) -> 0 | BI12: =IF($BF12=3,$BA12,0) -> 0 | BM12: =BJ12*0.84*BK12/1000 -> 0 | BN12: =BJ12*0.84*BL12/1000 -> 0 | BP12: =IF($BO12=1,$BJ12,0) -> 0 | BQ12: =IF($BO12=2,$BJ12,0) -> 0 | BU12: =BR12*0.84*BS12/1000 -> 0 | BV12: =BR12*0.84*BT12/1000 -> 0 | BX12: =IF($BW12=1,$BR12,0) -> 0 | BY12: =IF($BW12=2,$BR12,0) -> 0 | CC12: =BZ12*0.84*CA12/1000 -> 0 | CD12: =BZ12*0.84*CB12/1000 -> 0 | CF12: =IF($CE12=1,$BZ12,0) -> 0 | CG12: =IF($CE12=2,$BZ12,0) -> 0
B13: Воронцовский | D13: Добыча окисленной руды | H13: =E13*F13/1000 -> 0 | I13: =E13*G13/1000 -> 0 | K13: =IF($J13=15,$E13,0) -> 0 | L13: =IF($J13=1,$E13,0) -> 0 | M13: =IF($J13=2,$E13,0) -> 0 | N13: =IF($J13=3,$E13,0) -> 0 | O13: =IF($J13=4,$E13,0) -> 0 | P13: =IF($J13=5,$E13,0) -> 0 | Q13: =IF($J13=6,$E13,0) -> 0 | R13: =IF($J13=7,$E13,0) -> 0 | S13: =IF($J13=8,$E13,0) -> 0 | T13: =IF($J13=9,$E13,0) -> 0 | U13: =IF($J13=10,$E13,0) -> 0 | V13: =IF($J13=11,$E13,0) -> 0 | W13: =IF($J13=12,$E13,0) -> 0 | X13: =IF($J13=13,$E13,0) -> 0 | Y13: =IF($J13=14,$E13,0) -> 0 | AC13: =Z13*0.97*AA13/1000 -> 0 | AD13: =Z13*0.97*AB13/1000 -> 0 | AF13: =IF($AE13=1,$Z13,0) -> 0 | AG13: =IF($AE13=2,$Z13,0) -> 0 | AH13: =IF($AE13=3,$Z13,0) -> 0 | AL13: =AI13*0.97*AJ13/1000 -> 0 | AM13: =AI13*0.97*AK13/1000 -> 0 | AO13: =IF($AN13=1,$AI13,0) -> 0 | AP13: =IF($AN13=2,$AI13,0) -> 0 | AQ13: =IF($AN13=3,$AI13,0) -> 0 | AU13: =AR13*0.97*AS13/1000 -> 0 | AV13: =AR13*0.97*AT13/1000 -> 0 | AX13: =IF($AW13=1,$AR13,0) -> 0 | AY13: =IF($AW13=2,$AR13,0) -> 0 | AZ13: =IF($AW13=3,$AR13,0) -> 0 | BD13: =BA13*0.97*BB13/1000 -> 0 | BE13: =BA13*0.97*BC13/1000 -> 0 | BG13: =IF($BF13=1,$BA13,0) -> 0 | BH13: =IF($BF13=2,$BA13,0) -> 0 | BI13: =IF($BF13=3,$BA13,0) -> 0 | BM13: =BJ13*0.84*BK13/1000 -> 0 | BN13: =BJ13*0.84*BL13/1000 -> 0 | BP13: =IF($BO13=1,$BJ13,0) -> 0 | BQ13: =IF($BO13=2,$BJ13,0) -> 0 | BU13: =BR13*0.84*BS13/1000 -> 0 | BV13: =BR13*0.84*BT13/1000 -> 0 | BX13: =IF($BW13=1,$BR13,0) -> 0 | BY13: =IF($BW13=2,$BR13,0) -> 0 | CC13: =BZ13*0.84*CA13/1000 -> 0 | CD13: =BZ13*0.84*CB13/1000 -> 0 | CF13: =IF($CE13=1,$BZ13,0) -> 0 | CG13: =IF($CE13=2,$BZ13,0) -> 0
B14: ЮВК | D14: Добыча окисленной руды | H14: =E14*F14/1000 -> 0 | I14: =E14*G14/1000 -> 0 | K14: =IF($J14=15,$E14,0) -> 0 | L14: =IF($J14=1,$E14,0) -> 0 | M14: =IF($J14=2,$E14,0) -> 0 | N14: =IF($J14=3,$E14,0) -> 0 | O14: =IF($J14=4,$E14,0) -> 0 | P14: =IF($J14=5,$E14,0) -> 0 | Q14: =IF($J14=6,$E14,0) -> 0 | R14: =IF($J14=7,$E14,0) -> 0 | S14: =IF($J14=8,$E14,0) -> 0 | T14: =IF($J14=9,$E14,0) -> 0 | U14: =IF($J14=10,$E14,0) -> 0 | V14: =IF($J14=11,$E14,0) -> 0 | W14: =IF($J14=12,$E14,0) -> 0 | X14: =IF($J14=13,$E14,0) -> 0 | Y14: =IF($J14=14,$E14,0) -> 0 | AC14: =Z14*0.97*AA14/1000 -> 0 | AD14: =Z14*0.97*AB14/1000 -> 0 | AF14: =IF($AE14=1,$Z14,0) -> 0 | AG14: =IF($AE14=2,$Z14,0) -> 0 | AH14: =IF($AE14=3,$Z14,0) -> 0 | AL14: =AI14*0.97*AJ14/1000 -> 0 | AM14: =AI14*0.97*AK14/1000 -> 0 | AO14: =IF($AN14=1,$AI14,0) -> 0 | AP14: =IF($AN14=2,$AI14,0) -> 0 | AQ14: =IF($AN14=3,$AI14,0) -> 0 | AU14: =AR14*0.97*AS14/1000 -> 0 | AV14: =AR14*0.97*AT14/1000 -> 0 | AX14: =IF($AW14=1,$AR14,0) -> 0 | AY14: =IF($AW14=2,$AR14,0) -> 0 | AZ14: =IF($AW14=3,$AR14,0) -> 0 | BD14: =BA14*0.97*BB14/1000 -> 0 | BE14: =BA14*0.97*BC14/1000 -> 0 | BG14: =IF($BF14=1,$BA14,0) -> 0 | BH14: =IF($BF14=2,$BA14,0) -> 0 | BI14: =IF($BF14=3,$BA14,0) -> 0 | BM14: =BJ14*0.84*BK14/1000 -> 0 | BN14: =BJ14*0.84*BL14/1000 -> 0 | BP14: =IF($BO14=1,$BJ14,0) -> 0 | BQ14: =IF($BO14=2,$BJ14,0) -> 0 | BU14: =BR14*0.84*BS14/1000 -> 0 | BV14: =BR14*0.84*BT14/1000 -> 0 | BX14: =IF($BW14=1,$BR14,0) -> 0 | BY14: =IF($BW14=2,$BR14,0) -> 0 | CC14: =BZ14*0.84*CA14/1000 -> 0 | CD14: =BZ14*0.84*CB14/1000 -> 0 | CF14: =IF($CE14=1,$BZ14,0) -> 0 | CG14: =IF($CE14=2,$BZ14,0) -> 0
D15: Добыча окисленной руды | H15: =E15*F15/1000 -> 0 | I15: =E15*G15/1000 -> 0 | K15: =IF($J15=15,$E15,0) -> 0 | L15: =IF($J15=1,$E15,0) -> 0 | M15: =IF($J15=2,$E15,0) -> 0 | N15: =IF($J15=3,$E15,0) -> 0 | O15: =IF($J15=4,$E15,0) -> 0 | P15: =IF($J15=5,$E15,0) -> 0 | Q15: =IF($J15=6,$E15,0) -> 0 | R15: =IF($J15=7,$E15,0) -> 0 | S15: =IF($J15=8,$E15,0) -> 0 | T15: =IF($J15=9,$E15,0) -> 0 | U15: =IF($J15=10,$E15,0) -> 0 | V15: =IF($J15=11,$E15,0) -> 0 | W15: =IF($J15=12,$E15,0) -> 0 | X15: =IF($J15=13,$E15,0) -> 0 | Y15: =IF($J15=14,$E15,0) -> 0 | AC15: =Z15*0.97*AA15/1000 -> 0 | AD15: =Z15*0.97*AB15/1000 -> 0 | AF15: =IF($AE15=1,$Z15,0) -> 0 | AG15: =IF($AE15=2,$Z15,0) -> 0 | AH15: =IF($AE15=3,$Z15,0) -> 0 | AL15: =AI15*0.97*AJ15/1000 -> 0 | AM15: =AI15*0.97*AK15/1000 -> 0 | AO15: =IF($AN15=1,$AI15,0) -> 0 | AP15: =IF($AN15=2,$AI15,0) -> 0 | AQ15: =IF($AN15=3,$AI15,0) -> 0 | AU15: =AR15*0.97*AS15/1000 -> 0 | AV15: =AR15*0.97*AT15/1000 -> 0 | AX15: =IF($AW15=1,$AR15,0) -> 0 | AY15: =IF($AW15=2,$AR15,0) -> 0 | AZ15: =IF($AW15=3,$AR15,0) -> 0 | BD15: =BA15*0.97*BB15/1000 -> 0 | BE15: =BA15*0.97*BC15/1000 -> 0 | BG15: =IF($BF15=1,$BA15,0) -> 0 | BH15: =IF($BF15=2,$BA15,0) -> 0 | BI15: =IF($BF15=3,$BA15,0) -> 0 | BM15: =BJ15*0.84*BK15/1000 -> 0 | BN15: =BJ15*0.84*BL15/1000 -> 0 | BP15: =IF($BO15=1,$BJ15,0) -> 0 | BQ15: =IF($BO15=2,$BJ15,0) -> 0 | BU15: =BR15*0.84*BS15/1000 -> 0 | BV15: =BR15*0.84*BT15/1000 -> 0 | BX15: =IF($BW15=1,$BR15,0) -> 0 | BY15: =IF($BW15=2,$BR15,0) -> 0 | CC15: =BZ15*0.84*CA15/1000 -> 0 | CD15: =BZ15*0.84*CB15/1000 -> 0 | CF15: =IF($CE15=1,$BZ15,0) -> 0 | CG15: =IF($CE15=2,$BZ15,0) -> 0
B16: Воронцовский | D16: Добыча окисл. забал. руды | H16: =E16*F16/1000 -> 0 | I16: =E16*G16/1000 -> 0 | K16: =IF($J16=15,$E16,0) -> 0 | L16: =IF($J16=1,$E16,0) -> 0 | M16: =IF($J16=2,$E16,0) -> 0 | N16: =IF($J16=3,$E16,0) -> 0 | O16: =IF($J16=4,$E16,0) -> 0 | P16: =IF($J16=5,$E16,0) -> 0 | Q16: =IF($J16=6,$E16,0) -> 0 | R16: =IF($J16=7,$E16,0) -> 0 | S16: =IF($J16=8,$E16,0) -> 0 | T16: =IF($J16=9,$E16,0) -> 0 | U16: =IF($J16=10,$E16,0) -> 0 | V16: =IF($J16=11,$E16,0) -> 0 | W16: =IF($J16=12,$E16,0) -> 0 | X16: =IF($J16=13,$E16,0) -> 0 | Y16: =IF($J16=14,$E16,0) -> 0 | AC16: =Z16*0.97*AA16/1000 -> 0 | AD16: =Z16*0.97*AB16/1000 -> 0 | AF16: =IF($AE16=1,$Z16,0) -> 0 | AG16: =IF($AE16=2,$Z16,0) -> 0 | AH16: =IF($AE16=3,$Z16,0) -> 0 | AL16: =AI16*0.97*AJ16/1000 -> 0 | AM16: =AI16*0.97*AK16/1000 -> 0 | AO16: =IF($AN16=1,$AI16,0) -> 0 | AP16: =IF($AN16=2,$AI16,0) -> 0 | AQ16: =IF($AN16=3,$AI16,0) -> 0 | AU16: =AR16*0.97*AS16/1000 -> 0 | AV16: =AR16*0.97*AT16/1000 -> 0 | AX16: =IF($AW16=1,$AR16,0) -> 0 | AY16: =IF($AW16=2,$AR16,0) -> 0 | AZ16: =IF($AW16=3,$AR16,0) -> 0 | BD16: =BA16*0.97*BB16/1000 -> 0 | BE16: =BA16*0.97*BC16/1000 -> 0 | BG16: =IF($BF16=1,$BA16,0) -> 0 | BH16: =IF($BF16=2,$BA16,0) -> 0 | BI16: =IF($BF16=3,$BA16,0) -> 0 | BM16: =BJ16*0.84*BK16/1000 -> 0 | BN16: =BJ16*0.84*BL16/1000 -> 0 | BP16: =IF($BO16=1,$BJ16,0) -> 0 | BQ16: =IF($BO16=2,$BJ16,0) -> 0 | BU16: =BR16*0.84*BS16/1000 -> 0 | BV16: =BR16*0.84*BT16/1000 -> 0 | BX16: =IF($BW16=1,$BR16,0) -> 0 | BY16: =IF($BW16=2,$BR16,0) -> 0 | CC16: =BZ16*0.84*CA16/1000 -> 0 | CD16: =BZ16*0.84*CB16/1000 -> 0 | CF16: =IF($CE16=1,$BZ16,0) -> 0 | CG16: =IF($CE16=2,$BZ16,0) -> 0
B17: ЮВК | D17: Добыча окисл. забал. руды | H17: =E17*F17/1000 -> 0 | I17: =E17*G17/1000 -> 0 | K17: =IF($J17=15,$E17,0) -> 0 | L17: =IF($J17=1,$E17,0) -> 0 | M17: =IF($J17=2,$E17,0) -> 0 | N17: =IF($J17=3,$E17,0) -> 0 | O17: =IF($J17=4,$E17,0) -> 0 | P17: =IF($J17=5,$E17,0) -> 0 | Q17: =IF($J17=6,$E17,0) -> 0 | R17: =IF($J17=7,$E17,0) -> 0 | S17: =IF($J17=8,$E17,0) -> 0 | T17: =IF($J17=9,$E17,0) -> 0 | U17: =IF($J17=10,$E17,0) -> 0 | V17: =IF($J17=11,$E17,0) -> 0 | W17: =IF($J17=12,$E17,0) -> 0 | X17: =IF($J17=13,$E17,0) -> 0 | Y17: =IF($J17=14,$E17,0) -> 0 | AC17: =Z17*0.97*AA17/1000 -> 0 | AD17: =Z17*0.97*AB17/1000 -> 0 | AF17: =IF($AE17=1,$Z17,0) -> 0 | AG17: =IF($AE17=2,$Z17,0) -> 0 | AH17: =IF($AE17=3,$Z17,0) -> 0 | AL17: =AI17*0.97*AJ17/1000 -> 0 | AM17: =AI17*0.97*AK17/1000 -> 0 | AO17: =IF($AN17=1,$AI17,0) -> 0 | AP17: =IF($AN17=2,$AI17,0) -> 0 | AQ17: =IF($AN17=3,$AI17,0) -> 0 | AU17: =AR17*0.97*AS17/1000 -> 0 | AV17: =AR17*0.97*AT17/1000 -> 0 | AX17: =IF($AW17=1,$AR17,0) -> 0 | AY17: =IF($AW17=2,$AR17,0) -> 0 | AZ17: =IF($AW17=3,$AR17,0) -> 0 | BD17: =BA17*0.97*BB17/1000 -> 0 | BE17: =BA17*0.97*BC17/1000 -> 0 | BG17: =IF($BF17=1,$BA17,0) -> 0 | BH17: =IF($BF17=2,$BA17,0) -> 0 | BI17: =IF($BF17=3,$BA17,0) -> 0 | BM17: =BJ17*0.84*BK17/1000 -> 0 | BN17: =BJ17*0.84*BL17/1000 -> 0 | BP17: =IF($BO17=1,$BJ17,0) -> 0 | BQ17: =IF($BO17=2,$BJ17,0) -> 0 | BU17: =BR17*0.84*BS17/1000 -> 0 | BV17: =BR17*0.84*BT17/1000 -> 0 | BX17: =IF($BW17=1,$BR17,0) -> 0 | BY17: =IF($BW17=2,$BR17,0) -> 0 | CC17: =BZ17*0.84*CA17/1000 -> 0 | CD17: =BZ17*0.84*CB17/1000 -> 0 | CF17: =IF($CE17=1,$BZ17,0) -> 0 | CG17: =IF($CE17=2,$BZ17,0) -> 0
D18: Добыча окисл. забал. руды | H18: =E18*F18/1000 -> 0 | I18: =E18*G18/1000 -> 0 | K18: =IF($J18=15,$E18,0) -> 0 | L18: =IF($J18=1,$E18,0) -> 0 | M18: =IF($J18=2,$E18,0) -> 0 | N18: =IF($J18=3,$E18,0) -> 0 | O18: =IF($J18=4,$E18,0) -> 0 | P18: =IF($J18=5,$E18,0) -> 0 | Q18: =IF($J18=6,$E18,0) -> 0 | R18: =IF($J18=7,$E18,0) -> 0 | S18: =IF($J18=8,$E18,0) -> 0 | T18: =IF($J18=9,$E18,0) -> 0 | U18: =IF($J18=10,$E18,0) -> 0 | V18: =IF($J18=11,$E18,0) -> 0 | W18: =IF($J18=12,$E18,0) -> 0 | X18: =IF($J18=13,$E18,0) -> 0 | Y18: =IF($J18=14,$E18,0) -> 0 | AC18: =Z18*0.97*AA18/1000 -> 0 | AD18: =Z18*0.97*AB18/1000 -> 0 | AF18: =IF($AE18=1,$Z18,0) -> 0 | AG18: =IF($AE18=2,$Z18,0) -> 0 | AH18: =IF($AE18=3,$Z18,0) -> 0 | AL18: =AI18*0.97*AJ18/1000 -> 0 | AM18: =AI18*0.97*AK18/1000 -> 0 | AO18: =IF($AN18=1,$AI18,0) -> 0 | AP18: =IF($AN18=2,$AI18,0) -> 0 | AQ18: =IF($AN18=3,$AI18,0) -> 0 | AU18: =AR18*0.97*AS18/1000 -> 0 | AV18: =AR18*0.97*AT18/1000 -> 0 | AX18: =IF($AW18=1,$AR18,0) -> 0 | AY18: =IF($AW18=2,$AR18,0) -> 0 | AZ18: =IF($AW18=3,$AR18,0) -> 0 | BD18: =BA18*0.97*BB18/1000 -> 0 | BE18: =BA18*0.97*BC18/1000 -> 0 | BG18: =IF($BF18=1,$BA18,0) -> 0 | BH18: =IF($BF18=2,$BA18,0) -> 0 | BI18: =IF($BF18=3,$BA18,0) -> 0 | BM18: =BJ18*0.84*BK18/1000 -> 0 | BN18: =BJ18*0.84*BL18/1000 -> 0 | BP18: =IF($BO18=1,$BJ18,0) -> 0 | BQ18: =IF($BO18=2,$BJ18,0) -> 0 | BU18: =BR18*0.84*BS18/1000 -> 0 | BV18: =BR18*0.84*BT18/1000 -> 0 | BX18: =IF($BW18=1,$BR18,0) -> 0 | BY18: =IF($BW18=2,$BR18,0) -> 0 | CC18: =BZ18*0.84*CA18/1000 -> 0 | CD18: =BZ18*0.84*CB18/1000 -> 0 | CF18: =IF($CE18=1,$BZ18,0) -> 0 | CG18: =IF($CE18=2,$BZ18,0) -> 0
B19: Воронцовский | D19: Добыча аргилизитов | H19: =E19*F19/1000 -> 0 | I19: =E19*G19/1000 -> 0 | K19: =IF($J19=15,$E19,0) -> 0 | L19: =IF($J19=1,$E19,0) -> 0 | M19: =IF($J19=2,$E19,0) -> 0 | N19: =IF($J19=3,$E19,0) -> 0 | O19: =IF($J19=4,$E19,0) -> 0 | P19: =IF($J19=5,$E19,0) -> 0 | Q19: =IF($J19=6,$E19,0) -> 0 | R19: =IF($J19=7,$E19,0) -> 0 | S19: =IF($J19=8,$E19,0) -> 0 | T19: =IF($J19=9,$E19,0) -> 0 | U19: =IF($J19=10,$E19,0) -> 0 | V19: =IF($J19=11,$E19,0) -> 0 | W19: =IF($J19=12,$E19,0) -> 0 | X19: =IF($J19=13,$E19,0) -> 0 | Y19: =IF($J19=14,$E19,0) -> 0 | AC19: =Z19*0.97*AA19/1000 -> 0 | AD19: =Z19*0.97*AB19/1000 -> 0 | AF19: =IF($AE19=1,$Z19,0) -> 0 | AG19: =IF($AE19=2,$Z19,0) -> 0 | AH19: =IF($AE19=3,$Z19,0) -> 0 | AL19: =AI19*0.97*AJ19/1000 -> 0 | AM19: =AI19*0.97*AK19/1000 -> 0 | AO19: =IF($AN19=1,$AI19,0) -> 0 | AP19: =IF($AN19=2,$AI19,0) -> 0 | AQ19: =IF($AN19=3,$AI19,0) -> 0 | AU19: =AR19*0.97*AS19/1000 -> 0 | AV19: =AR19*0.97*AT19/1000 -> 0 | AX19: =IF($AW19=1,$AR19,0) -> 0 | AY19: =IF($AW19=2,$AR19,0) -> 0 | AZ19: =IF($AW19=3,$AR19,0) -> 0 | BD19: =BA19*0.97*BB19/1000 -> 0 | BE19: =BA19*0.97*BC19/1000 -> 0 | BG19: =IF($BF19=1,$BA19,0) -> 0 | BH19: =IF($BF19=2,$BA19,0) -> 0 | BI19: =IF($BF19=3,$BA19,0) -> 0 | BM19: =BJ19*0.84*BK19/1000 -> 0 | BN19: =BJ19*0.84*BL19/1000 -> 0 | BP19: =IF($BO19=1,$BJ19,0) -> 0 | BQ19: =IF($BO19=2,$BJ19,0) -> 0 | BU19: =BR19*0.84*BS19/1000 -> 0 | BV19: =BR19*0.84*BT19/1000 -> 0 | BX19: =IF($BW19=1,$BR19,0) -> 0 | BY19: =IF($BW19=2,$BR19,0) -> 0 | CC19: =BZ19*0.84*CA19/1000 -> 0 | CD19: =BZ19*0.84*CB19/1000 -> 0 | CF19: =IF($CE19=1,$BZ19,0) -> 0 | CG19: =IF($CE19=2,$BZ19,0) -> 0
